Workbook

Sheet ÇOKLU ASANSÖR
A1: ÇOKLU ASANSÖR TRAFİK HESABI — Farklı kapasitede asansör grubu (MMO/697 s.12)
A2: ▶ BU SAYFA BİRDEN FAZLA ASANSÖR İÇİNDİR — çıktısı PAFTA-COKLU sayfasıdır. Tek asansör için HESAPLAMA sayfasını kullanın. | Kaynak: MMO/697, Ocak 2020. Farklı kapasiteli asansörler için grup formülü (s.12) uygulanır.
A4: ORTAK BİNA BİLGİLERİ (tüm asansörler için aynı)
A5: ① Bina Tipi (tek seçim) | B5: Konut | C5: Manuel k (yalnız Tablo-9'da değer yoksa)
A6: → Tablo-9 %k tipi (otomatik) | B6: =IFERROR(INDEX('TABLO-10'!$L$2:$L$11,MATCH($B$5,'TABLO-10'!$J$2:$J$11,0)),"Manuel k gerekli") | C6: k girişi modu | D6: =IF(B6="Manuel k gerekli","Manuel gerekli",IF(LEFT($B$5,4)="Kamu","Tablo-9'da kamu yok → İş Merkezi %k varsayıldı (E5 ile değiştirilebilir)","Tablo-9 kilitli"))
A7: → Tablo-2 hız grubu (otomatik) | B7: =IFERROR(INDEX('TABLO-10'!$K$2:$K$11,MATCH($B$5,'TABLO-10'!$J$2:$J$11,0)),"Manuel hız gerekli") | C7: V girişi modu | D7: =IF(B7="Manuel hız gerekli","Manuel gerekli",IF(LEFT($B$5,4)="Kamu","Tablo-2'de kamu yok → Büro/İş Merkezi hızı varsayıldı",IF(B9+1>=20,"Manuel — eşik kontrollü","Tablo-2 kilitli")))
A8: Hesap standardı (yükseklikten otomatik) | B8: =IF(OR(D8>21.5,D9>30.5),"Yükseltilmiş","Standart") | C8: ② Bina yüksekliği (m) — bodrum hariç | D8: 39.98
A9: ③ Kat sayısı N (ana giriş üstü) | B9: 11 | C9: ④ Yapı yüksekliği (m) — bodrum dâhil | D9: 43
A10: ="⑤ "&IF($B$5="Konut","Daire sayısı (bağımsız bölüm adedi)",IF(OR(LEFT($B$5,10)="İş Merkezi",LEFT($B$5,4)="Kamu"),"Toplam çalışma alanı (m²) → 12 m² = 1 kişi",IF(OR(LEFT($B$5,4)="Otel",$B$5="Hastane"),"Toplam yatak sayısı",IF($B$5="Katlı Otopark","Özel amaçlı araç adedi","Bu bina tipinde hızlı giriş yok — aşağıdaki 5) tabloyu doldurun")))) | B10: 44 | C10: Manuel ortak V (yalnız gerektiğinde)
A11: =IF($B$5="Konut","⑥ Daire başına DİĞER oda sayısı (ilk yatak odası hariç; mutfak ve ıslak hacim sayılmaz)",IF($B$5="Katlı Otopark","⑥ Ticari amaçlı araç adedi",IF(OR($B$5="Konut",LEFT($B$5,10)="İş Merkezi",LEFT($B$5,4)="Kamu",LEFT($B$5,4)="Otel",$B$5="Hastane"),"⑥ (bu bina tipinde gerekmiyor — boş bırakın)","⑥ (kullanılmıyor — nüfusu aşağıdaki 5) tablodan girin)"))) | B11: 3
A12: ⑦ Kat yüksekliği h (m) — ortak (farklı binadaki asansör için 62. satır) | B12: 3 | C12: =IF(AND(ISNUMBER($B$12),OR($B$12<2,$B$12>6)),"⚠ h olağandışı — 2–6 m bekleniyor",IF(AND(ISNUMBER($D$9),ISNUMBER($B$9),ISNUMBER($B$12),$D$9<$B$9*$B$12),"⚠ Yapı yüksekliği < N × h — kontrol et",IF(AND(ISNUMBER($D$8),ISNUMBER($D$9),$D$8>$D$9),"⚠ Bina yüks. > yapı yüks. olamaz",""))) | H12: yardımcı (gizli): H13 = efektif ortak bodrum durak adedi
A13: ⑪ Bodrum durak adedi (ortak, ana giriş altı) | C13: Asansör bazında farklıysa 100. satırdan girin. Bodrum H ve S'yi değiştirmez; yalnız Tablo-2 hız seçimine ve seyahat mesafesine girer. | H13: =IF(AND(ISNUMBER($B$13),$B$13>=0,$B$13<=10,$B$13=INT($B$13)),$B$13,0)
A14: b = Temel nüfus = Σc | B14: =$F$79
A15: n = Artış oranı (b<200→0,3 ; b≥200→0,25) | B15: =IF(B14<200,0.3,0.25)
A16: B = Tasarım nüfusu = b+(n×b) | B16: =ROUNDUP(B14*(1+B15),0)
A17: k = Taşınacak insan yüzdesi (Tablo-9) | B17: =IF(AND(LEFT($B$5,4)="Kamu",ISNUMBER($E$5),$E$5>0,$E$5<=1),$E$5,IF($B$6="Manuel k gerekli",IF(AND(ISNUMBER($E$5),$E$5>0,$E$5<=1),$E$5,"Manuel k gerekli"),IFERROR(INDEX('TABLO-9'!$D$2:$E$6,MATCH($B$6,'TABLO-9'!$A$2:$A$6,0),IF($B$8="Standart",1,2)),"Manuel k gerekli")))
A18: V = Kabin hızı (durak = N+1+bodrum, Tablo-2) | B18: =IF(AND(ISNUMBER($D$10),COUNTIF($H$86:$H$95,$D$10)=0),"Manuel V geçersiz — listeden seçin (0,63 / 1 / 1,6 / 1,75 / 2 / 2,5 / 3 / 3,5 / 5 / 6 m/s)",IF(ISNUMBER($D$10),$D$10,IF(ISNUMBER($H$98),$H$98,"Manuel hız gerekli")))
A19: tv = h / V (katlar arası geçiş) | B19: =IFERROR(B12/B18,"Manuel hız gerekli")
A20: tg = Tek kat geçme (Tablo-6, hıza bağlı) | B20: =IFERROR(IF(B18<1,10,IF(B18=1,7,IF(B18=1.6,6,IF(B18=1.75,5.8875,IF(B18=2,5.7,IF(B18=2.5,5.5,IF(B18=3,5.25,IF(B18=3.5,5,IF(B18=5,4.5,IF(B18>5,4.3,"Hız Tablo-6 dışı")))))))))),"Manuel hız gerekli")
A21: → Asansör bazında BODRUM DURAĞI ve İMALATÇI SÜRELERİ (ta/tk/tg/tp) girişleri 99. satırdaki blokta yer alır; normal projede boş bırakılır.
A22: ASANSÖR BAZINDA HESAP (kullanmadığın kolonu boş bırak)
B23: ASANSÖR-1 | C23: ASANSÖR-2 | D23: ASANSÖR-3 | E23: ASANSÖR-4
A24: ⑧ Kabin kapasitesi P (kişi) — her asansör için ayrı | B24: 10 | C24: 16
A25: ⑨ Kapı genişliği (mm) — ta/tk + güncel tp | B25: 900 | C25: 1100
A26: ⑩ Kapı tipi | B26: Teleskopik Otomatik | C26: Teleskopik Otomatik
A27: p = 0,8 × P | B27: =IF(B24="","",0.8*B24) | C27: =IF(C24="","",0.8*C24) | D27: =IF(D24="","",0.8*D24) | E27: =IF(E24="","",0.8*E24)
A28: H = Ort. en yüksek dönüş katı (Tablo-3) | B28: =IF(B24="","",IF(NOT(ISNUMBER(B60)),"Durak geçersiz",IFERROR(INDEX('TABLO-3'!$B$3:$AD$32,MATCH(B60,'TABLO-3'!$A$3:$A$32,0),MATCH(VALUE(B24),'TABLO-3'!$B$2:$AD$2,0)),"P/N aralık dışı"))) | C28: =IF(C24="","",IF(NOT(ISNUMBER(C60)),"Durak geçersiz",IFERROR(INDEX('TABLO-3'!$B$3:$AD$32,MATCH(C60,'TABLO-3'!$A$3:$A$32,0),MATCH(VALUE(C24),'TABLO-3'!$B$2:$AD$2,0)),"P/N aralık dışı"))) | D28: =IF(D24="","",IF(NOT(ISNUMBER(D60)),"Durak geçersiz",IFERROR(INDEX('TABLO-3'!$B$3:$AD$32,MATCH(D60,'TABLO-3'!$A$3:$A$32,0),MATCH(VALUE(D24),'TABLO-3'!$B$2:$AD$2,0)),"P/N aralık dışı"))) | E28: =IF(E24="","",IF(NOT(ISNUMBER(E60)),"Durak geçersiz",IFERROR(INDEX('TABLO-3'!$B$3:$AD$32,MATCH(E60,'TABLO-3'!$A$3:$A$32,0),MATCH(VALUE(E24),'TABLO-3'!$B$2:$AD$2,0)),"P/N aralık dışı")))
A29: S = Ort. durak adedi (Tablo-5) | B29: =IF(B24="","",IF(NOT(ISNUMBER(B60)),"Durak geçersiz",IFERROR(INDEX('TABLO-5'!$B$3:$AD$32,MATCH(B60,'TABLO-5'!$A$3:$A$32,0),MATCH(VALUE(B24),'TABLO-5'!$B$2:$AD$2,0)),"P/N aralık dışı"))) | C29: =IF(C24="","",IF(NOT(ISNUMBER(C60)),"Durak geçersiz",IFERROR(INDEX('TABLO-5'!$B$3:$AD$32,MATCH(C60,'TABLO-5'!$A$3:$A$32,0),MATCH(VALUE(C24),'TABLO-5'!$B$2:$AD$2,0)),"P/N aralık dışı"))) | D29: =IF(D24="","",IF(NOT(ISNUMBER(D60)),"Durak geçersiz",IFERROR(INDEX('TABLO-5'!$B$3:$AD$32,MATCH(D60,'TABLO-5'!$A$3:$A$32,0),MATCH(VALUE(D24),'TABLO-5'!$B$2:$AD$2,0)),"P/N aralık dışı"))) | E29: =IF(E24="","",IF(NOT(ISNUMBER(E60)),"Durak geçersiz",IFERROR(INDEX('TABLO-5'!$B$3:$AD$32,MATCH(E60,'TABLO-5'!$A$3:$A$32,0),MATCH(VALUE(E24),'TABLO-5'!$B$2:$AD$2,0)),"P/N aralık dışı")))
A30: ta = Kapı açılma (Tablo-4) | B30: =IF(B24="","",IF(ISNUMBER(B102),B102,IFERROR(INDEX('TABLO-4'!$I$4:$N$10,MATCH(VALUE(B25),'TABLO-4'!$A$4:$A$10,0),IF(B26="Teleskopik Otomatik",1,IF(OR(B26="Merkezden Açılan Oto.",B26="Merkezden Açılan Otomatik"),3,5))),"Veri yok"))) | C30: =IF(C24="","",IF(ISNUMBER(C102),C102,IFERROR(INDEX('TABLO-4'!$I$4:$N$10,MATCH(VALUE(C25),'TABLO-4'!$A$4:$A$10,0),IF(C26="Teleskopik Otomatik",1,IF(OR(C26="Merkezden Açılan Oto.",C26="Merkezden Açılan Otomatik"),3,5))),"Veri yok"))) | D30: =IF(D24="","",IF(ISNUMBER(D102),D102,IFERROR(INDEX('TABLO-4'!$I$4:$N$10,MATCH(VALUE(D25),'TABLO-4'!$A$4:$A$10,0),IF(D26="Teleskopik Otomatik",1,IF(OR(D26="Merkezden Açılan Oto.",D26="Merkezden Açılan Otomatik"),3,5))),"Veri yok"))) | E30: =IF(E24="","",IF(ISNUMBER(E102),E102,IFERROR(INDEX('TABLO-4'!$I$4:$N$10,MATCH(VALUE(E25),'TABLO-4'!$A$4:$A$10,0),IF(E26="Teleskopik Otomatik",1,IF(OR(E26="Merkezden Açılan Oto.",E26="Merkezden Açılan Otomatik"),3,5))),"Veri yok")))
A31: tk = Kapı kapanma (Tablo-4) | B31: =IF(B24="","",IF(ISNUMBER(B103),B103,IFERROR(INDEX('TABLO-4'!$I$4:$N$10,MATCH(VALUE(B25),'TABLO-4'!$A$4:$A$10,0),IF(B26="Teleskopik Otomatik",2,IF(OR(B26="Merkezden Açılan Oto.",B26="Merkezden Açılan Otomatik"),4,6))),"Veri yok"))) | C31: =IF(C24="","",IF(ISNUMBER(C103),C103,IFERROR(INDEX('TABLO-4'!$I$4:$N$10,MATCH(VALUE(C25),'TABLO-4'!$A$4:$A$10,0),IF(C26="Teleskopik Otomatik",2,IF(OR(C26="Merkezden Açılan Oto.",C26="Merkezden Açılan Otomatik"),4,6))),"Veri yok"))) | D31: =IF(D24="","",IF(ISNUMBER(D103),D103,IFERROR(INDEX('TABLO-4'!$I$4:$N$10,MATCH(VALUE(D25),'TABLO-4'!$A$4:$A$10,0),IF(D26="Teleskopik Otomatik",2,IF(OR(D26="Merkezden Açılan Oto.",D26="Merkezden Açılan Otomatik"),4,6))),"Veri yok"))) | E31: =IF(E24="","",IF(ISNUMBER(E103),E103,IFERROR(INDEX('TABLO-4'!$I$4:$N$10,MATCH(VALUE(E25),'TABLO-4'!$A$4:$A$10,0),IF(E26="Teleskopik Otomatik",2,IF(OR(E26="Merkezden Açılan Oto.",E26="Merkezden Açılan Otomatik"),4,6))),"Veri yok")))
A32: tg = Tek kat geçme (asansör bazında, Tablo-6) | B32: =IF(B24="","",IF(ISNUMBER(B104),B104,IF(B57<1,10,IF(B57=1,7,IF(B57=1.6,6,IF(B57=1.75,5.8875,IF(B57=2,5.7,IF(B57=2.5,5.5,IF(B57=3,5.25,IF(B57=3.5,5,IF(B57=5,4.5,IF(B57>5,4.3,"Hız Tablo-6 dışı")))))))))))) | C32: =IF(C24="","",IF(ISNUMBER(C104),C104,IF(C57<1,10,IF(C57=1,7,IF(C57=1.6,6,IF(C57=1.75,5.8875,IF(C57=2,5.7,IF(C57=2.5,5.5,IF(C57=3,5.25,IF(C57=3.5,5,IF(C57=5,4.5,IF(C57>5,4.3,"Hız Tablo-6 dışı")))))))))))) | D32: =IF(D24="","",IF(ISNUMBER(D104),D104,IF(D57<1,10,IF(D57=1,7,IF(D57=1.6,6,IF(D57=1.75,5.8875,IF(D57=2,5.7,IF(D57=2.5,5.5,IF(D57=3,5.25,IF(D57=3.5,5,IF(D57=5,4.5,IF(D57>5,4.3,"Hız Tablo-6 dışı")))))))))))) | E32: =IF(E24="","",IF(ISNUMBER(E104),E104,IF(E57<1,10,IF(E57=1,7,IF(E57=1.6,6,IF(E57=1.75,5.8875,IF(E57=2,5.7,IF(E57=2.5,5.5,IF(E57=3,5.25,IF(E57=3.5,5,IF(E57=5,4.5,IF(E57>5,4.3,"Hız Tablo-6 dışı"))))))))))))
A33: tp = Kişi transfer (Tablo-8) | B33: =IF(B24="","",IF(ISNUMBER(B105),B105,IFERROR(INDEX('TABLO-8'!$B$2:$H$2,1,MATCH(VALUE(B25),'TABLO-8'!$B$1:$H$1,0)),"tp verisi yok"))) | C33: =IF(C24="","",IF(ISNUMBER(C105),C105,IFERROR(INDEX('TABLO-8'!$B$2:$H$2,1,MATCH(VALUE(C25),'TABLO-8'!$B$1:$H$1,0)),"tp verisi yok"))) | D33: =IF(D24="","",IF(ISNUMBER(D105),D105,IFERROR(INDEX('TABLO-8'!$B$2:$H$2,1,MATCH(VALUE(D25),'TABLO-8'!$B$1:$H$1,0)),"tp verisi yok"))) | E33: =IF(E24="","",IF(ISNUMBER(E105),E105,IFERROR(INDEX('TABLO-8'!$B$2:$H$2,1,MATCH(VALUE(E25),'TABLO-8'!$B$1:$H$1,0)),"tp verisi yok")))
A34: tv = h/V (ortak) | B34: =IF(B24="","",IFERROR(IF(B62="",$B$12,B62)/B57,"Hız geçersiz")) | C34: =IF(C24="","",IFERROR(IF(C62="",$B$12,C62)/C57,"Hız geçersiz")) | D34: =IF(D24="","",IFERROR(IF(D62="",$B$12,D62)/D57,"Hız geçersiz")) | E34: =IF(E24="","",IFERROR(IF(E62="",$B$12,E62)/E57,"Hız geçersiz"))
A35: ts = ta+tk+tg−tv | B35: =IF(B24="","",IFERROR(B30+B31+B32-B34,"?")) | C35: =IF(C24="","",IFERROR(C30+C31+C32-C34,"?")) | D35: =IF(D24="","",IFERROR(D30+D31+D32-D34,"?")) | E35: =IF(E24="","",IFERROR(E30+E31+E32-E34,"?"))
A36: TR = 2·H·tv+(S+1)·ts+2·p·tp | B36: =IF(B24="","",IFERROR(2*B28*B34+(B29+1)*B35+2*B27*B33,"?")) | C36: =IF(C24="","",IFERROR(2*C28*C34+(C29+1)*C35+2*C27*C33,"?")) | D36: =IF(D24="","",IFERROR(2*D28*D34+(D29+1)*D35+2*D27*D33,"?")) | E36: =IF(E24="","",IFERROR(2*E28*E34+(E29+1)*E35+2*E27*E33,"?"))
A37: R = 5·60·p/TR (5 dk taşıma) | B37: =IF(B24="","",IFERROR(5*60*B27/B36,"?")) | C37: =IF(C24="","",IFERROR(5*60*C27/C36,"?")) | D37: =IF(D24="","",IFERROR(5*60*D27/D36,"?")) | E37: =IF(E24="","",IFERROR(5*60*E27/E36,"?"))
A38: Beyan yükü karşılığı (kg, otomatik) | B38: =IF(B24="","",IF(B24=6,450,IF(B24=8,630,IF(B24=10,800,IF(B24=13,1000,IF(B24=15,1125,IF(B24=16,1275,IF(B24=20,1600,IF(B24=25,2000,IF(B24=30,2500,B24*75)))))))))) | C38: =IF(C24="","",IF(C24=6,450,IF(C24=8,630,IF(C24=10,800,IF(C24=13,1000,IF(C24=15,1125,IF(C24=16,1275,IF(C24=20,1600,IF(C24=25,2000,IF(C24=30,2500,C24*75)))))))))) | D38: =IF(D24="","",IF(D24=6,450,IF(D24=8,630,IF(D24=10,800,IF(D24=13,1000,IF(D24=15,1125,IF(D24=16,1275,IF(D24=20,1600,IF(D24=25,2000,IF(D24=30,2500,D24*75)))))))))) | E38: =IF(E24="","",IF(E24=6,450,IF(E24=8,630,IF(E24=10,800,IF(E24=13,1000,IF(E24=15,1125,IF(E24=16,1275,IF(E24=20,1600,IF(E24=25,2000,IF(E24=30,2500,E24*75))))))))))
A39: GRUP KONTROLÜ (MMO/697 s.12)
A40: Reş = ΣR (grubun 5 dk taşıma kapasitesi) | B40: =IF($B$47<>"OK","HESAP HATASI",SUM(B37:E37)) | C40: kişi/5dk
A41: Gereken = B × k (Reş bunu ≥ karşılamalı) | B41: =$B$16*$B$17 | C41: kişi/5dk
...

Sheet PAFTA-COKLU
A1: ÇOKLU ASANSÖR TRAFİK HESABI
A2: ORTAK BİNA BİLGİLERİ
A3: Bina tipi / standart (yükseklikten otomatik) | B3: =IFERROR('ÇOKLU ASANSÖR'!B5&" / "&'ÇOKLU ASANSÖR'!B8,"—")
A4: Kat sayısı N (ana giriş üstü) / bodrum — grup maksimumu | B4: =IFERROR('ÇOKLU ASANSÖR'!B9&IF('ÇOKLU ASANSÖR'!$H$13>0," + "&'ÇOKLU ASANSÖR'!$H$13&" bodrum durağı",""),"—") | F4: kat
A5: =IF('ÇOKLU ASANSÖR'!B5="Konut","Tablo-1: Her dairenin ilk yatak odası için 2 kişi, diğer odaların her biri için 1 kişi alınır; mutfak ve ıslak hacimler hesaba katılmaz.",IF(OR(LEFT('ÇOKLU ASANSÖR'!B5,10)="İş Merkezi",LEFT('ÇOKLU ASANSÖR'!B5,4)="Kamu"),"Tablo-1: Çalışma alanının her 12 m²si için 1 kişi alınır.",IF(LEFT('ÇOKLU ASANSÖR'!B5,4)="Otel","Tablo-1: Her yatak için 1 kişi alınır.",IF('ÇOKLU ASANSÖR'!B5="Hastane","Tablo-1: Her yatak için 3 kişi alınır.",IF('ÇOKLU ASANSÖR'!B5="Katlı Otopark","Tablo-1: Özel amaçlı araç başına 1 kişi, ticari amaçlı araç başına 1,5 kişi alınır.","Nüfus MMO/697 Tablo-1'e göre hesaplanmıştır.")))))
A6: =IF(AND('ÇOKLU ASANSÖR'!B5="Konut",ISNUMBER('ÇOKLU ASANSÖR'!B11)),IF('ÇOKLU ASANSÖR'!B11=INT('ÇOKLU ASANSÖR'!B11),"Daireler "&'ÇOKLU ASANSÖR'!B11&"+1 olup bir dairede sayılan oda adedi "&('ÇOKLU ASANSÖR'!B11+1)&" olarak alınmıştır (1 ilk yatak odası + "&'ÇOKLU ASANSÖR'!B11&" diğer oda). Bir dairedeki kişi sayısı = 2 + ("&'ÇOKLU ASANSÖR'!B11&" × 1) = "&(2+'ÇOKLU ASANSÖR'!B11)&" kişi.","Daire başına ortalama diğer oda adedi "&INT(ROUND('ÇOKLU ASANSÖR'!B11,2))&","&TEXT(MOD(ROUND('ÇOKLU ASANSÖR'!B11*100,0),100),"00")&" alınmıştır. Bir dairedeki ortalama kişi sayısı = 2 + "&INT(ROUND('ÇOKLU ASANSÖR'!B11,2))&","&TEXT(MOD(ROUND('ÇOKLU ASANSÖR'!B11*100,0),100),"00")&" = "&INT(ROUND((2+'ÇOKLU ASANSÖR'!B11),2))&","&TEXT(MOD(ROUND((2+'ÇOKLU ASANSÖR'!B11)*100,0),100),"00")&" kişi."),IF(AND(OR(LEFT('ÇOKLU ASANSÖR'!B5,10)="İş Merkezi",LEFT('ÇOKLU ASANSÖR'!B5,4)="Kamu"),ISNUMBER('ÇOKLU ASANSÖR'!B10)),"Binadaki toplam çalışma alanı "&IF('ÇOKLU ASANSÖR'!B10=INT('ÇOKLU ASANSÖR'!B10),'ÇOKLU ASANSÖR'!B10&"",INT(ROUND('ÇOKLU ASANSÖR'!B10,2))&","&TEXT(MOD(ROUND('ÇOKLU ASANSÖR'!B10*100,0),100),"00"))&" m² olarak alınmıştır.",IF(AND(OR(LEFT('ÇOKLU ASANSÖR'!B5,4)="Otel",'ÇOKLU ASANSÖR'!B5="Hastane"),ISNUMBER('ÇOKLU ASANSÖR'!B10)),"Binadaki toplam yatak sayısı "&IF('ÇOKLU ASANSÖR'!B10=INT('ÇOKLU ASANSÖR'!B10),'ÇOKLU ASANSÖR'!B10&"",INT(ROUND('ÇOKLU ASANSÖR'!B10,2))&","&TEXT(MOD(ROUND('ÇOKLU ASANSÖR'!B10*100,0),100),"00"))&" olarak alınmıştır.",IF(AND('ÇOKLU ASANSÖR'!B5="Katlı Otopark",ISNUMBER('ÇOKLU ASANSÖR'!B10)),"Özel amaçlı araç adedi "&IF('ÇOKLU ASANSÖR'!B10=INT('ÇOKLU ASANSÖR'!B10),'ÇOKLU ASANSÖR'!B10&"",INT(ROUND('ÇOKLU ASANSÖR'!B10,2))&","&TEXT(MOD(ROUND('ÇOKLU ASANSÖR'!B10*100,0),100),"00"))&", ticari amaçlı araç adedi "&IF(ISNUMBER('ÇOKLU ASANSÖR'!B11),IF('ÇOKLU ASANSÖR'!B11=INT('ÇOKLU ASANSÖR'!B11),'ÇOKLU ASANSÖR'!B11&"",INT(ROUND('ÇOKLU ASANSÖR'!B11,2))&","&TEXT(MOD(ROUND('ÇOKLU ASANSÖR'!B11*100,0),100),"00"))&"","0")&" olarak alınmıştır.","Nüfus, hesap sayfasındaki ayrıntılı tablodan alınmıştır."))))
A7: =IF(NOT(ISNUMBER('ÇOKLU ASANSÖR'!B14)),"",IF(AND(ISNUMBER('ÇOKLU ASANSÖR'!B10),ABS('ÇOKLU ASANSÖR'!B14-(IF('ÇOKLU ASANSÖR'!B5="Konut",'ÇOKLU ASANSÖR'!B10*(2+'ÇOKLU ASANSÖR'!B11),IF(OR(LEFT('ÇOKLU ASANSÖR'!B5,10)="İş Merkezi",LEFT('ÇOKLU ASANSÖR'!B5,4)="Kamu"),'ÇOKLU ASANSÖR'!B10/12,IF(LEFT('ÇOKLU ASANSÖR'!B5,4)="Otel",'ÇOKLU ASANSÖR'!B10,IF('ÇOKLU ASANSÖR'!B5="Hastane",'ÇOKLU ASANSÖR'!B10*3,IF('ÇOKLU ASANSÖR'!B5="Katlı Otopark",'ÇOKLU ASANSÖR'!B10+IF(ISNUMBER('ÇOKLU ASANSÖR'!B11),'ÇOKLU ASANSÖR'!B11*1.5,0),-1)))))))<0.01),IF('ÇOKLU ASANSÖR'!B5="Konut","Daire adedi "&IF('ÇOKLU ASANSÖR'!B10=INT('ÇOKLU ASANSÖR'!B10),'ÇOKLU ASANSÖR'!B10&"",INT(ROUND('ÇOKLU ASANSÖR'!B10,2))&","&TEXT(MOD(ROUND('ÇOKLU ASANSÖR'!B10*100,0),100),"00"))&" → b = "&IF('ÇOKLU ASANSÖR'!B10=INT('ÇOKLU ASANSÖR'!B10),'ÇOKLU ASANSÖR'!B10&"",INT(ROUND('ÇOKLU ASANSÖR'!B10,2))&","&TEXT(MOD(ROUND('ÇOKLU ASANSÖR'!B10*100,0),100),"00"))&" × "&IF((2+'ÇOKLU ASANSÖR'!B11)=INT((2+'ÇOKLU ASANSÖR'!B11)),(2+'ÇOKLU ASANSÖR'!B11)&"",INT(ROUND((2+'ÇOKLU ASANSÖR'!B11),2))&","&TEXT(MOD(ROUND((2+'ÇOKLU ASANSÖR'!B11)*100,0),100),"00"))&" = "&IF('ÇOKLU ASANSÖR'!B14=INT('ÇOKLU ASANSÖR'!B14),'ÇOKLU ASANSÖR'!B14&"",INT(ROUND('ÇOKLU ASANSÖR'!B14,2))&","&TEXT(MOD(ROUND('ÇOKLU ASANSÖR'!B14*100,0),100),"00"))&" kişi",IF(OR(LEFT('ÇOKLU ASANSÖR'!B5,10)="İş Merkezi",LEFT('ÇOKLU ASANSÖR'!B5,4)="Kamu"),"b = "&IF('ÇOKLU ASANSÖR'!B10=INT('ÇOKLU ASANSÖR'!B10),'ÇOKLU ASANSÖR'!B10&"",INT(ROUND('ÇOKLU ASANSÖR'!B10,2))&","&TEXT(MOD(ROUND('ÇOKLU ASANSÖR'!B10*100,0),100),"00"))&" ÷ 12 = "&IF('ÇOKLU ASANSÖR'!B14=INT('ÇOKLU ASANSÖR'!B14),'ÇOKLU ASANSÖR'!B14&"",INT(ROUND('ÇOKLU ASANSÖR'!B14,2))&","&TEXT(MOD(ROUND('ÇOKLU ASANSÖR'!B14*100,0),100),"00"))&" kişi",IF(LEFT('ÇOKLU ASANSÖR'!B5,4)="Otel","b = "&IF('ÇOKLU ASANSÖR'!B10=INT('ÇOKLU ASANSÖR'!B10),'ÇOKLU ASANSÖR'!B10&"",INT(ROUND('ÇOKLU ASANSÖR'!B10,2))&","&TEXT(MOD(ROUND('ÇOKLU ASANSÖR'!B10*100,0),100),"00"))&" × 1 = "&IF('ÇOKLU ASANSÖR'!B14=INT('ÇOKLU ASANSÖR'!B14),'ÇOKLU ASANSÖR'!B14&"",INT(ROUND('ÇOKLU ASANSÖR'!B14,2))&","&TEXT(MOD(ROUND('ÇOKLU ASANSÖR'!B14*100,0),100),"00"))&" kişi",IF('ÇOKLU ASANSÖR'!B5="Hastane","b = "&IF('ÇOKLU ASANSÖR'!B10=INT('ÇOKLU ASANSÖR'!B10),'ÇOKLU ASANSÖR'!B10&"",INT(ROUND('ÇOKLU ASANSÖR'!B10,2))&","&TEXT(MOD(ROUND('ÇOKLU ASANSÖR'!B10*100,0),100),"00"))&" × 3 = "&IF('ÇOKLU ASANSÖR'!B14=INT('ÇOKLU ASANSÖR'!B14),'ÇOKLU ASANSÖR'!B14&"",INT(ROUND('ÇOKLU ASANSÖR'!B14,2))&","&TEXT(MOD(ROUND('ÇOKLU ASANSÖR'!B14*100,0),100),"00"))&" kişi","b = ("&IF('ÇOKLU ASANSÖR'!B10=INT('ÇOKLU ASANSÖR'!B10),'ÇOKLU ASANSÖR'!B10&"",INT(ROUND('ÇOKLU ASANSÖR'!B10,2))&","&TEXT(MOD(ROUND('ÇOKLU ASANSÖR'!B10*100,0),100),"00"))&" × 1) + ("&IF(ISNUMBER('ÇOKLU ASANSÖR'!B11),IF('ÇOKLU ASANSÖR'!B11=INT('ÇOKLU ASANSÖR'!B11),'ÇOKLU ASANSÖR'!B11&"",INT(ROUND('ÇOKLU ASANSÖR'!B11,2))&","&TEXT(MOD(ROUND('ÇOKLU ASANSÖR'!B11*100,0),100),"00"))&"","0")&" × 1,5) = "&IF('ÇOKLU ASANSÖR'!B14=INT('ÇOKLU ASANSÖR'!B14),'ÇOKLU ASANSÖR'!B14&"",INT(ROUND('ÇOKLU ASANSÖR'!B14,2))&","&TEXT(MOD(ROUND('ÇOKLU ASANSÖR'!B14*100,0),100),"00"))&" kişi")))),"b = Σc = "&IF('ÇOKLU ASANSÖR'!B14=INT('ÇOKLU ASANSÖR'!B14),'ÇOKLU ASANSÖR'!B14&"",INT(ROUND('ÇOKLU ASANSÖR'!B14,2))&","&TEXT(MOD(ROUND('ÇOKLU ASANSÖR'!B14*100,0),100),"00"))&" kişi (hesap sayfasındaki ayrıntılı nüfus tablosundan)"))
A8: b = Sürekli kişi / n = artış | B8: =IFERROR(IF('ÇOKLU ASANSÖR'!B14=INT('ÇOKLU ASANSÖR'!B14),'ÇOKLU ASANSÖR'!B14&"",INT(ROUND('ÇOKLU ASANSÖR'!B14,2))&","&TEXT(MOD(ROUND('ÇOKLU ASANSÖR'!B14*100,0),100),"00"))&" kişi / "&INT(ROUND('ÇOKLU ASANSÖR'!B15,2))&","&TEXT(MOD(ROUND('ÇOKLU ASANSÖR'!B15*100,0),100),"00"),"—")
A9: ="B = b + (n·b) = "&'ÇOKLU ASANSÖR'!B14&" + ("&INT(ROUND('ÇOKLU ASANSÖR'!B15,2))&","&TEXT(MOD(ROUND('ÇOKLU ASANSÖR'!B15*100,0),100),"00")&"·"&'ÇOKLU ASANSÖR'!B14&") = "&INT(ROUND('ÇOKLU ASANSÖR'!B16,1))&","&TEXT(MOD(ROUND('ÇOKLU ASANSÖR'!B16*10,0),10),"0")&" kişi"
A10: k = Taşınacak insan yüzdesi | B10: =IFERROR('ÇOKLU ASANSÖR'!B17,"—") | F10: Tablo-9
A11: V = Kabin hızı (asansör bazında) | B11: =IFERROR(TRIM(IF('ÇOKLU ASANSÖR'!B24<>"","A1: "&IF(ISNUMBER('ÇOKLU ASANSÖR'!B57),INT(ROUND('ÇOKLU ASANSÖR'!B57,2))&","&TEXT(MOD(ROUND('ÇOKLU ASANSÖR'!B57*100,0),100),"00"),'ÇOKLU ASANSÖR'!B57)&" m/s","")&IF('ÇOKLU ASANSÖR'!C24<>""," | A2: "&IF(ISNUMBER('ÇOKLU ASANSÖR'!C57),INT(ROUND('ÇOKLU ASANSÖR'!C57,2))&","&TEXT(MOD(ROUND('ÇOKLU ASANSÖR'!C57*100,0),100),"00"),'ÇOKLU ASANSÖR'!C57)&" m/s","")&IF('ÇOKLU ASANSÖR'!D24<>""," | A3: "&IF(ISNUMBER('ÇOKLU ASANSÖR'!D57),INT(ROUND('ÇOKLU ASANSÖR'!D57,2))&","&TEXT(MOD(ROUND('ÇOKLU ASANSÖR'!D57*100,0),100),"00"),'ÇOKLU ASANSÖR'!D57)&" m/s","")&IF('ÇOKLU ASANSÖR'!E24<>""," | A4: "&IF(ISNUMBER('ÇOKLU ASANSÖR'!E57),INT(ROUND('ÇOKLU ASANSÖR'!E57,2))&","&TEXT(MOD(ROUND('ÇOKLU ASANSÖR'!E57*100,0),100),"00"),'ÇOKLU ASANSÖR'!E57)&" m/s","")),"—") | F11: Tablo-2
A12: ASANSÖR BAZINDA HESAP
B13: =IF('ÇOKLU ASANSÖR'!B24="","","ASANSÖR-1") | C13: =IF('ÇOKLU ASANSÖR'!C24="","","ASANSÖR-2") | D13: =IF('ÇOKLU ASANSÖR'!D24="","","ASANSÖR-3") | E13: =IF('ÇOKLU ASANSÖR'!E24="","","ASANSÖR-4") | F13: Kaynak
A14: P = Kabin kapasitesi (kişi) | B14: =IFERROR(IF('ÇOKLU ASANSÖR'!B24="","",'ÇOKLU ASANSÖR'!B24),"—") | C14: =IFERROR(IF('ÇOKLU ASANSÖR'!C24="","",'ÇOKLU ASANSÖR'!C24),"—") | D14: =IFERROR(IF('ÇOKLU ASANSÖR'!D24="","",'ÇOKLU ASANSÖR'!D24),"—") | E14: =IFERROR(IF('ÇOKLU ASANSÖR'!E24="","",'ÇOKLU ASANSÖR'!E24),"—") | F14: =IF(COUNTIF('ÇOKLU ASANSÖR'!B24:E24,15)>0,"15 kişi: MMO örn. s.53-54 (Tablo-7 dışı)","Tablo-7")
A15: Kapı genişliği (mm) | B15: =IFERROR(IF('ÇOKLU ASANSÖR'!B24="","",'ÇOKLU ASANSÖR'!B25),"—") | C15: =IFERROR(IF('ÇOKLU ASANSÖR'!C24="","",'ÇOKLU ASANSÖR'!C25),"—") | D15: =IFERROR(IF('ÇOKLU ASANSÖR'!D24="","",'ÇOKLU ASANSÖR'!D25),"—") | E15: =IFERROR(IF('ÇOKLU ASANSÖR'!E24="","",'ÇOKLU ASANSÖR'!E25),"—") | F15: Projeden
A16: h = Katlar arası mesafe (m) | B16: =IFERROR(IF('ÇOKLU ASANSÖR'!B24="","",INT(ROUND(IF('ÇOKLU ASANSÖR'!B62="",'ÇOKLU ASANSÖR'!$B$12,'ÇOKLU ASANSÖR'!B62),2))&","&TEXT(MOD(ROUND(IF('ÇOKLU ASANSÖR'!B62="",'ÇOKLU ASANSÖR'!$B$12,'ÇOKLU ASANSÖR'!B62)*100,0),100),"00")),"—") | C16: =IFERROR(IF('ÇOKLU ASANSÖR'!C24="","",INT(ROUND(IF('ÇOKLU ASANSÖR'!C62="",'ÇOKLU ASANSÖR'!$B$12,'ÇOKLU ASANSÖR'!C62),2))&","&TEXT(MOD(ROUND(IF('ÇOKLU ASANSÖR'!C62="",'ÇOKLU ASANSÖR'!$B$12,'ÇOKLU ASANSÖR'!C62)*100,0),100),"00")),"—") | D16: =IFERROR(IF('ÇOKLU ASANSÖR'!D24="","",INT(ROUND(IF('ÇOKLU ASANSÖR'!D62="",'ÇOKLU ASANSÖR'!$B$12,'ÇOKLU ASANSÖR'!D62),2))&","&TEXT(MOD(ROUND(IF('ÇOKLU ASANSÖR'!D62="",'ÇOKLU ASANSÖR'!$B$12,'ÇOKLU ASANSÖR'!D62)*100,0),100),"00")),"—") | E16: =IFERROR(IF('ÇOKLU ASANSÖR'!E24="","",INT(ROUND(IF('ÇOKLU ASANSÖR'!E62="",'ÇOKLU ASANSÖR'!$B$12,'ÇOKLU ASANSÖR'!E62),2))&","&TEXT(MOD(ROUND(IF('ÇOKLU ASANSÖR'!E62="",'ÇOKLU ASANSÖR'!$B$12,'ÇOKLU ASANSÖR'!E62)*100,0),100),"00")),"—") | F16: Projeden
A17: p = 0,8·P | B17: =IFERROR(IF('ÇOKLU ASANSÖR'!B24="","",'ÇOKLU ASANSÖR'!B27),"—") | C17: =IFERROR(IF('ÇOKLU ASANSÖR'!C24="","",'ÇOKLU ASANSÖR'!C27),"—") | D17: =IFERROR(IF('ÇOKLU ASANSÖR'!D24="","",'ÇOKLU ASANSÖR'!D27),"—") | E17: =IFERROR(IF('ÇOKLU ASANSÖR'!E24="","",'ÇOKLU ASANSÖR'!E27),"—") | F17: MMO/697
A18: H = Ort. en yüksek dönüş katı | B18: =IFERROR(IF('ÇOKLU ASANSÖR'!B24="","",'ÇOKLU ASANSÖR'!B28),"—") | C18: =IFERROR(IF('ÇOKLU ASANSÖR'!C24="","",'ÇOKLU ASANSÖR'!C28),"—") | D18: =IFERROR(IF('ÇOKLU ASANSÖR'!D24="","",'ÇOKLU ASANSÖR'!D28),"—") | E18: =IFERROR(IF('ÇOKLU ASANSÖR'!E24="","",'ÇOKLU ASANSÖR'!E28),"—") | F18: Tablo-3 (Ni)
A19: S = Ortalama durak adedi | B19: =IFERROR(IF('ÇOKLU ASANSÖR'!B24="","",'ÇOKLU ASANSÖR'!B29),"—") | C19: =IFERROR(IF('ÇOKLU ASANSÖR'!C24="","",'ÇOKLU ASANSÖR'!C29),"—") | D19: =IFERROR(IF('ÇOKLU ASANSÖR'!D24="","",'ÇOKLU ASANSÖR'!D29),"—") | E19: =IFERROR(IF('ÇOKLU ASANSÖR'!E24="","",'ÇOKLU ASANSÖR'!E29),"—") | F19: Tablo-5 (Ni)
A20: ta / tk (kapı aç/kapa) | B20: =IFERROR(IF('ÇOKLU ASANSÖR'!B24="","",INT(ROUND('ÇOKLU ASANSÖR'!B30,1))&","&TEXT(MOD(ROUND('ÇOKLU ASANSÖR'!B30*10,0),10),"0")&" / "&INT(ROUND('ÇOKLU ASANSÖR'!B31,1))&","&TEXT(MOD(ROUND('ÇOKLU ASANSÖR'!B31*10,0),10),"0")),"—") | C20: =IFERROR(IF('ÇOKLU ASANSÖR'!C24="","",INT(ROUND('ÇOKLU ASANSÖR'!C30,1))&","&TEXT(MOD(ROUND('ÇOKLU ASANSÖR'!C30*10,0),10),"0")&" / "&INT(ROUND('ÇOKLU ASANSÖR'!C31,1))&","&TEXT(MOD(ROUND('ÇOKLU ASANSÖR'!C31*10,0),10),"0")),"—") | D20: =IFERROR(IF('ÇOKLU ASANSÖR'!D24="","",INT(ROUND('ÇOKLU ASANSÖR'!D30,1))&","&TEXT(MOD(ROUND('ÇOKLU ASANSÖR'!D30*10,0),10),"0")&" / "&INT(ROUND('ÇOKLU ASANSÖR'!D31,1))&","&TEXT(MOD(ROUND('ÇOKLU ASANSÖR'!D31*10,0),10),"0")),"—") | E20: =IFERROR(IF('ÇOKLU ASANSÖR'!E24="","",INT(ROUND('ÇOKLU ASANSÖR'!E30,1))&","&TEXT(MOD(ROUND('ÇOKLU ASANSÖR'!E30*10,0),10),"0")&" / "&INT(ROUND('ÇOKLU ASANSÖR'!E31,1))&","&TEXT(MOD(ROUND('ÇOKLU ASANSÖR'!E31*10,0),10),"0")),"—") | F20: =IF(COUNT('ÇOKLU ASANSÖR'!B102:E103)>0,"Tablo-4 / imalatçı verisi","Tablo-4")
A21: tg / tp (geçiş / transfer) | B21: =IFERROR(IF('ÇOKLU ASANSÖR'!B24="","",INT(ROUND('ÇOKLU ASANSÖR'!B32,1))&","&TEXT(MOD(ROUND('ÇOKLU ASANSÖR'!B32*10,0),10),"0")&" / "&INT(ROUND('ÇOKLU ASANSÖR'!B33,1))&","&TEXT(MOD(ROUND('ÇOKLU ASANSÖR'!B33*10,0),10),"0")),"—") | C21: =IFERROR(IF('ÇOKLU ASANSÖR'!C24="","",INT(ROUND('ÇOKLU ASANSÖR'!C32,1))&","&TEXT(MOD(ROUND('ÇOKLU ASANSÖR'!C32*10,0),10),"0")&" / "&INT(ROUND('ÇOKLU ASANSÖR'!C33,1))&","&TEXT(MOD(ROUND('ÇOKLU ASANSÖR'!C33*10,0),10),"0")),"—") | D21: =IFERROR(IF('ÇOKLU ASANSÖR'!D24="","",INT(ROUND('ÇOKLU ASANSÖR'!D32,1))&","&TEXT(MOD(ROUND('ÇOKLU ASANSÖR'!D32*10,0),10),"0")&" / "&INT(ROUND('ÇOKLU ASANSÖR'!D33,1))&","&TEXT(MOD(ROUND('ÇOKLU ASANSÖR'!D33*10,0),10),"0")),"—") | E21: =IFERROR(IF('ÇOKLU ASANSÖR'!E24="","",INT(ROUND('ÇOKLU ASANSÖR'!E32,1))&","&TEXT(MOD(ROUND('ÇOKLU ASANSÖR'!E32*10,0),10),"0")&" / "&INT(ROUND('ÇOKLU ASANSÖR'!E33,1))&","&TEXT(MOD(ROUND('ÇOKLU ASANSÖR'!E33*10,0),10),"0")),"—") | F21: =IF(COUNT('ÇOKLU ASANSÖR'!B104:E105)>0,"MMO T-6 / ISO 8100-32 T-6 / imalatçı","MMO T-6 / ISO 8100-32 T-6")
A22: ts = ta+tk+tg−tv | B22: =IFERROR(IF('ÇOKLU ASANSÖR'!B24="","",'ÇOKLU ASANSÖR'!B35),"—") | C22: =IFERROR(IF('ÇOKLU ASANSÖR'!C24="","",'ÇOKLU ASANSÖR'!C35),"—") | D22: =IFERROR(IF('ÇOKLU ASANSÖR'!D24="","",'ÇOKLU ASANSÖR'!D35),"—") | E22: =IFERROR(IF('ÇOKLU ASANSÖR'!E24="","",'ÇOKLU ASANSÖR'!E35),"—")
A23: TR = 2·H·tv+(S+1)·ts+2·p·tp (s) | B23: =IFERROR(IF('ÇOKLU ASANSÖR'!B24="","",'ÇOKLU ASANSÖR'!B36),"—") | C23: =IFERROR(IF('ÇOKLU ASANSÖR'!C24="","",'ÇOKLU ASANSÖR'!C36),"—") | D23: =IFERROR(IF('ÇOKLU ASANSÖR'!D24="","",'ÇOKLU ASANSÖR'!D36),"—") | E23: =IFERROR(IF('ÇOKLU ASANSÖR'!E24="","",'ÇOKLU ASANSÖR'!E36),"—")
A24: R = 5·60·p / TR (kişi/5dk) | B24: =IFERROR(IF('ÇOKLU ASANSÖR'!B24="","",'ÇOKLU ASANSÖR'!B37),"—") | C24: =IFERROR(IF('ÇOKLU ASANSÖR'!C24="","",'ÇOKLU ASANSÖR'!C37),"—") | D24: =IFERROR(IF('ÇOKLU ASANSÖR'!D24="","",'ÇOKLU ASANSÖR'!D37),"—") | E24: =IFERROR(IF('ÇOKLU ASANSÖR'!E24="","",'ÇOKLU ASANSÖR'!E37),"—")
A25: GRUP KONTROLÜ — MMO/697 s.12 (farklı kapasiteli asansörler)
A26: Reş = ΣRi ≥ B·k ve 1/TReş = Σ(1/TRi), TReş ≤ Izul
A27: =IF('ÇOKLU ASANSÖR'!$B$47<>"OK",'ÇOKLU ASANSÖR'!$B$47,"Reş = "&IF('ÇOKLU ASANSÖR'!B24<>"","R1="&INT(ROUND('ÇOKLU ASANSÖR'!B37,1))&","&TEXT(MOD(ROUND('ÇOKLU ASANSÖR'!B37*10,0),10),"0"),"")&IF('ÇOKLU ASANSÖR'!C24<>"",IF('ÇOKLU ASANSÖR'!B24<>""," + ","")&"R2="&INT(ROUND('ÇOKLU ASANSÖR'!C37,1))&","&TEXT(MOD(ROUND('ÇOKLU ASANSÖR'!C37*10,0),10),"0"),"")&IF('ÇOKLU ASANSÖR'!D24<>"",IF(COUNT('ÇOKLU ASANSÖR'!B24:C24)>0," + ","")&"R3="&INT(ROUND('ÇOKLU ASANSÖR'!D37,1))&","&TEXT(MOD(ROUND('ÇOKLU ASANSÖR'!D37*10,0),10),"0"),"")&IF('ÇOKLU ASANSÖR'!E24<>"",IF(COUNT('ÇOKLU ASANSÖR'!B24:D24)>0," + ","")&"R4="&INT(ROUND('ÇOKLU ASANSÖR'!E37,1))&","&TEXT(MOD(ROUND('ÇOKLU ASANSÖR'!E37*10,0),10),"0"),"")&" = "&INT(ROUND('ÇOKLU ASANSÖR'!B40,1))&","&TEXT(MOD(ROUND('ÇOKLU ASANSÖR'!B40*10,0),10),"0")&" ≥ B·k = "&INT(ROUND('ÇOKLU ASANSÖR'!B41,1))&","&TEXT(MOD(ROUND('ÇOKLU ASANSÖR'!B41*10,0),10),"0")&" → "&IF('ÇOKLU ASANSÖR'!B40>='ÇOKLU ASANSÖR'!B41,"SAĞLANIYOR","SAĞLANMIYOR"))
A28: =IF('ÇOKLU ASANSÖR'!$B$47<>"OK",'ÇOKLU ASANSÖR'!$B$47,"1/TReş = "&IF('ÇOKLU ASANSÖR'!B24<>"","1/TR1 (1/"&INT(ROUND('ÇOKLU ASANSÖR'!B36,1))&","&TEXT(MOD(ROUND('ÇOKLU ASANSÖR'!B36*10,0),10),"0")&")","")&IF('ÇOKLU ASANSÖR'!C24<>"",IF('ÇOKLU ASANSÖR'!B24<>""," + ","")&"1/TR2 (1/"&INT(ROUND('ÇOKLU ASANSÖR'!C36,1))&","&TEXT(MOD(ROUND('ÇOKLU ASANSÖR'!C36*10,0),10),"0")&")","")&IF('ÇOKLU ASANSÖR'!D24<>"",IF(COUNT('ÇOKLU ASANSÖR'!B24:C24)>0," + ","")&"1/TR3 (1/"&INT(ROUND('ÇOKLU ASANSÖR'!D36,1))&","&TEXT(MOD(ROUND('ÇOKLU ASANSÖR'!D36*10,0),10),"0")&")","")&IF('ÇOKLU ASANSÖR'!E24<>"",IF(COUNT('ÇOKLU ASANSÖR'!B24:D24)>0," + ","")&"1/TR4 (1/"&INT(ROUND('ÇOKLU ASANSÖR'!E36,1))&","&TEXT(MOD(ROUND('ÇOKLU ASANSÖR'!E36*10,0),10),"0")&")","")&" → TReş = "&INT(ROUND('ÇOKLU ASANSÖR'!B43,1))&","&TEXT(MOD(ROUND('ÇOKLU ASANSÖR'!B43*10,0),10),"0")&" s ≤ Izul = "&'ÇOKLU ASANSÖR'!B44&" s → "&IF('ÇOKLU ASANSÖR'!B43<='ÇOKLU ASANSÖR'!B44,"SAĞLANIYOR","SAĞLANMIYOR"))
A29: ='ÇOKLU ASANSÖR'!B53
A30: ='ÇOKLU ASANSÖR'!B54

Sheet NÜFUS GİRİŞİ
A1: MMO/697 NÜFUS KATSAYILARI — YARDIMCI REFERANS
A2: Nüfus girdileri artık HESAPLAMA ve ÇOKLU ASANSÖR sayfalarının altındaki ayrıntılı tablolara girilir. Bu sayfa yalnız katsayı kaynağıdır.
A3: TABLO-1 KATSAYI EŞLEMESİ | E3: KULLANIM NOTLARI
A4: Kalem | B4: Birim | C4: Kişi katsayısı | E4: Konut: Her bağımsız bölümün ilk yatak odasını ve diğer odalarını ayrı miktarlar olarak girin.
A5: KONUT — İlk yatak odası | B5: oda | C5: 2 | E5: İş merkezi / resmî bina: Miktar alanına toplam çalışma alanını m² olarak girin; katsayı 1/12'dir.
A6: KONUT — Diğer oda | B6: oda | C6: 1 | E6: Karma yapı: Her kullanım kalemini ayrı satıra ekleyin. Tablo-9'da k yoksa manuel k zorunludur.
A7: OTEL — Yatak | B7: yatak | C7: 1 | E7: DOĞRUDAN KİŞİ kalemi MMO/697 Tablo-1 dışındaki proje verileri içindir; mühendislik gerekçesini açıklama alanına yazın.
A8: İŞ MERKEZİ — Çalışma alanı | B8: m² | C8: 0.083333333 | E8: HIZLI GİRİŞ: HESAPLAMA ve ÇOKLU ASANSÖR sayfalarındaki ⑤/⑥ kutuları bina tipine göre doğru Tablo-1 kalemini kendisi seçer; bu tabloya yalnız karma/istisnai nüfus için satır eklenir.
A9: HASTANE — Yatak | B9: yatak | C9: 3
A10: RESMİ BİNA — Çalışma alanı | B10: m² | C10: 0.083333333
A11: OTOPARK — Ticari araç | B11: araç | C11: 1.5
A12: OTOPARK — Özel araç | B12: araç | C12: 1
A13: DOĞRUDAN KİŞİ — Tablo-1 dışı | B13: kişi | C13: 1

Sheet KAYNAKLAR
A1: HESAP VE UYUM KAYNAKLARI
A3: Konu | B3: Kaynak | C3: Konum | D3: Uygulama notu
A4: Ana trafik hesabı | B4: MMO/697 — Asansör Avan Projesi Hazırlama Teknik Esasları, 2. Baskı, Ocak 2020 | C4: s.11-17 | D4: TR, R, H, S, p, Tablo 1-10 ve b=Σc
A5: Yüksek bina tanımı | B5: Binaların Yangından Korunması Hakkında Yönetmelik Kılavuzu | C5: md.4 / PDF s.15 | D5: Bina yüksekliği >21,50 m veya yapı yüksekliği >30,50 m ise yüksek bina
A6: Resmî kaynak URL | B6: https://webdosya.csb.gov.tr/v2/meslekihizmetler/2026/05/Binalar-n-Yang-n-Korunmas-Hakk-nda-Y-netmelik-K-lavuzu-20260507112134.pdf | C6: ÇŞİDB Mesleki Hizmetler Genel Müdürlüğü | D6: Yüksek bina ölçütü çalışma kitabında otomatik standarda dönüştürülür
A7: 15 kişi / 1125 kg | B7: MMO/697 örnek proje | C7: s.53-54 | D7: Tablo-7 kaydı değildir; örnek istisnası olarak etiketlenir
A8: Basılı TR₁ aritmetiği | B8: MMO/697 örnek proje | C8: s.54 | D8: Basılı 149,9955 s yerine kitabın eski tp=2,2 s girdileriyle denklem sonucu yaklaşık 174,03 s'dir; güncel tp tablosunda TR değişir
A9: Kişi transfer zamanı (tp) | B9: ISO 8100-32:2020, "Lifts — Part 32: Planning and selection of passenger lifts to be installed in office, hotel and residential buildings", Tablo 6 | C9: Tablo-8 | D9: 800 mm: 1,2 s | 900 mm: 1,1 s | 1000-1100 mm: 1,0 s | 1200-1300 mm: 0,9 s. 800 mm satırı ISO/CD 8100-32 (2017) Tablo 6 ve Barney/Peters (2018) Tablo 3 ile teyitlidir; 1300 mm, 1200 mm değerinin düz devamıdır.
A10: Not: Yükseklik değerleri mimari projeden ayrı ayrı girilmelidir; N×h yaklaşımı bina/yapı yüksekliği tanımlarının yerine kullanılmaz.
A11: Bina yüksekliği nedir | B11: Binanın kot aldığı noktadan saçak seviyesine kadar olan mesafedir; bodrum katlar bu ölçüye girmez. | C11: BYKHY md.4 | D11: HESAPLAMA E8 / ÇOKLU ASANSÖR D8 hücresine yazılır.
A12: Yapı yüksekliği nedir | B12: Bodrum katlar, asma katlar ve çatı arası piyesler dâhil, yapının inşa edilen bütün katlarının toplam yüksekliğidir. Bu nedenle yapı yüksekliği ≥ bina yüksekliği; bodrumsuz binada ikisi eşittir. | C12: BYKHY md.4 | D12: HESAPLAMA E9 / ÇOKLU ASANSÖR D9 hücresine yazılır.
A13: Neden ikisi de soruluyor | B13: Yüksek bina ölçütü iki koşuldan BİRİ aşılınca oluşur: bina yüksekliği > 21,50 m VEYA yapı yüksekliği > 30,50 m. Örnek: 3 bodrum (9 m) + zemin + 6 normal kat (21 m) → bina yüksekliği 21 m ile sınırın altındadır, ancak bir bodrum daha eklenince yapı yüksekliği 33 m olur ve bina yüksek bina sınıfına girer. | C13: BYKHY md.4 | D13: Yüksek binada HESAPLAMA C8 'Yükseltilmiş'e döner: k yüzdesi artar, Tablo-10 bekleme sınırı düşer (kamu binasında 40 → 30 sn); sonuç genelde daha fazla asansördür.
A14: Sık yapılan hata | B14: N × h çarpımı yükseklik yerine kullanılamaz. N yalnızca ana giriş üstündeki kat adedidir, bodrumları içermez; iki yükseklik değeri mimari projeden ayrı ayrı okunur. | C14: MMO/697 + BYKHY | D14: Emin olunamayan durumda büyük değeri yapı yüksekliğine yazın — eksik yazmak kriteri gevşetir.
A16: BU DOSYA NASIL KULLANILIR — KULLANIM SENARYOLARI
A17: Durum | B17: Hangi sayfayı doldurursun | C17: Çıktı (PDF'e basılan) | D17: Not
A18: TEK ASANSÖR | B18: HESAPLAMA | C18: PAFTA | D18: Kabini ve hızı sen verirsin, gereken adedi hesap bulur: n = MAX[taşıma adedi ; bekleme adedi].
A19: BİRDEN FAZLA ASANSÖR | B19: ÇOKLU ASANSÖR | C19: PAFTA-COKLU | D19: Planladığın asansörleri sen girersin, hesap grubu kontrol eder: Reş = ΣR ≥ B·k ve TReş = 1/Σ(1/TR) ≤ Izul (MMO/697 s.12).
A20: FARKLI KAPASİTEDE ASANSÖR | B20: ÇOKLU ASANSÖR (zorunlu) | C20: PAFTA-COKLU | D20: HESAPLAMA'nın verdiği adet, asansörlerin HEPSİNİN aynı kabin ve aynı hızda olduğunu varsayar. Kapasiteler farklıysa grup formülü zorunludur.
A21: ÖNERİLEN SIRA | B21: Önce HESAPLAMA ile kaç adet gerektiğine bak | C21: Tek çıkarsa PAFTA; birden fazla ve farklı kapasiteliyse ÇOKLU ASANSÖR'e geç | D21: İki sayfanın girdileri BAĞIMSIZDIR — birinde yaptığın değişiklik diğerine geçmez. Hangi paftayı basacaksan onun kendi girdilerini doldur.
A22: YENİ PROJEYE BAŞLARKEN KONTROL EDİLECEKLER
A23: Önceki projeden kalıntı | B23: HESAPLAMA E26:E29 (manuel ta / tk / tg / tp) ve C39 (elle asansör adedi) bir önceki işten kalmış olabilir | C23: E30 ve E39 uyarı yazar | D23: Boşalt. Manuel süre girilirse paftada kaynak 'İmalatçı verisi'ne döner ve teknik föy referansı istenir.
A24: Kapsam sınırları | B24: Kabin 6–34 kişi, kat N = 1–30. Kapı genişliği tam hesaplanabilir değerler: 900 / 1100 / 1300 mm (Tablo-4 ∩ Tablo-8). | C24: Tablo-3 / 4 / 5 / 8 | D24: Aralık dışında hesap durur ve EKSİK OLAN DEĞERİ ADIYLA söyler; sessizce yanlış sonuç üretmez. N > 30 için tek bölgeli hesap geçersizdir, bölgeli (zoned) hesap gerekir.
A25: Manuel giriş gereken tipler | B25: Karma Binalar, Poliklinik, Katlı Otopark ve Hastane | C25: Tablo-2 / Tablo-9 | D25: Bu tiplerde hız ve/veya %k tabloda yoktur; E10 (manuel V) ve E5 (manuel k) hücrelerinden girilir.
A26: Bodrum katı | B26: N = ana giriş katının ÜSTÜNDEKİ kat adedidir; bodrum N'e dâhil EDİLMEZ | C26: MMO/697 s.11 | D26: Bodrum durağı seyir mesafesini, kuyu dibini ve durak/kapı adedini etkiler; tur süresine girmez. Bodrumdan yolcu binen bina (kapalı otopark) bu yöntemle modellenmez.
A27: tp değerinin MMO/697 ile ilişkisi | B27: Tablo-8 değerleri MMO/697'nin BASILI tablosu değildir; MMO/697 kendi örneğinde tp = 2,2 s kullanır (eski ISO 4190-6:1984 yaklaşımı 1,75 s idi). Çalışma kitabı güncel ISO 8100-32:2020 Tablo 6 değerlerini kullanır. | C27: ISO 8100-32:2020 | D27: Sıkışık hesaplarda bu fark sonucu değiştirir. İtiraz gelirse dayanak ISO 8100-32:2020 Tablo 6'dır; muhafazakâr konut tasarımı için Barney/Peters +0,3 s konut düzeltmesi E29 hücresinden elle uygulanabilir.
A28: Ondalık ayırıcı | B28: Ondalık yazarken NOKTA değil VİRGÜL kullanın | C28: Türkçe Excel | D28: "17.1" yazarsanız 17 Ocak tarihine (46039) dönüşür ve hesap sessizce bozulur.
A30: Asansör adedinin boyutlandığı sınır | B30: Gereken adet, MMO/697 Tablo-10 STANDART sınırına (yüksek yapıda Yükseltilmiş) göre bulunur; Şartlı Kabul sınırına göre değil. | C30: Tablo-10 | D30: Şartlı Kabul yalnızca sonuç raporlanırken, daha az asansörle de geçilebileceğini göstermek için PAFTA satırında ayrıca yazılır ve taahhütname gerektirir.
A31: Ara hız değerleri (1,75 / 3,00 m/s) | B31: Tablo-6 satır başlığı değildir; tg doğrusal enterpolasyonla bulunur. | C31: Tablo-6 | D31: Paftada kaynak "Tablo-6 (ara değer — enterpolasyon)" olarak basılır.
A32: Öneri bloğu kapı genişliği varsayımı | B32: ISO 8100-32:2020, Ek C, Tablo 8 — beyan yüküne göre varsayılan kapı genişlikleri | C32: HESAPLAMA 6) blok | D32: 630 kg→800 mm, 800 kg→900 mm, 1000/1275/1600 kg→1100 mm, 2000 kg→1300 mm. Yalnız öneri tablosunda kullanılır; kesin hesap ⑨ girdinizle yapılır.

Sheet TABLO-1
A1: Bina Tipi * | C1: b
A2: KONUT ** | B2: her dairede ilk yatak odası için | C2: 2
B3: diğer odaların her biri için | C3: 1
A4: OTEL | B4: Her yatak için | C4: 1
A5: İŞ MERKEZİ | B5: çalışma alanının her 12 m²si için | C5: 1
A6: HASTANE | B6: her yatak için | C6: 3
A7: RESMİ BİNALAR | B7: çalışma alanının 12 m²si için | C7: 1
A8: OTOPARK | B8: ticari amaçlı araç adedi başına | C8: 1,5
B9: özel amaçlı araç adedi başına | C9: 1
A10: * Servis asansörleri bu değerlerin dışındadır.
A11: ** Diğer bölümler ve mutfak hesaba katılmayacaktır.
A12: *** Engelliler için ayrıca hesap yapılmayacaktır.
A13: Tablo –1 Binada sürekli bulunan insan sayısı
A14: Kaynak: MMO/697 "Asansör Avan Projesi Hazırlama Teknik Esasları", 2. Baskı, Ocak 2020, s.13

Sheet TABLO-2
A1: Bina Tipi | B1: Durak Adedi | C1: Hız [m/s]
A2: Konut | B2: 2-9 Durak | C2: 1
B3: 10-14 Durak | C3: 1.6
B4: 15-19 Durak | C4: 2.0
B5: 20 Durak ve üzeri | C5: ≥ 2.5
A6: Büro ve İş Merkezi | B6: 2-5 Durak | C6: 1
B7: 6-10 Durak | C7: 1.6
B8: 11-15 Durak | C8: 2.0
B9: 16-19 Durak | C9: 2.5
B10: 20 Durak ve üzeri | C10: > 2.5
A11: Otel | B11: 2-6 Durak | C11: 1
B12: 7-10 Durak | C12: 1.6
B13: 11-15 Durak | C13: 2.0
B14: 16-19 Durak | C14: 2.5
B15: 20 Durak ve üzeri | C15: > 2.5
A17: Tablo –2 Kabin hızları
A18: Kaynak: MMO/697, 2. Baskı, Ocak 2020, s.13

Sheet TABLO-3
A1: Ana giriş üstündeki kat sayısı (N) | B1: ASANSÖRÜN KAPASİTESİ (KİŞİ)
B2: 6 | C2: 7 | D2: 8 | E2: 9 | F2: 10 | G2: 11 | H2: 12 | I2: 13 | J2: 14 | K2: 15 | L2: 16 | M2: 17 | N2: 18 | O2: 19 | P2: 20 | Q2: 21 | R2: 22 | S2: 23 | T2: 24 | U2: 25 | V2: 26 | W2: 27 | X2: 28 | Y2: 29 | Z2: 30 | AA2: 31 | AB2: 32 | AC2: 33 | AD2: 34 | AG2: i (yardımcı)
A3: 1 | B3: =$A3 - SUMPRODUCT(($AG$3:$AG$31<$A3)*(($AG$3:$AG$31/$A3)^B$2)) | C3: =$A3 - SUMPRODUCT(($AG$3:$AG$31<$A3)*(($AG$3:$AG$31/$A3)^C$2)) | D3: =$A3 - SUMPRODUCT(($AG$3:$AG$31<$A3)*(($AG$3:$AG$31/$A3)^D$2)) | E3: =$A3 - SUMPRODUCT(($AG$3:$AG$31<$A3)*(($AG$3:$AG$31/$A3)^E$2)) | F3: =$A3 - SUMPRODUCT(($AG$3:$AG$31<$A3)*(($AG$3:$AG$31/$A3)^F$2)) | G3: =$A3 - SUMPRODUCT(($AG$3:$AG$31<$A3)*(($AG$3:$AG$31/$A3)^G$2)) | H3: =$A3 - SUMPRODUCT(($AG$3:$AG$31<$A3)*(($AG$3:$AG$31/$A3)^H$2)) | I3: =$A3 - SUMPRODUCT(($AG$3:$AG$31<$A3)*(($AG$3:$AG$31/$A3)^I$2)) | ... AD3: =$A3 - SUMPRODUCT(($AG$3:$AG$31<$A3)*(($AG$3:$AG$31/$A3)^AD$2)) | AG3: 1
A4: 2 | B4: =$A4 - SUMPRODUCT(($AG$3:$AG$31<$A4)*(($AG$3:$AG$31/$A4)^B$2)) | C4: =$A4 - SUMPRODUCT(($AG$3:$AG$31<$A4)*(($AG$3:$AG$31/$A4)^C$2)) | D4: =$A4 - SUMPRODUCT(($AG$3:$AG$31<$A4)*(($AG$3:$AG$31/$A4)^D$2)) | E4: =$A4 - SUMPRODUCT(($AG$3:$AG$31<$A4)*(($AG$3:$AG$31/$A4)^E$2)) | F4: =$A4 - SUMPRODUCT(($AG$3:$AG$31<$A4)*(($AG$3:$AG$31/$A4)^F$2)) | G4: =$A4 - SUMPRODUCT(($AG$3:$AG$31<$A4)*(($AG$3:$AG$31/$A4)^G$2)) | H4: =$A4 - SUMPRODUCT(($AG$3:$AG$31<$A4)*(($AG$3:$AG$31/$A4)^H$2)) | I4: =$A4 - SUMPRODUCT(($AG$3:$AG$31<$A4)*(($AG$3:$AG$31/$A4)^I$2)) | ... AD4: =$A4 - SUMPRODUCT(($AG$3:$AG$31<$A4)*(($AG$3:$AG$31/$A4)^AD$2)) | AG4: 2
A5: 3 | B5: =$A5 - SUMPRODUCT(($AG$3:$AG$31<$A5)*(($AG$3:$AG$31/$A5)^B$2)) | C5: =$A5 - SUMPRODUCT(($AG$3:$AG$31<$A5)*(($AG$3:$AG$31/$A5)^C$2)) | D5: =$A5 - SUMPRODUCT(($AG$3:$AG$31<$A5)*(($AG$3:$AG$31/$A5)^D$2)) | E5: =$A5 - SUMPRODUCT(($AG$3:$AG$31<$A5)*(($AG$3:$AG$31/$A5)^E$2)) | F5: =$A5 - SUMPRODUCT(($AG$3:$AG$31<$A5)*(($AG$3:$AG$31/$A5)^F$2)) | G5: =$A5 - SUMPRODUCT(($AG$3:$AG$31<$A5)*(($AG$3:$AG$31/$A5)^G$2)) | H5: =$A5 - SUMPRODUCT(($AG$3:$AG$31<$A5)*(($AG$3:$AG$31/$A5)^H$2)) | I5: =$A5 - SUMPRODUCT(($AG$3:$AG$31<$A5)*(($AG$3:$AG$31/$A5)^I$2)) | ... AD5: =$A5 - SUMPRODUCT(($AG$3:$AG$31<$A5)*(($AG$3:$AG$31/$A5)^AD$2)) | AG5: 3
A6: 4 | B6: =$A6 - SUMPRODUCT(($AG$3:$AG$31<$A6)*(($AG$3:$AG$31/$A6)^B$2)) | C6: =$A6 - SUMPRODUCT(($AG$3:$AG$31<$A6)*(($AG$3:$AG$31/$A6)^C$2)) | D6: =$A6 - SUMPRODUCT(($AG$3:$AG$31<$A6)*(($AG$3:$AG$31/$A6)^D$2)) | E6: =$A6 - SUMPRODUCT(($AG$3:$AG$31<$A6)*(($AG$3:$AG$31/$A6)^E$2)) | F6: =$A6 - SUMPRODUCT(($AG$3:$AG$31<$A6)*(($AG$3:$AG$31/$A6)^F$2)) | G6: =$A6 - SUMPRODUCT(($AG$3:$AG$31<$A6)*(($AG$3:$AG$31/$A6)^G$2)) | H6: =$A6 - SUMPRODUCT(($AG$3:$AG$31<$A6)*(($AG$3:$AG$31/$A6)^H$2)) | I6: =$A6 - SUMPRODUCT(($AG$3:$AG$31<$A6)*(($AG$3:$AG$31/$A6)^I$2)) | ... AD6: =$A6 - SUMPRODUCT(($AG$3:$AG$31<$A6)*(($AG$3:$AG$31/$A6)^AD$2)) | AG6: 4
A7: 5 | B7: =$A7 - SUMPRODUCT(($AG$3:$AG$31<$A7)*(($AG$3:$AG$31/$A7)^B$2)) | C7: =$A7 - SUMPRODUCT(($AG$3:$AG$31<$A7)*(($AG$3:$AG$31/$A7)^C$2)) | D7: =$A7 - SUMPRODUCT(($AG$3:$AG$31<$A7)*(($AG$3:$AG$31/$A7)^D$2)) | E7: =$A7 - SUMPRODUCT(($AG$3:$AG$31<$A7)*(($AG$3:$AG$31/$A7)^E$2)) | F7: =$A7 - SUMPRODUCT(($AG$3:$AG$31<$A7)*(($AG$3:$AG$31/$A7)^F$2)) | G7: =$A7 - SUMPRODUCT(($AG$3:$AG$31<$A7)*(($AG$3:$AG$31/$A7)^G$2)) | H7: =$A7 - SUMPRODUCT(($AG$3:$AG$31<$A7)*(($AG$3:$AG$31/$A7)^H$2)) | I7: =$A7 - SUMPRODUCT(($AG$3:$AG$31<$A7)*(($AG$3:$AG$31/$A7)^I$2)) | ... AD7: =$A7 - SUMPRODUCT(($AG$3:$AG$31<$A7)*(($AG$3:$AG$31/$A7)^AD$2)) | AG7: 5
A8: 6 | B8: =$A8 - SUMPRODUCT(($AG$3:$AG$31<$A8)*(($AG$3:$AG$31/$A8)^B$2)) | C8: =$A8 - SUMPRODUCT(($AG$3:$AG$31<$A8)*(($AG$3:$AG$31/$A8)^C$2)) | D8: =$A8 - SUMPRODUCT(($AG$3:$AG$31<$A8)*(($AG$3:$AG$31/$A8)^D$2)) | E8: =$A8 - SUMPRODUCT(($AG$3:$AG$31<$A8)*(($AG$3:$AG$31/$A8)^E$2)) | F8: =$A8 - SUMPRODUCT(($AG$3:$AG$31<$A8)*(($AG$3:$AG$31/$A8)^F$2)) | G8: =$A8 - SUMPRODUCT(($AG$3:$AG$31<$A8)*(($AG$3:$AG$31/$A8)^G$2)) | H8: =$A8 - SUMPRODUCT(($AG$3:$AG$31<$A8)*(($AG$3:$AG$31/$A8)^H$2)) | I8: =$A8 - SUMPRODUCT(($AG$3:$AG$31<$A8)*(($AG$3:$AG$31/$A8)^I$2)) | ... AD8: =$A8 - SUMPRODUCT(($AG$3:$AG$31<$A8)*(($AG$3:$AG$31/$A8)^AD$2)) | AG8: 6
A9: 7 | B9: =$A9 - SUMPRODUCT(($AG$3:$AG$31<$A9)*(($AG$3:$AG$31/$A9)^B$2)) | C9: =$A9 - SUMPRODUCT(($AG$3:$AG$31<$A9)*(($AG$3:$AG$31/$A9)^C$2)) | D9: =$A9 - SUMPRODUCT(($AG$3:$AG$31<$A9)*(($AG$3:$AG$31/$A9)^D$2)) | E9: =$A9 - SUMPRODUCT(($AG$3:$AG$31<$A9)*(($AG$3:$AG$31/$A9)^E$2)) | F9: =$A9 - SUMPRODUCT(($AG$3:$AG$31<$A9)*(($AG$3:$AG$31/$A9)^F$2)) | G9: =$A9 - SUMPRODUCT(($AG$3:$AG$31<$A9)*(($AG$3:$AG$31/$A9)^G$2)) | H9: =$A9 - SUMPRODUCT(($AG$3:$AG$31<$A9)*(($AG$3:$AG$31/$A9)^H$2)) | I9: =$A9 - SUMPRODUCT(($AG$3:$AG$31<$A9)*(($AG$3:$AG$31/$A9)^I$2)) | ... AD9: =$A9 - SUMPRODUCT(($AG$3:$AG$31<$A9)*(($AG$3:$AG$31/$A9)^AD$2)) | AG9: 7
A10: 8 | B10: =$A10 - SUMPRODUCT(($AG$3:$AG$31<$A10)*(($AG$3:$AG$31/$A10)^B$2)) | C10: =$A10 - SUMPRODUCT(($AG$3:$AG$31<$A10)*(($AG$3:$AG$31/$A10)^C$2)) | D10: =$A10 - SUMPRODUCT(($AG$3:$AG$31<$A10)*(($AG$3:$AG$31/$A10)^D$2)) | E10: =$A10 - SUMPRODUCT(($AG$3:$AG$31<$A10)*(($AG$3:$AG$31/$A10)^E$2)) | F10: =$A10 - SUMPRODUCT(($AG$3:$AG$31<$A10)*(($AG$3:$AG$31/$A10)^F$2)) | G10: =$A10 - SUMPRODUCT(($AG$3:$AG$31<$A10)*(($AG$3:$AG$31/$A10)^G$2)) | H10: =$A10 - SUMPRODUCT(($AG$3:$AG$31<$A10)*(($AG$3:$AG$31/$A10)^H$2)) | I10: =$A10 - SUMPRODUCT(($AG$3:$AG$31<$A10)*(($AG$3:$AG$31/$A10)^I$2)) | ... AD10: =$A10 - SUMPRODUCT(($AG$3:$AG$31<$A10)*(($AG$3:$AG$31/$A10)^AD$2)) | AG10: 8
A11: 9 | B11: =$A11 - SUMPRODUCT(($AG$3:$AG$31<$A11)*(($AG$3:$AG$31/$A11)^B$2)) | C11: =$A11 - SUMPRODUCT(($AG$3:$AG$31<$A11)*(($AG$3:$AG$31/$A11)^C$2)) | D11: =$A11 - SUMPRODUCT(($AG$3:$AG$31<$A11)*(($AG$3:$AG$31/$A11)^D$2)) | E11: =$A11 - SUMPRODUCT(($AG$3:$AG$31<$A11)*(($AG$3:$AG$31/$A11)^E$2)) | F11: =$A11 - SUMPRODUCT(($AG$3:$AG$31<$A11)*(($AG$3:$AG$31/$A11)^F$2)) | G11: =$A11 - SUMPRODUCT(($AG$3:$AG$31<$A11)*(($AG$3:$AG$31/$A11)^G$2)) | H11: =$A11 - SUMPRODUCT(($AG$3:$AG$31<$A11)*(($AG$3:$AG$31/$A11)^H$2)) | I11: =$A11 - SUMPRODUCT(($AG$3:$AG$31<$A11)*(($AG$3:$AG$31/$A11)^I$2)) | ... AD11: =$A11 - SUMPRODUCT(($AG$3:$AG$31<$A11)*(($AG$3:$AG$31/$A11)^AD$2)) | AG11: 9
A12: 10 | B12: =$A12 - SUMPRODUCT(($AG$3:$AG$31<$A12)*(($AG$3:$AG$31/$A12)^B$2)) | C12: =$A12 - SUMPRODUCT(($AG$3:$AG$31<$A12)*(($AG$3:$AG$31/$A12)^C$2)) | D12: =$A12 - SUMPRODUCT(($AG$3:$AG$31<$A12)*(($AG$3:$AG$31/$A12)^D$2)) | E12: =$A12 - SUMPRODUCT(($AG$3:$AG$31<$A12)*(($AG$3:$AG$31/$A12)^E$2)) | F12: =$A12 - SUMPRODUCT(($AG$3:$AG$31<$A12)*(($AG$3:$AG$31/$A12)^F$2)) | G12: =$A12 - SUMPRODUCT(($AG$3:$AG$31<$A12)*(($AG$3:$AG$31/$A12)^G$2)) | H12: =$A12 - SUMPRODUCT(($AG$3:$AG$31<$A12)*(($AG$3:$AG$31/$A12)^H$2)) | I12: =$A12 - SUMPRODUCT(($AG$3:$AG$31<$A12)*(($AG$3:$AG$31/$A12)^I$2)) | ... AD12: =$A12 - SUMPRODUCT(($AG$3:$AG$31<$A12)*(($AG$3:$AG$31/$A12)^AD$2)) | AG12: 10
A13: 11 | B13: =$A13 - SUMPRODUCT(($AG$3:$AG$31<$A13)*(($AG$3:$AG$31/$A13)^B$2)) | C13: =$A13 - SUMPRODUCT(($AG$3:$AG$31<$A13)*(($AG$3:$AG$31/$A13)^C$2)) | D13: =$A13 - SUMPRODUCT(($AG$3:$AG$31<$A13)*(($AG$3:$AG$31/$A13)^D$2)) | E13: =$A13 - SUMPRODUCT(($AG$3:$AG$31<$A13)*(($AG$3:$AG$31/$A13)^E$2)) | F13: =$A13 - SUMPRODUCT(($AG$3:$AG$31<$A13)*(($AG$3:$AG$31/$A13)^F$2)) | G13: =$A13 - SUMPRODUCT(($AG$3:$AG$31<$A13)*(($AG$3:$AG$31/$A13)^G$2)) | H13: =$A13 - SUMPRODUCT(($AG$3:$AG$31<$A13)*(($AG$3:$AG$31/$A13)^H$2)) | I13: =$A13 - SUMPRODUCT(($AG$3:$AG$31<$A13)*(($AG$3:$AG$31/$A13)^I$2)) | ... AD13: =$A13 - SUMPRODUCT(($AG$3:$AG$31<$A13)*(($AG$3:$AG$31/$A13)^AD$2)) | AG13: 11
A14: 12 | B14: =$A14 - SUMPRODUCT(($AG$3:$AG$31<$A14)*(($AG$3:$AG$31/$A14)^B$2)) | C14: =$A14 - SUMPRODUCT(($AG$3:$AG$31<$A14)*(($AG$3:$AG$31/$A14)^C$2)) | D14: =$A14 - SUMPRODUCT(($AG$3:$AG$31<$A14)*(($AG$3:$AG$31/$A14)^D$2)) | E14: =$A14 - SUMPRODUCT(($AG$3:$AG$31<$A14)*(($AG$3:$AG$31/$A14)^E$2)) | F14: =$A14 - SUMPRODUCT(($AG$3:$AG$31<$A14)*(($AG$3:$AG$31/$A14)^F$2)) | G14: =$A14 - SUMPRODUCT(($AG$3:$AG$31<$A14)*(($AG$3:$AG$31/$A14)^G$2)) | H14: =$A14 - SUMPRODUCT(($AG$3:$AG$31<$A14)*(($AG$3:$AG$31/$A14)^H$2)) | I14: =$A14 - SUMPRODUCT(($AG$3:$AG$31<$A14)*(($AG$3:$AG$31/$A14)^I$2)) | ... AD14: =$A14 - SUMPRODUCT(($AG$3:$AG$31<$A14)*(($AG$3:$AG$31/$A14)^AD$2)) | AG14: 12
... A31: 29 | B31: =$A31 - SUMPRODUCT(($AG$3:$AG$31<$A31)*(($AG$3:$AG$31/$A31)^B$2)) | C31: =$A31 - SUMPRODUCT(($AG$3:$AG$31<$A31)*(($AG$3:$AG$31/$A31)^C$2)) | D31: =$A31 - SUMPRODUCT(($AG$3:$AG$31<$A31)*(($AG$3:$AG$31/$A31)^D$2)) | E31: =$A31 - SUMPRODUCT(($AG$3:$AG$31<$A31)*(($AG$3:$AG$31/$A31)^E$2)) | F31: =$A31 - SUMPRODUCT(($AG$3:$AG$31<$A31)*(($AG$3:$AG$31/$A31)^F$2)) | G31: =$A31 - SUMPRODUCT(($AG$3:$AG$31<$A31)*(($AG$3:$AG$31/$A31)^G$2)) | H31: =$A31 - SUMPRODUCT(($AG$3:$AG$31<$A31)*(($AG$3:$AG$31/$A31)^H$2)) | I31: =$A31 - SUMPRODUCT(($AG$3:$AG$31<$A31)*(($AG$3:$AG$31/$A31)^I$2)) | ... AD31: =$A31 - SUMPRODUCT(($AG$3:$AG$31<$A31)*(($AG$3:$AG$31/$A31)^AD$2)) | AG31: 29
A32: 30 | B32: =$A32 - SUMPRODUCT(($AG$3:$AG$31<$A32)*(($AG$3:$AG$31/$A32)^B$2)) | C32: =$A32 - SUMPRODUCT(($AG$3:$AG$31<$A32)*(($AG$3:$AG$31/$A32)^C$2)) | D32: =$A32 - SUMPRODUCT(($AG$3:$AG$31<$A32)*(($AG$3:$AG$31/$A32)^D$2)) | E32: =$A32 - SUMPRODUCT(($AG$3:$AG$31<$A32)*(($AG$3:$AG$31/$A32)^E$2)) | F32: =$A32 - SUMPRODUCT(($AG$3:$AG$31<$A32)*(($AG$3:$AG$31/$A32)^F$2)) | G32: =$A32 - SUMPRODUCT(($AG$3:$AG$31<$A32)*(($AG$3:$AG$31/$A32)^G$2)) | H32: =$A32 - SUMPRODUCT(($AG$3:$AG$31<$A32)*(($AG$3:$AG$31/$A32)^H$2)) | I32: =$A32 - SUMPRODUCT(($AG$3:$AG$31<$A32)*(($AG$3:$AG$31/$A32)^I$2)) | ... AD32: =$A32 - SUMPRODUCT(($AG$3:$AG$31<$A32)*(($AG$3:$AG$31/$A32)^AD$2))
A34: TABLO-3 ORTALAMA EN YÜKSEK DÖNÜŞ KATI — H = N − Σ(i/N)^P , i=1..N-1
A35: N = Ana Giriş Üzerindeki Kat Adedi. Kaynak: MMO/697, Ocak 2020, s.14 (Tablo-3, kapasite 6-34 kişi, N=1-30)

Sheet TABLO-4
B1: Kapı Tipi
A2: Kapı Genişliği (mm) | B2: Teleskopik Otomatik | D2: Merkezden Açılan Oto. | F2: Kabin İçi Oto. Kat K.Ç.
B3: ta[s] | C3: tk[s] | D3: ta[s] | E3: tk[s] | F3: ta[s] | G3: tk[s] | I3: ta_num | J3: tk_num | K3: ta_num | L3: tk_num | M3: ta_num | N3: tk_num
A4: 700 | B4: 2,5 | C4: 3 | D4: 2 | E4: 2,5 | F4: 5 | G4: 5 | I4: 2.5 | J4: 3 | K4: 2 | L4: 2.5 | M4: 5 | N4: 5
A5: 800 | B5: 2,5 | C5: 3 | D5: 2 | E5: 2,5 | F5: 5 | G5: 5 | I5: 2.5 | J5: 3 | K5: 2 | L5: 2.5 | M5: 5 | N5: 5
A6: 900 | B6: 2,5 | C6: 3,8 | D6: 2,3 | E6: 2,9 | F6: 5 | G6: 5 | I6: 2.5 | J6: 3.8 | K6: 2.3 | L6: 2.9 | M6: 5 | N6: 5
A7: 1000 | B7: 2,75 | C7: 3,9 | D7: 2,4 | E7: 3,2 | F7: 5,5 | G7: 5,5 | I7: 2.75 | J7: 3.9 | K7: 2.4 | L7: 3.2 | M7: 5.5 | N7: 5.5
A8: 1100 | B8: 3 | C8: 4 | D8: 2,5 | E8: 3,5 | F8: 6 | G8: 6 | I8: 3 | J8: 4 | K8: 2.5 | L8: 3.5 | M8: 6 | N8: 6
A9: 1200 | B9: 3,35 | C9: 4,5 | D9: 2,6 | E9: 3,6 | F9: YOK | G9: YOK | I9: 3.35 | J9: 4.5 | K9: 2.6 | L9: 3.6 | M9: YOK | N9: YOK
A10: 1300 | B10: 3,7 | C10: 5 | D10: 2,7 | E10: 3,7 | F10: YOK | G10: YOK | I10: 3.7 | J10: 5 | K10: 2.7 | L10: 3.7 | M10: YOK | N10: YOK
A11: Tablo –4 Kapı açılma ve kapanma zamanları | Kaynak: MMO/697, Ocak 2020, s.15 (kitapla birebir doğrulandı) | 1000 ve 1200 mm satırları MMO/697 Tablo-4'te BASILI DEĞİLDİR; komşu satırlar arasında doğrusal enterpolasyonla türetilmiştir ( 1000 = (900+1100)/2 , 1200 = (1100+1300)/2 ) — Tablo-6'daki 1,75 ve 3,00 m/s ara değerleriyle aynı yöntem. 'Kabin İçi Oto. Kat K.Ç.' sütunu 1300 mm'de tabloda bulunmadığından 1200 mm için de üretilememiştir; bu iki hücrede imalatçı değeri elle girilmelidir.

Sheet TABLO-5
A1: Ana giriş üstündeki kat sayısı (N) | B1: ASANSÖRÜN KAPASİTESİ (KİŞİ)
B2: 6 | C2: 7 | D2: 8 | E2: 9 | F2: 10 | G2: 11 | H2: 12 | I2: 13 | J2: 14 | K2: 15 | L2: 16 | M2: 17 | N2: 18 | O2: 19 | P2: 20 | Q2: 21 | R2: 22 | S2: 23 | T2: 24 | U2: 25 | V2: 26 | W2: 27 | X2: 28 | Y2: 29 | Z2: 30 | AA2: 31 | AB2: 32 | AC2: 33 | AD2: 34
A3: 1 | B3: =$A3*(1-(($A3-1)/$A3)^B$2) | C3: =$A3*(1-(($A3-1)/$A3)^C$2) | D3: =$A3*(1-(($A3-1)/$A3)^D$2) | E3: =$A3*(1-(($A3-1)/$A3)^E$2) | F3: =$A3*(1-(($A3-1)/$A3)^F$2) | G3: =$A3*(1-(($A3-1)/$A3)^G$2) | H3: =$A3*(1-(($A3-1)/$A3)^H$2) | I3: =$A3*(1-(($A3-1)/$A3)^I$2) | ... AD3: =$A3*(1-(($A3-1)/$A3)^AD$2)
A4: 2 | B4: =$A4*(1-(($A4-1)/$A4)^B$2) | C4: =$A4*(1-(($A4-1)/$A4)^C$2) | D4: =$A4*(1-(($A4-1)/$A4)^D$2) | E4: =$A4*(1-(($A4-1)/$A4)^E$2) | F4: =$A4*(1-(($A4-1)/$A4)^F$2) | G4: =$A4*(1-(($A4-1)/$A4)^G$2) | H4: =$A4*(1-(($A4-1)/$A4)^H$2) | I4: =$A4*(1-(($A4-1)/$A4)^I$2) | ... AD4: =$A4*(1-(($A4-1)/$A4)^AD$2)
A5: 3 | B5: =$A5*(1-(($A5-1)/$A5)^B$2) | C5: =$A5*(1-(($A5-1)/$A5)^C$2) | D5: =$A5*(1-(($A5-1)/$A5)^D$2) | E5: =$A5*(1-(($A5-1)/$A5)^E$2) | F5: =$A5*(1-(($A5-1)/$A5)^F$2) | G5: =$A5*(1-(($A5-1)/$A5)^G$2) | H5: =$A5*(1-(($A5-1)/$A5)^H$2) | I5: =$A5*(1-(($A5-1)/$A5)^I$2) | ... AD5: =$A5*(1-(($A5-1)/$A5)^AD$2)
A6: 4 | B6: =$A6*(1-(($A6-1)/$A6)^B$2) | C6: =$A6*(1-(($A6-1)/$A6)^C$2) | D6: =$A6*(1-(($A6-1)/$A6)^D$2) | E6: =$A6*(1-(($A6-1)/$A6)^E$2) | F6: =$A6*(1-(($A6-1)/$A6)^F$2) | G6: =$A6*(1-(($A6-1)/$A6)^G$2) | H6: =$A6*(1-(($A6-1)/$A6)^H$2) | I6: =$A6*(1-(($A6-1)/$A6)^I$2) | ... AD6: =$A6*(1-(($A6-1)/$A6)^AD$2)
A7: 5 | B7: =$A7*(1-(($A7-1)/$A7)^B$2) | C7: =$A7*(1-(($A7-1)/$A7)^C$2) | D7: =$A7*(1-(($A7-1)/$A7)^D$2) | E7: =$A7*(1-(($A7-1)/$A7)^E$2) | F7: =$A7*(1-(($A7-1)/$A7)^F$2) | G7: =$A7*(1-(($A7-1)/$A7)^G$2) | H7: =$A7*(1-(($A7-1)/$A7)^H$2) | I7: =$A7*(1-(($A7-1)/$A7)^I$2) | ... AD7: =$A7*(1-(($A7-1)/$A7)^AD$2)
A8: 6 | B8: =$A8*(1-(($A8-1)/$A8)^B$2) | C8: =$A8*(1-(($A8-1)/$A8)^C$2) | D8: =$A8*(1-(($A8-1)/$A8)^D$2) | E8: =$A8*(1-(($A8-1)/$A8)^E$2) | F8: =$A8*(1-(($A8-1)/$A8)^F$2) | G8: =$A8*(1-(($A8-1)/$A8)^G$2) | H8: =$A8*(1-(($A8-1)/$A8)^H$2) | I8: =$A8*(1-(($A8-1)/$A8)^I$2) | ... AD8: =$A8*(1-(($A8-1)/$A8)^AD$2)
A9: 7 | B9: =$A9*(1-(($A9-1)/$A9)^B$2) | C9: =$A9*(1-(($A9-1)/$A9)^C$2) | D9: =$A9*(1-(($A9-1)/$A9)^D$2) | E9: =$A9*(1-(($A9-1)/$A9)^E$2) | F9: =$A9*(1-(($A9-1)/$A9)^F$2) | G9: =$A9*(1-(($A9-1)/$A9)^G$2) | H9: =$A9*(1-(($A9-1)/$A9)^H$2) | I9: =$A9*(1-(($A9-1)/$A9)^I$2) | ... AD9: =$A9*(1-(($A9-1)/$A9)^AD$2)
A10: 8 | B10: =$A10*(1-(($A10-1)/$A10)^B$2) | C10: =$A10*(1-(($A10-1)/$A10)^C$2) | D10: =$A10*(1-(($A10-1)/$A10)^D$2) | E10: =$A10*(1-(($A10-1)/$A10)^E$2) | F10: =$A10*(1-(($A10-1)/$A10)^F$2) | G10: =$A10*(1-(($A10-1)/$A10)^G$2) | H10: =$A10*(1-(($A10-1)/$A10)^H$2) | I10: =$A10*(1-(($A10-1)/$A10)^I$2) | ... AD10: =$A10*(1-(($A10-1)/$A10)^AD$2)
A11: 9 | B11: =$A11*(1-(($A11-1)/$A11)^B$2) | C11: =$A11*(1-(($A11-1)/$A11)^C$2) | D11: =$A11*(1-(($A11-1)/$A11)^D$2) | E11: =$A11*(1-(($A11-1)/$A11)^E$2) | F11: =$A11*(1-(($A11-1)/$A11)^F$2) | G11: =$A11*(1-(($A11-1)/$A11)^G$2) | H11: =$A11*(1-(($A11-1)/$A11)^H$2) | I11: =$A11*(1-(($A11-1)/$A11)^I$2) | ... AD11: =$A11*(1-(($A11-1)/$A11)^AD$2)
A12: 10 | B12: =$A12*(1-(($A12-1)/$A12)^B$2) | C12: =$A12*(1-(($A12-1)/$A12)^C$2) | D12: =$A12*(1-(($A12-1)/$A12)^D$2) | E12: =$A12*(1-(($A12-1)/$A12)^E$2) | F12: =$A12*(1-(($A12-1)/$A12)^F$2) | G12: =$A12*(1-(($A12-1)/$A12)^G$2) | H12: =$A12*(1-(($A12-1)/$A12)^H$2) | I12: =$A12*(1-(($A12-1)/$A12)^I$2) | ... AD12: =$A12*(1-(($A12-1)/$A12)^AD$2)
A13: 11 | B13: =$A13*(1-(($A13-1)/$A13)^B$2) | C13: =$A13*(1-(($A13-1)/$A13)^C$2) | D13: =$A13*(1-(($A13-1)/$A13)^D$2) | E13: =$A13*(1-(($A13-1)/$A13)^E$2) | F13: =$A13*(1-(($A13-1)/$A13)^F$2) | G13: =$A13*(1-(($A13-1)/$A13)^G$2) | H13: =$A13*(1-(($A13-1)/$A13)^H$2) | I13: =$A13*(1-(($A13-1)/$A13)^I$2) | ... AD13: =$A13*(1-(($A13-1)/$A13)^AD$2)
A14: 12 | B14: =$A14*(1-(($A14-1)/$A14)^B$2) | C14: =$A14*(1-(($A14-1)/$A14)^C$2) | D14: =$A14*(1-(($A14-1)/$A14)^D$2) | E14: =$A14*(1-(($A14-1)/$A14)^E$2) | F14: =$A14*(1-(($A14-1)/$A14)^F$2) | G14: =$A14*(1-(($A14-1)/$A14)^G$2) | H14: =$A14*(1-(($A14-1)/$A14)^H$2) | I14: =$A14*(1-(($A14-1)/$A14)^I$2) | ... AD14: =$A14*(1-(($A14-1)/$A14)^AD$2)
... A32: 30 | B32: =$A32*(1-(($A32-1)/$A32)^B$2) | C32: =$A32*(1-(($A32-1)/$A32)^C$2) | D32: =$A32*(1-(($A32-1)/$A32)^D$2) | E32: =$A32*(1-(($A32-1)/$A32)^E$2) | F32: =$A32*(1-(($A32-1)/$A32)^F$2) | G32: =$A32*(1-(($A32-1)/$A32)^G$2) | H32: =$A32*(1-(($A32-1)/$A32)^H$2) | I32: =$A32*(1-(($A32-1)/$A32)^I$2) | ... AD32: =$A32*(1-(($A32-1)/$A32)^AD$2)
A34: TABLO-5 ORTALAMA DURAK ADEDİ — S = N·(1−((N−1)/N)^P)
A35: N = Ana Giriş Üzerindeki Kat Adedi. Kaynak: MMO/697, Ocak 2020, s.16 (Tablo-5, kapasite 6-34 kişi, N=1-30)

Sheet TABLO-6
A1: Hız [m/s] | B1: <1 | C1: 1 | D1: 1,6 | E1: 2 | F1: 2,5 | G1: 3,5 | H1: 5 | I1: >5,00
A2: tg [s] | B2: 10 | C2: 7 | D2: 6 | E2: 5,7 | F2: 5,5 | G2: 5 | H2: 4,5 | I2: 4,3
A3: Tablo –6 Tek katı geçme zamanı | Kaynak: MMO/697, Ocak 2020, s.17 (kitapla birebir doğrulandı)
A4: Ara değerler: 1,75 m/s → tg = 5,8875 s ve 3,00 m/s → tg = 5,25 s, komşu tablo noktaları arasında doğrusal enterpolasyonla türetilmiştir. MMO/697 Tablo-6 satır başlığı değildir; paftada kaynak "Tablo-6 (ara değer — enterpolasyon)" olarak yazılır.

Sheet TABLO-7
A1: Kabin Kapasitesi (P)
A2: 6 kişi | B2: 8 kişi | C2: 10 kişi | D2: 13 kişi | E2: 16 kişi | F2: 20 kişi | G2: 25 kişi | H2: 30 kişi
A3: 450 kg | B3: 630 kg | C3: 800 kg | D3: 1000 kg | E3: 1275 kg | F3: 1600 kg | G3: 2000 kg | H3: 2500 kg
A4: Tablo –7 Kabin kapasitesi | Kaynak: MMO/697, Ocak 2020, s.17
A5: Not: 15 kişi / 1125 kg bu Tablo-7'de yer almaz; MMO/697'nin s.53-54 örnek projesinde kullanıldığı için hesap sayfalarında açıkça 'örnek istisnası' olarak desteklenir.
A6: Kaynak ayrımı: Tablo-7 s.17 | 15 kişi / 1125 kg örneği s.53-54

Sheet TABLO-8
A1: Kapı Genişliği [mm] | B1: 700 | C1: 800 | D1: 900 | E1: 1000 | F1: 1100 | G1: 1200 | H1: 1300
A2: tp [s] | B2: 1.3 | C2: 1.2 | D2: 1.1 | E2: 1 | F2: 1 | G2: 0.9 | H2: 0.9
A3: Tablo –8 Kişi transfer zamanı (tp) — kapı tipinden bağımsız, net kapı genişliğine göre. tp = tek yolcunun kabine giriş VEYA çıkış süresidir; TR denkleminde 2·p·tp olarak kullanılır.
A5: Kaynak: ISO 8100-32:2020 "Planning and selection of passenger lifts…", Tablo 6 — 900 mm: 1,1 s | 1000 mm: 1,0 s | 1100 mm: 1,0 s | 1200 mm: 0,9 s.
A6: 800 mm: 1,2 s — ISO/CD 8100-32 (2017 komite taslağı) Tablo 6'nın 800 mm satırından; ayrıca Barney & Peters, "Expert Systems for Lift Traffic Design", 9th Symposium on Lift & Escalator Technology (2018), Tablo 3 (450-800 kg / 800 mm → 1,2 s) ile birebir aynıdır. 800 mm, EN 81-70'in erişilebilir asansör için istediği asgari net kapı genişliğidir.
A7: 1300 mm: 0,9 s — ISO tablosu 1200 mm'de biter; 1200 mm değeri düz devam ettirilmiştir. Barney/Peters >1100 mm için 0,8 s verdiğinden bu değer güvenli taraftadır.
A8: 700 mm ISO 8100-32:2020 Tablo 6'da ve Barney/Peters tablolarında YOKTUR (tablo 800 mm'de başlar, ayrıca 700 mm TS EN 81-70 erişilebilirlik asgarisi olan 800 mm'nin altındadır). Buradaki 1,3 s değeri 800→900 mm eğiminden ( −0,1 s / 100 mm ) DOĞRUSAL DIŞ DEĞERLEME ile bulunmuştur; büyük tp, TR'yi büyüttüğü için emniyetli taraftadır. İmalatçı verisi varsa manuel tp girilmelidir.
A10: NOT — bina tipi düzeltmesi: Barney/Peters Tablo 3 ofis değerleri içindir ve konut için +0,3 s, otel için +0,5 s eklenmesini önerir. ISO 8100-32:2020 Tablo 6 böyle bir ayrım yapmaz ve MMO/697 de yapmaz; bu çalışma kitabı ISO değerlerini olduğu gibi kullanır. Muhafazakâr bir konut tasarımı isteniyorsa HESAPLAMA E29 hücresine tp + 0,3 s elle girilebilir.

Sheet TABLO-9
A1: Bina Tipi | B1: Standart | C1: Yükseltilmiş 1) | D1: Standart_num | E1: Yükseltilmiş_num
A2: Konut | B2: % 7.5 | C2: % 10 | D2: 0.075 | E2: 0.1
A3: Otel | B3: % 12 | C3: % 15 | D3: 0.12 | E3: 0.15
A4: İş Merkezi | B4: % 15 | C4: % 17 | D4: 0.15 | E4: 0.17
A5: Hastane | B5: % 10 | C5: % 20 | D5: 0.1 | E5: 0.2
A6: Otopark | B6: % 10 | C6: % 20 | D6: 0.1 | E6: 0.2
A8: 1) Yüksek yapılardaki asansörlerin hesabı için yükseltilmiş değerlerin seçilmelidir.
A9: Tablo –9 Taşınacak insan yüzdesi (% k)
A10: Kaynak: MMO/697, Ocak 2020, s.17
A11: Otomatik yüksek bina kontrolü: bina yüksekliği >21,50 m veya yapı yüksekliği >30,50 m ise Yükseltilmiş seçilir (BYKHY md.4; kaynak KAYNAKLAR).
A12: Kamu binaları Tablo-9'da yoktur; çalışma kitabı İş Merkezi yüzdesini (%15 / yükseltilmiş %17) varsayar ve bunu HESAPLAMA E6 hücresinde belirtir.

Sheet TABLO-10
A1: Sınıf | B1: Kabul Edilemez | C1: Şartlı Kabul 2) | D1: Standart | E1: Yükseltilmiş 3) | F1: Sartli_num | G1: Standart_num | H1: Yukseltilmis_num | J1: Bina Tipi (ana seçim) | K1: → Tablo-2 hız grubu | L1: → Tablo-9 %k tipi
A2: Konut | B2: 120 sn. üzeri | C2: 120 sn. | D2: 100 sn. | E2: 80 sn. | F2: 120 | G2: 100 | H2: 80 | J2: Konut | K2: Konut | L2: Konut
A3: Karma Binalar (İşyeri ve Konut) | B3: 60 sn. üzeri | C3: 60 sn. | D3: 50 sn. | E3: 30 sn. | F3: 60 | G3: 50 | H3: 30 | J3: Karma Binalar (İşyeri ve Konut) | K3: Manuel hız gerekli | L3: Manuel k gerekli
A4: İş Merkezi (Tek Firmalı) | B4: 60 sn. üzeri | C4: 60 sn. | D4: 50 sn. | E4: 40 sn. | F4: 60 | G4: 50 | H4: 40 | J4: İş Merkezi (Tek Firmalı) | K4: Büro ve İş Merkezi | L4: İş Merkezi
A5: İş Merkezi (Çok Firmalı) | B5: 50 sn. üzeri | C5: 50 sn. | D5: 40 sn. | E5: 30 sn. | F5: 50 | G5: 40 | H5: 30 | J5: İş Merkezi (Çok Firmalı) | K5: Büro ve İş Merkezi | L5: İş Merkezi
A6: Otel (3* ve altı) | B6: 60 sn. üzeri | C6: 60 sn. | D6: 50 sn. | E6: 40 sn. | F6: 60 | G6: 50 | H6: 40 | J6: Otel (3* ve altı) | K6: Otel | L6: Otel
A7: Otel (4* ve üzeri) | B7: 50 sn. üzeri | C7: 50 sn. | D7: 40 sn. | E7: 30 sn. | F7: 50 | G7: 40 | H7: 30 | J7: Otel (4* ve üzeri) | K7: Otel | L7: Otel
A8: Kamu Binaları | B8: 40 sn. üzeri | C8: -- | D8: 40 sn. | E8: 30 sn. | G8: 40 | H8: 30 | J8: Kamu Binaları | K8: Büro ve İş Merkezi | L8: İş Merkezi
A9: Hastane | B9: 40 sn. üzeri | C9: -- | D9: 40 sn. | E9: 30 sn. | G9: 40 | H9: 30 | J9: Hastane | K9: Manuel hız gerekli | L9: Hastane
A10: Poliklinik Binaları ve Yaşlı Bakım Ev. | B10: 60 sn. üzeri | C10: 60 sn. | D10: 50 sn. | E10: 40 sn. | F10: 60 | G10: 50 | H10: 40 | J10: Poliklinik Binaları ve Yaşlı Bakım Ev. | K10: Manuel hız gerekli | L10: Manuel k gerekli
A11: Katlı Otopark | B11: 60 sn. üzeri | C11: 60 sn. | D11: 50 sn. | E11: 40 sn. | F11: 60 | G11: 50 | H11: 40 | J11: Katlı Otopark | K11: Manuel hız gerekli | L11: Otopark
A12: 2) Sadece asansör yaptırıcısı/bina sorumlusu onayı ile (Taahhütname)
A13: 3) Yüksek yapılardaki asansörlerin hesabı için yükseltilmiş standart seçilmelidir. | J13: EŞLEME TABLOSU — Yalnız MMO/697 Tablo-2 ve Tablo-9'da açıkça bulunan değerler otomatik seçilir.
A14: Tablo-10 İzin verilen en fazla bekleme zamanı (Izul) | J14: Tabloda bulunmayan bina sınıflarında hız ve/veya k değeri kullanıcı tarafından proje verisine göre girilmeden hesap yapılmaz.
A15: Kaynak: MMO/697, Ocak 2020, s.17
J16: Kamu Binaları: MMO/697 Tablo-2'de hız, Tablo-9'da %k verilmemiştir. Kullanım karakteri büro olduğundan Büro/İş Merkezi değerleri varsayılan alınır; V (E10) ve k (E5) hücrelerinden değiştirilebilir. Bekleme sınırı Tablo-10'un kendi Kamu satırından (40/30 sn) okunur.
