Workbook

Sheet HESAPLAMA
B1: ASANSÖR TRAFİK HESABI — Tablolardan Otomatik Veri Çeken Hesaplama Sayfası
B2: ▶ BU SAYFA TEK ASANSÖR İÇİNDİR — çıktısı PAFTA sayfasıdır. Birden fazla asansör için ÇOKLU ASANSÖR sayfasını kullanın. | Sarı hücreler: siz girersiniz. Beyaz hücreler: tablolardan/formüllerden otomatik gelir. Ayrıntılı nüfus girişi bu sayfanın altındadır.
B3: Kaynak: MMO/697, 2. Baskı, Ocak 2020, s.11-17. Yüksek bina ölçütü ve ayrıntılı kaynaklar için KAYNAKLAR sayfasına bakın.
B4: 1) GİRDİLER — yalnız SARI hücreleri ① → ⑩ sırasıyla doldurun
B5: ① Bina Tipi (hız, %k ve bekleme sınıfı buradan türer) | C5: Konut | D5: Manuel k (yalnız Tablo-9'da değer yoksa)
B6: → Tablo-9 %k tipi (otomatik) | C6: =IFERROR(INDEX('TABLO-10'!$L$2:$L$11,MATCH($C$5,'TABLO-10'!$J$2:$J$11,0)),"Manuel k gerekli") | D6: k girişi modu | E6: =IF(C6="Manuel k gerekli","Manuel gerekli",IF(LEFT($C$5,4)="Kamu","Tablo-9'da kamu yok → İş Merkezi %k varsayıldı (E5 ile değiştirilebilir)","Tablo-9 kilitli"))
B7: → Tablo-10 bekleme sınıfı (otomatik) | C7: =C5 | D7: V girişi modu | E7: =IF(C17="Manuel hız gerekli","Manuel gerekli",IF(LEFT($C$5,4)="Kamu","Tablo-2'de kamu yok → Büro/İş Merkezi hızı varsayıldı","Tablo-2 min otomatik — üstü de altı da seçilebilir"))
B8: Hesap standardı (yükseklikten otomatik) | C8: =IF(OR(E8>21.5,E9>30.5),"Yükseltilmiş","Standart") | D8: ② Bina yüksekliği (m) — kot noktasından saçak seviyesine (bodrum hariç) | E8: 39.98
B9: ③ Kat sayısı N (Ana giriş üstündeki kat adedi) | C9: 13 | D9: ④ Yapı yüksekliği (m) — bodrum ve çatı arası dâhil tüm katlar | E9: 43
B10: ="⑤ "&IF($C$5="Konut","Daire sayısı (bağımsız bölüm adedi)",IF(OR(LEFT($C$5,10)="İş Merkezi",LEFT($C$5,4)="Kamu"),"Toplam çalışma alanı (m²) → 12 m² = 1 kişi",IF(OR(LEFT($C$5,4)="Otel",$C$5="Hastane"),"Toplam yatak sayısı",IF($C$5="Katlı Otopark","Özel amaçlı araç adedi","Bu bina tipinde hızlı giriş yok — aşağıdaki 5) tabloyu doldurun")))) | C10: 44 | D10: Manuel V (opsiyonel — boş bırakılırsa Tablo-2 minimumu)
B11: =IF($C$5="Konut","⑥ Daire başına DİĞER oda sayısı (ilk yatak odası hariç; mutfak ve ıslak hacim sayılmaz)",IF($C$5="Katlı Otopark","⑥ Ticari amaçlı araç adedi",IF(OR($C$5="Konut",LEFT($C$5,10)="İş Merkezi",LEFT($C$5,4)="Kamu",LEFT($C$5,4)="Otel",$C$5="Hastane"),"⑥ (bu bina tipinde gerekmiyor — boş bırakın)","⑥ (kullanılmıyor — nüfusu aşağıdaki 5) tablodan girin)"))) | C11: 3 | D11: ↓ Bu iki kutu aşağıdaki 5) nüfus tablosunu otomatik doldurur. Ondalık yazarken VİRGÜL kullanın — nokta tarihe dönüşür.
B12: ⑦ Kat yüksekliği h (m) | C12: 3 | D12: =IF(AND(ISNUMBER($C$12),OR($C$12<2,$C$12>6)),"⚠ h olağandışı — 2–6 m bekleniyor",IF(AND(ISNUMBER($E$9),ISNUMBER($C$9),ISNUMBER($C$12),$E$9<$C$9*$C$12),"⚠ Yapı yüksekliği < N × h — kontrol et",IF(AND(ISNUMBER($E$8),ISNUMBER($E$9),$E$8>$E$9),"⚠ Bina yüks. > yapı yüks. olamaz","")))
B13: ⑧ Kabin kapasitesi P (kişi) | C13: 13 | D13: Yük (kg; 15 kişi = 1125 kg örnek istisnasıdır) | E13: =IF(C13="","",IF(C13=6,450,IF(C13=8,630,IF(C13=10,800,IF(C13=13,1000,IF(C13=15,1125,IF(C13=16,1275,IF(C13=20,1600,IF(C13=25,2000,IF(C13=30,2500,C13*75))))))))))
B14: ⑨ Kapı genişliği (mm) — ta/tk ve güncel tp için ortak giriş | C14: 1000 | E14: Tüm genişlikler ( 700 – 1300 mm ) hesaplanabilir. MMO Tablo-4'te 1000 ve 1200 mm, ISO 8100-32 Tablo 6'da 700 mm BASILI DEĞİLDİR; bu değerler komşu satırlardan enterpolasyon / dış değerleme ile türetilir ve paftada kaynağı 'ara değer' olarak yazılır. 'Kabin İçi Oto. Kat K.Ç.' kapı tipi 1200 ve 1300 mm'de tabloda yoktur — bu ikisinde E26/E27'ye imalatçı değeri girin.
B15: p = 0,8 × P (indirgenmiş kişi sayısı, %80 doluluk) | C15: =0.8*C13 | E15: p = 0,8P; TR ve R formüllerinde p kullanılır. | H15: yardımcı (gizli): H16 = efektif bodrum durak adedi · H17 = toplam seyahat mesafesi = (N + Nb) · h
B16: ⑩ Kapı tipi (Tablo-4) | C16: Merkezden Açılan Oto. | D16: ⑪ Bodrum durak adedi (ana giriş altı) — boş bırakırsanız 0 | E16: 2 | H16: =IF(AND(ISNUMBER($E$16),$E$16>=0,$E$16<=10,$E$16=INT($E$16)),$E$16,0)
B17: → Tablo-2 hız grubu (otomatik) | C17: =IFERROR(INDEX('TABLO-10'!$K$2:$K$11,MATCH($C$5,'TABLO-10'!$J$2:$J$11,0)),"Manuel hız gerekli") | E17: Hız seçimi bu gruba göre yapılır (EŞLEME tablosundan). | H17: =IF(AND(ISNUMBER($C$9),ISNUMBER($C$12)),($C$9+$H$16)*$C$12,"")
B18: 2) NÜFUS VE TABLO DEĞERLERİ (otomatik)
B19: Bodrum durağı, MMO/697 tanımı gereği H (Tablo-3) ve S (Tablo-5) değerlerini DEĞİŞTİRMEZ — bu iki büyüklük ana giriş üstündeki kat adedi N üzerinden tanımlıdır ve yukarı yoğun trafikte tur ana giriş katından başlar. Bodrum durağı yalnız (a) Tablo-2 asgari hız seçimindeki durak adedine ve (b) toplam seyahat mesafesine girer.
B20: b = Binadaki temel nüfus = Σc | C20: =$G$64 | D20: =IF(OR(NOT(ISNUMBER($G$64)),$G$64<=0),"⚠ NÜFUS GİRİLMEDİ — ⑤/⑥ kutularını (10-11. satır) doldurun","")
B21: n = Nüfus artış oranı (b<200 → 0,3 / b≥200 → 0,25) | C21: =IF(C20<200,0.3,0.25)
B22: B = Tasarım nüfusu = b + (n×b) | C22: =ROUNDUP(C20*(1+C21),0)
B23: V = Kabin hızı (durak adedi = N + 1 + bodrum) | C23: =IF(AND(ISNUMBER($E$10),COUNTIF($I$86:$I$95,$E$10)=0),"Manuel V geçersiz — listeden seçin (0,63 / 1 / 1,6 / 1,75 / 2 / 2,5 / 3 / 3,5 / 5 / 6 m/s)",IF(ISNUMBER($E$10),$E$10,IF(ISNUMBER($I$68),$I$68,"Manuel hız gerekli — bu bina tipinde Tablo-2 değeri yok"))) | E23: =IF(NOT(ISNUMBER($C$23)),"",IF(OR($C$17="Manuel hız gerekli",NOT(ISNUMBER($I$68))),"Tablo-2'de bu bina tipi yok — hız tümüyle proje kararıdır; gerekçesini paftaya yazın.",IF($C$23<$I$68,"⚠ Tablo-2 minimumu "&INT(ROUND($I$68,2))&","&TEXT(MOD(ROUND($I$68*100,0),100),"00")&" m/s — seçilen "&INT(ROUND($C$23,2))&","&TEXT(MOD(ROUND($C$23*100,0),100),"00")&" m/s bunun ALTINDA. Bekleme süresi sağlandığı için hesap geçerlidir; gerekçeyi paftaya yazın.",IF($C$23>$I$68,"Tablo-2 minimumu "&INT(ROUND($I$68,2))&","&TEXT(MOD(ROUND($I$68*100,0),100),"00")&" m/s — seçilen "&INT(ROUND($C$23,2))&","&TEXT(MOD(ROUND($C$23*100,0),100),"00")&" m/s (üstü).","Tablo-2 minimumu uygulandı: "&INT(ROUND($C$23,2))&","&TEXT(MOD(ROUND($C$23*100,0),100),"00")&" m/s. Bekleme tutmazsa listeden üst hızı seçebilirsiniz."))))
B24: H = Ortalama en yüksek dönüş katı | C24: =IFERROR(INDEX('TABLO-3'!$B$3:$AD$32,MATCH(VALUE($C$9),'TABLO-3'!$A$3:$A$32,0),MATCH(VALUE($C$13),'TABLO-3'!$B$2:$AD$2,0)),"P/N aralık dışı (P:6-34, N:1-30)")
B25: S = Ortalama durak adedi | C25: =IFERROR(INDEX('TABLO-5'!$B$3:$AD$32,MATCH(VALUE($C$9),'TABLO-5'!$A$3:$A$32,0),MATCH(VALUE($C$13),'TABLO-5'!$B$2:$AD$2,0)),"P/N aralık dışı (P:6-34, N:1-30)") | H25: yardımcı (gizli): manuel giriş öncesi MMO tablo değerleri — PAFTA sapma özeti bunları okur
B26: ta = Kapı açılma süresi | C26: =IF(ISNUMBER($E$26),$E$26,IFERROR(IF(ISNUMBER(INDEX('TABLO-4'!$I$4:$N$10,MATCH(VALUE($C$14),'TABLO-4'!$A$4:$A$10,0),IF($C$16="Teleskopik Otomatik",1,IF(OR($C$16="Merkezden Açılan Oto.",$C$16="Merkezden Açılan Otomatik"),3,5)))),INDEX('TABLO-4'!$I$4:$N$10,MATCH(VALUE($C$14),'TABLO-4'!$A$4:$A$10,0),IF($C$16="Teleskopik Otomatik",1,IF(OR($C$16="Merkezden Açılan Oto.",$C$16="Merkezden Açılan Otomatik"),3,5))),"Veri yok"),"Veri yok")) | D26: Manuel ta (sn) — boş bırakılırsa Tablo-4 | H26: =IFERROR(INDEX('TABLO-4'!$I$4:$N$10,MATCH(VALUE($C$14),'TABLO-4'!$A$4:$A$10,0),IF($C$16="Teleskopik Otomatik",1,IF(OR($C$16="Merkezden Açılan Oto.",$C$16="Merkezden Açılan Otomatik"),3,5))),"")
B27: tk = Kapı kapanma süresi | C27: =IF(ISNUMBER($E$27),$E$27,IFERROR(IF(ISNUMBER(INDEX('TABLO-4'!$I$4:$N$10,MATCH(VALUE($C$14),'TABLO-4'!$A$4:$A$10,0),IF($C$16="Teleskopik Otomatik",2,IF(OR($C$16="Merkezden Açılan Oto.",$C$16="Merkezden Açılan Otomatik"),4,6)))),INDEX('TABLO-4'!$I$4:$N$10,MATCH(VALUE($C$14),'TABLO-4'!$A$4:$A$10,0),IF($C$16="Teleskopik Otomatik",2,IF(OR($C$16="Merkezden Açılan Oto.",$C$16="Merkezden Açılan Otomatik"),4,6))),"Veri yok"),"Veri yok")) | D27: Manuel tk (sn) — boş bırakılırsa Tablo-4 | H27: =IFERROR(INDEX('TABLO-4'!$I$4:$N$10,MATCH(VALUE($C$14),'TABLO-4'!$A$4:$A$10,0),IF($C$16="Teleskopik Otomatik",2,IF(OR($C$16="Merkezden Açılan Oto.",$C$16="Merkezden Açılan Otomatik"),4,6))),"")
B28: tg = Tek kat geçme süresi | C28: =IF(ISNUMBER($E$28),$E$28,IF($C$23<1,10,IF($C$23=1,7,IF($C$23=1.6,6,IF($C$23=1.75,5.8875,IF($C$23=2,5.7,IF($C$23=2.5,5.5,IF($C$23=3,5.25,IF($C$23=3.5,5,IF($C$23=5,4.5,IF($C$23>5,4.3,"Hız Tablo-6 dışı"))))))))))) | D28: Manuel tg (sn) — boş bırakılırsa Tablo-6 | H28: =IF($C$23<1,10,IF($C$23=1,7,IF($C$23=1.6,6,IF($C$23=1.75,5.8875,IF($C$23=2,5.7,IF($C$23=2.5,5.5,IF($C$23=3,5.25,IF($C$23=3.5,5,IF($C$23=5,4.5,IF($C$23>5,4.3,""))))))))))
B29: tp = Kişi transfer süresi | C29: =IF(ISNUMBER($E$29),$E$29,IFERROR(INDEX('TABLO-8'!$B$2:$H$2,1,MATCH(VALUE($C$14),'TABLO-8'!$B$1:$H$1,0)),"tp verisi yok")) | D29: Manuel tp (sn) — boş bırakılırsa Tablo-8 | H29: =IFERROR(INDEX('TABLO-8'!$B$2:$H$2,1,MATCH(VALUE($C$14),'TABLO-8'!$B$1:$H$1,0)),"")
B30: k = Taşınacak insan yüzdesi | C30: =IF(AND(LEFT($C$5,4)="Kamu",ISNUMBER($E$5),$E$5>0,$E$5<=1),$E$5,IF($C$6="Manuel k gerekli",IF(AND(ISNUMBER($E$5),$E$5>0,$E$5<=1),$E$5,"Manuel k gerekli"),IFERROR(INDEX('TABLO-9'!$D$2:$E$6,MATCH($C$6,'TABLO-9'!$A$2:$A$6,0),IF($C$8="Standart",1,2)),"Manuel k gerekli"))) | E30: =IF(COUNT($E$26:$E$29)=0,"","⚠ "&COUNT($E$26:$E$29)&" adet süre imalatçı verisiyle değiştirildi (MMO Tablo-4/6/8 yerine). Paftada marka-model ve teknik föy referansı belirtilmelidir.")
B32: 3) TUR SÜRESİ VE ASANSÖR SAYISI
B33: tv = h / V (katlar arası geçiş süresi) | C33: =IFERROR($C$12/$C$23,"Hız geçersiz")
B34: ts = ta + tk + tg − tv (her duraktaki zaman kaybı) | C34: =IFERROR(C26+C27+C28-C33,"Kapı verisi eksik")
B35: TR = 2·H·tv + (S+1)·ts + 2·p·tp (tur süresi; p = 0,8·P) | C35: =IFERROR(2*C24*C33+(C25+1)*C34+2*C15*C29,"H/S/kapı verisi eksik") | E35: MMO/697 s.11-12 denklemi uygulanır. Kitabın s.54'teki 15 kişilik TR1 basılı aritmetik sonucu hatalı olduğundan denklem sonucu esas alınır.
B36: R = 5·60·p / TR (5 dk'da taşınan kişi) | C36: =IFERROR(5*60*C15/C35,"—")
B37: n = Uygulanan asansör adedi (C39 boşsa MAX[taşıma adedi; bekleme adedi]) | C37: =IF(AND(ISNUMBER($C$39),$C$39>=1),$C$39,$H$37) | E37: =IF($V$68=0,"ÖNERİ: hesaplanamadı — girdileri kontrol edin","ÖNERİ: "&TRIM(INDEX($B$70:$B$83,$V$68))&" → "&INDEX($R$70:$R$83,$V$68)&" adet, bekleme "&INT(ROUND(INDEX($S$70:$S$83,$V$68),1))&","&TEXT(MOD(ROUND(INDEX($S$70:$S$83,$V$68)*10,0),10),"0")&" sn — "&INDEX($U$70:$U$83,$V$68)&" (ayrıntı: 6) blok)") | H37: =IFERROR(MAX(1,ROUNDUP(($C$22*$C$30)/$C$36,0),ROUNDUP($C$35/$K$68,0)),"—")
B38: Ieer = TR / n (hesaplanan bekleme süresi) | C38: =IFERROR(C35/C37,"—") | E38: =IF(OR(NOT(ISNUMBER($C$35)),NOT(ISNUMBER($C$37)),NOT(ISNUMBER($K$68))),"",IF($C$37<=1,"TEK ASANSÖR YETERLİ — bekleme "&INT(ROUND($C$38,1))&","&TEXT(MOD(ROUND($C$38*10,0),10),"0")&" sn.","TEK ASANSÖR İÇİN: TR ≤ "&INT(ROUND($K$68,1))&","&TEXT(MOD(ROUND($K$68*10,0),10),"0")&" sn olmalı; şu an "&INT(ROUND($C$35,1))&","&TEXT(MOD(ROUND($C$35*10,0),10),"0")&" sn ("&INT(ROUND(($C$35-$K$68),1))&","&TEXT(MOD(ROUND(($C$35-$K$68)*10,0),10),"0")&" sn fazla). ts=ta+tk+tg toplamını "&INT(ROUND(($C$35-$K$68)/($C$25+1),1))&","&TEXT(MOD(ROUND(($C$35-$K$68)/($C$25+1)*10,0),10),"0")&" sn kısmak gerekir — E26:E29 kutularına imalatçı verisi girin, kabini küçültün veya hızı artırın."))
B39: Asansör adedini ELLE dene (boş bırak = otomatik) | E39: =IF(NOT(ISNUMBER($H$37)),"",IF(NOT(ISNUMBER($C$39)),"Otomatik: hesap "&$H$37&" adet gerektiriyor.",IF($C$39<$H$37,"⚠ Elle "&$C$39&" adet seçildi; MMO/697 hesabı "&$H$37&" adet gerektiriyor. SONUÇ satırına bakın.",IF($C$39>$H$37,"Elle "&$C$39&" adet seçildi — hesabın gerektirdiği "&$H$37&" adetten fazla.","Elle "&$C$39&" adet seçildi — otomatik sonuçla aynı."))))
B40: 4) SONUÇ — Tablo-10 ile karşılaştırma
B41: Şartlı Kabul eşiği (seçilen sınıf için) | C41: =IFERROR(INDEX('TABLO-10'!$F$2:$F$11,MATCH($C$7,'TABLO-10'!$A$2:$A$11,0)),"Yok")
...

Sheet PAFTA
A1: ASANSÖR TRAFİK HESABI
A2: BİNADA BULUNAN İNSAN SAYISININ TESPİTİ (B)
A3: Bina tipi / hesap standardı (otomatik) | B3: =IFERROR(HESAPLAMA!C5&" / "&HESAPLAMA!C8,"—") | D3: MMO Tablo-9/10
A4: Kat sayısı N (ana giriş üstü) / bodrum durağı | B4: =IFERROR(HESAPLAMA!C9&IF(HESAPLAMA!$H$16>0," + "&HESAPLAMA!$H$16&" bodrum durağı",""),"—") | C4: kat | D4: Projeden
A5: Bina / yapı yüksekliği | B5: =IFERROR(INT(ROUND(HESAPLAMA!E8,2))&","&TEXT(MOD(ROUND(HESAPLAMA!E8*100,0),100),"00")&" / "&INT(ROUND(HESAPLAMA!E9,2))&","&TEXT(MOD(ROUND(HESAPLAMA!E9*100,0),100),"00"),"—") | C5: m | D5: BYKHY md.4
A6: =IF(HESAPLAMA!C5="Konut","Tablo-1: Her dairenin ilk yatak odası için 2 kişi, diğer odaların her biri için 1 kişi alınır; mutfak ve ıslak hacimler hesaba katılmaz.",IF(OR(LEFT(HESAPLAMA!C5,10)="İş Merkezi",LEFT(HESAPLAMA!C5,4)="Kamu"),"Tablo-1: Çalışma alanının her 12 m²si için 1 kişi alınır.",IF(LEFT(HESAPLAMA!C5,4)="Otel","Tablo-1: Her yatak için 1 kişi alınır.",IF(HESAPLAMA!C5="Hastane","Tablo-1: Her yatak için 3 kişi alınır.",IF(HESAPLAMA!C5="Katlı Otopark","Tablo-1: Özel amaçlı araç başına 1 kişi, ticari amaçlı araç başına 1,5 kişi alınır.","Nüfus MMO/697 Tablo-1'e göre hesaplanmıştır.")))))
A7: =IF(AND(HESAPLAMA!C5="Konut",ISNUMBER(HESAPLAMA!C11)),IF(HESAPLAMA!C11=INT(HESAPLAMA!C11),"Daireler "&HESAPLAMA!C11&"+1 olup bir dairede sayılan oda adedi "&(HESAPLAMA!C11+1)&" olarak alınmıştır (1 ilk yatak odası + "&HESAPLAMA!C11&" diğer oda). Bir dairedeki kişi sayısı = 2 + ("&HESAPLAMA!C11&" × 1) = "&(2+HESAPLAMA!C11)&" kişi.","Daire başına ortalama diğer oda adedi "&INT(ROUND(HESAPLAMA!C11,2))&","&TEXT(MOD(ROUND(HESAPLAMA!C11*100,0),100),"00")&" alınmıştır. Bir dairedeki ortalama kişi sayısı = 2 + "&INT(ROUND(HESAPLAMA!C11,2))&","&TEXT(MOD(ROUND(HESAPLAMA!C11*100,0),100),"00")&" = "&INT(ROUND((2+HESAPLAMA!C11),2))&","&TEXT(MOD(ROUND((2+HESAPLAMA!C11)*100,0),100),"00")&" kişi."),IF(AND(OR(LEFT(HESAPLAMA!C5,10)="İş Merkezi",LEFT(HESAPLAMA!C5,4)="Kamu"),ISNUMBER(HESAPLAMA!C10)),"Binadaki toplam çalışma alanı "&IF(HESAPLAMA!C10=INT(HESAPLAMA!C10),HESAPLAMA!C10&"",INT(ROUND(HESAPLAMA!C10,2))&","&TEXT(MOD(ROUND(HESAPLAMA!C10*100,0),100),"00"))&" m² olarak alınmıştır.",IF(AND(OR(LEFT(HESAPLAMA!C5,4)="Otel",HESAPLAMA!C5="Hastane"),ISNUMBER(HESAPLAMA!C10)),"Binadaki toplam yatak sayısı "&IF(HESAPLAMA!C10=INT(HESAPLAMA!C10),HESAPLAMA!C10&"",INT(ROUND(HESAPLAMA!C10,2))&","&TEXT(MOD(ROUND(HESAPLAMA!C10*100,0),100),"00"))&" olarak alınmıştır.",IF(AND(HESAPLAMA!C5="Katlı Otopark",ISNUMBER(HESAPLAMA!C10)),"Özel amaçlı araç adedi "&IF(HESAPLAMA!C10=INT(HESAPLAMA!C10),HESAPLAMA!C10&"",INT(ROUND(HESAPLAMA!C10,2))&","&TEXT(MOD(ROUND(HESAPLAMA!C10*100,0),100),"00"))&", ticari amaçlı araç adedi "&IF(ISNUMBER(HESAPLAMA!C11),IF(HESAPLAMA!C11=INT(HESAPLAMA!C11),HESAPLAMA!C11&"",INT(ROUND(HESAPLAMA!C11,2))&","&TEXT(MOD(ROUND(HESAPLAMA!C11*100,0),100),"00"))&"","0")&" olarak alınmıştır.","Nüfus, hesap sayfasındaki ayrıntılı tablodan alınmıştır."))))
A8: =IF(NOT(ISNUMBER(HESAPLAMA!C20)),"",IF(AND(ISNUMBER(HESAPLAMA!C10),ABS(HESAPLAMA!C20-(IF(HESAPLAMA!C5="Konut",HESAPLAMA!C10*(2+HESAPLAMA!C11),IF(OR(LEFT(HESAPLAMA!C5,10)="İş Merkezi",LEFT(HESAPLAMA!C5,4)="Kamu"),HESAPLAMA!C10/12,IF(LEFT(HESAPLAMA!C5,4)="Otel",HESAPLAMA!C10,IF(HESAPLAMA!C5="Hastane",HESAPLAMA!C10*3,IF(HESAPLAMA!C5="Katlı Otopark",HESAPLAMA!C10+IF(ISNUMBER(HESAPLAMA!C11),HESAPLAMA!C11*1.5,0),-1)))))))<0.01),IF(HESAPLAMA!C5="Konut","Daire adedi "&IF(HESAPLAMA!C10=INT(HESAPLAMA!C10),HESAPLAMA!C10&"",INT(ROUND(HESAPLAMA!C10,2))&","&TEXT(MOD(ROUND(HESAPLAMA!C10*100,0),100),"00"))&" → b = "&IF(HESAPLAMA!C10=INT(HESAPLAMA!C10),HESAPLAMA!C10&"",INT(ROUND(HESAPLAMA!C10,2))&","&TEXT(MOD(ROUND(HESAPLAMA!C10*100,0),100),"00"))&" × "&IF((2+HESAPLAMA!C11)=INT((2+HESAPLAMA!C11)),(2+HESAPLAMA!C11)&"",INT(ROUND((2+HESAPLAMA!C11),2))&","&TEXT(MOD(ROUND((2+HESAPLAMA!C11)*100,0),100),"00"))&" = "&IF(HESAPLAMA!C20=INT(HESAPLAMA!C20),HESAPLAMA!C20&"",INT(ROUND(HESAPLAMA!C20,2))&","&TEXT(MOD(ROUND(HESAPLAMA!C20*100,0),100),"00"))&" kişi",IF(OR(LEFT(HESAPLAMA!C5,10)="İş Merkezi",LEFT(HESAPLAMA!C5,4)="Kamu"),"b = "&IF(HESAPLAMA!C10=INT(HESAPLAMA!C10),HESAPLAMA!C10&"",INT(ROUND(HESAPLAMA!C10,2))&","&TEXT(MOD(ROUND(HESAPLAMA!C10*100,0),100),"00"))&" ÷ 12 = "&IF(HESAPLAMA!C20=INT(HESAPLAMA!C20),HESAPLAMA!C20&"",INT(ROUND(HESAPLAMA!C20,2))&","&TEXT(MOD(ROUND(HESAPLAMA!C20*100,0),100),"00"))&" kişi",IF(LEFT(HESAPLAMA!C5,4)="Otel","b = "&IF(HESAPLAMA!C10=INT(HESAPLAMA!C10),HESAPLAMA!C10&"",INT(ROUND(HESAPLAMA!C10,2))&","&TEXT(MOD(ROUND(HESAPLAMA!C10*100,0),100),"00"))&" × 1 = "&IF(HESAPLAMA!C20=INT(HESAPLAMA!C20),HESAPLAMA!C20&"",INT(ROUND(HESAPLAMA!C20,2))&","&TEXT(MOD(ROUND(HESAPLAMA!C20*100,0),100),"00"))&" kişi",IF(HESAPLAMA!C5="Hastane","b = "&IF(HESAPLAMA!C10=INT(HESAPLAMA!C10),HESAPLAMA!C10&"",INT(ROUND(HESAPLAMA!C10,2))&","&TEXT(MOD(ROUND(HESAPLAMA!C10*100,0),100),"00"))&" × 3 = "&IF(HESAPLAMA!C20=INT(HESAPLAMA!C20),HESAPLAMA!C20&"",INT(ROUND(HESAPLAMA!C20,2))&","&TEXT(MOD(ROUND(HESAPLAMA!C20*100,0),100),"00"))&" kişi","b = ("&IF(HESAPLAMA!C10=INT(HESAPLAMA!C10),HESAPLAMA!C10&"",INT(ROUND(HESAPLAMA!C10,2))&","&TEXT(MOD(ROUND(HESAPLAMA!C10*100,0),100),"00"))&" × 1) + ("&IF(ISNUMBER(HESAPLAMA!C11),IF(HESAPLAMA!C11=INT(HESAPLAMA!C11),HESAPLAMA!C11&"",INT(ROUND(HESAPLAMA!C11,2))&","&TEXT(MOD(ROUND(HESAPLAMA!C11*100,0),100),"00"))&"","0")&" × 1,5) = "&IF(HESAPLAMA!C20=INT(HESAPLAMA!C20),HESAPLAMA!C20&"",INT(ROUND(HESAPLAMA!C20,2))&","&TEXT(MOD(ROUND(HESAPLAMA!C20*100,0),100),"00"))&" kişi")))),"b = Σc = "&IF(HESAPLAMA!C20=INT(HESAPLAMA!C20),HESAPLAMA!C20&"",INT(ROUND(HESAPLAMA!C20,2))&","&TEXT(MOD(ROUND(HESAPLAMA!C20*100,0),100),"00"))&" kişi (hesap sayfasındaki ayrıntılı nüfus tablosundan)"))
A9: b = Sürekli kişi / n = artış | B9: =IFERROR(IF(HESAPLAMA!C20=INT(HESAPLAMA!C20),HESAPLAMA!C20&"",INT(ROUND(HESAPLAMA!C20,2))&","&TEXT(MOD(ROUND(HESAPLAMA!C20*100,0),100),"00"))&" kişi / "&INT(ROUND(HESAPLAMA!C21,2))&","&TEXT(MOD(ROUND(HESAPLAMA!C21*100,0),100),"00"),"—") | D9: Tablo-1
A10: ="B = b + (n·b) = "&INT(ROUND(HESAPLAMA!C20,1))&","&TEXT(MOD(ROUND(HESAPLAMA!C20*10,0),10),"0")&" + ("&INT(ROUND(HESAPLAMA!C21,2))&","&TEXT(MOD(ROUND(HESAPLAMA!C21*100,0),100),"00")&"·"&INT(ROUND(HESAPLAMA!C20,1))&","&TEXT(MOD(ROUND(HESAPLAMA!C20*10,0),10),"0")&") = "&ROUND(HESAPLAMA!C22,0)&" kişi"
A11: HESAP DEĞERLERİ
A12: h = Katlar arası mesafe | B12: =IFERROR(HESAPLAMA!C12,"—") | C12: m | D12: =IFERROR("Projeden — toplam seyahat "&INT(ROUND(HESAPLAMA!$H$17,2))&","&TEXT(MOD(ROUND(HESAPLAMA!$H$17*100,0),100),"00")&" m","Projeden")
A13: V = Kabin hızı | B13: =IFERROR(HESAPLAMA!C23,"—") | C13: m/s | D13: =IF(HESAPLAMA!$H$16>0,"Tablo-2 (durak = N+1+bodrum)","Tablo-2")
A14: H = Ortalama en yüksek dönüş katı | B14: =IFERROR(HESAPLAMA!C24,"—") | D14: Tablo-3
A15: tv = Katlar arası geçiş = h/V | B15: =IFERROR(HESAPLAMA!C33,"—") | C15: s | D15: h/V
A16: S = Ortalama durak adedi | B16: =IFERROR(HESAPLAMA!C25,"—") | D16: Tablo-5
A17: ts = ta+tk+tg−tv (duruş kaybı) | B17: =IFERROR(HESAPLAMA!C34,"—") | C17: s
A18: P = Kabin kişi adedi | B18: =IFERROR(HESAPLAMA!C13,"—") | C18: kişi | D18: =IFERROR(IF(HESAPLAMA!C13=15,"MMO örneği s.53-54 (Tablo-7 dışı)","Tablo-7"),"—")
A19: p = 0,8·P (indirgenmiş kişi) | B19: =IFERROR(HESAPLAMA!C15,"—") | C19: kişi | D19: MMO/697
A20: tp = Kişi transfer zamanı | B20: =IFERROR(HESAPLAMA!C29,"—") | C20: s | D20: =IF(ISNUMBER(HESAPLAMA!$E$29),"İmalatçı verisi",IF(HESAPLAMA!$C$14=700,"ISO 8100-32:2020 Tablo 6 (kapsam dışı — dış değerleme)","ISO 8100-32:2020, Tablo 6"))
A21: ta = Kapı açılma zamanı | B21: =IFERROR(HESAPLAMA!C26,"—") | C21: s | D21: =IF(ISNUMBER(HESAPLAMA!$E$26),"İmalatçı verisi",IF(OR(HESAPLAMA!$C$14=1000,HESAPLAMA!$C$14=1200),"Tablo-4 (ara değer — enterpolasyon)","Tablo-4"))
A22: tk = Kapı kapanma zamanı | B22: =IFERROR(HESAPLAMA!C27,"—") | C22: s | D22: =IF(ISNUMBER(HESAPLAMA!$E$27),"İmalatçı verisi",IF(OR(HESAPLAMA!$C$14=1000,HESAPLAMA!$C$14=1200),"Tablo-4 (ara değer — enterpolasyon)","Tablo-4"))
A23: tg = Tek katı geçme zamanı | B23: =IFERROR(HESAPLAMA!C28,"—") | C23: s | D23: =IF(ISNUMBER(HESAPLAMA!$E$28),"İmalatçı verisi",IF(OR(HESAPLAMA!$C$23=1.75,HESAPLAMA!$C$23=3),"Tablo-6 (ara değer — enterpolasyon)","Tablo-6"))
A24: ASANSÖRÜN BİR SEFERİ İÇİN GEREKLİ SEYİR ZAMANI (TR)
A25: TR = 2·H·tv + (S+1)·ts + 2·p·tp
A26: =IF(HESAPLAMA!$E$45<>"","—","TR = 2·"&INT(ROUND(HESAPLAMA!C24,2))&","&TEXT(MOD(ROUND(HESAPLAMA!C24*100,0),100),"00")&"·"&INT(ROUND(HESAPLAMA!C33,2))&","&TEXT(MOD(ROUND(HESAPLAMA!C33*100,0),100),"00")&" + ("&INT(ROUND(HESAPLAMA!C25,2))&","&TEXT(MOD(ROUND(HESAPLAMA!C25*100,0),100),"00")&"+1)·"&INT(ROUND(HESAPLAMA!C34,2))&","&TEXT(MOD(ROUND(HESAPLAMA!C34*100,0),100),"00")&" + 2·"&INT(ROUND(HESAPLAMA!C15,1))&","&TEXT(MOD(ROUND(HESAPLAMA!C15*10,0),10),"0")&"·"&INT(ROUND(HESAPLAMA!C29,1))&","&TEXT(MOD(ROUND(HESAPLAMA!C29*10,0),10),"0")&" = "&INT(ROUND(HESAPLAMA!C35,2))&","&TEXT(MOD(ROUND(HESAPLAMA!C35*100,0),100),"00")&" s")
A27: GEREKLİ ASANSÖR SAYISININ HESABI
A28: =IF(HESAPLAMA!$E$45<>"","—","R = 5·60·p / TR = 5·60·"&INT(ROUND(HESAPLAMA!C15,1))&","&TEXT(MOD(ROUND(HESAPLAMA!C15*10,0),10),"0")&" / "&INT(ROUND(HESAPLAMA!C35,2))&","&TEXT(MOD(ROUND(HESAPLAMA!C35*100,0),100),"00")&" = "&INT(ROUND(HESAPLAMA!C36,1))&","&TEXT(MOD(ROUND(HESAPLAMA!C36*10,0),10),"0")&" kişi / 5 dk")
A29: k = Taşınacak insan yüzdesi | B29: =IFERROR(HESAPLAMA!C30,"—") | D29: Tablo-9
A30: =IF(HESAPLAMA!$E$45<>"","—","Taşıma adedi = "&ROUNDUP((HESAPLAMA!C22*HESAPLAMA!C30)/HESAPLAMA!C36,0)&"; Bekleme adedi = "&ROUNDUP(HESAPLAMA!C35/HESAPLAMA!$K$68,0)&" (uygulanan sınır Izul = "&HESAPLAMA!$K$68&" sn — Tablo-10 "&HESAPLAMA!$C$8&")"&" → Nihai gerekli sayı = "&HESAPLAMA!C37&" adet"&IF(AND(ISNUMBER(HESAPLAMA!$C$41),HESAPLAMA!$C$41>0)," | Şartlı Kabul sınırı ("&HESAPLAMA!$C$41&" sn) için "&ROUNDUP(HESAPLAMA!C35/HESAPLAMA!$C$41,0)&" adet yeterli olurdu (taahhütname gerekir)",""))
A31: BEKLEME ZAMANI (IZUL) KONTROLÜ
A32: =IF(HESAPLAMA!$E$45<>"","—","Ieer = TR / n = "&INT(ROUND(HESAPLAMA!$C$35,2))&","&TEXT(MOD(ROUND(HESAPLAMA!$C$35*100,0),100),"00")&" / "&HESAPLAMA!$C$37&" = "&INT(ROUND(HESAPLAMA!$C$38,1))&","&TEXT(MOD(ROUND(HESAPLAMA!$C$38*10,0),10),"0")&" sn"&" → "&HESAPLAMA!$C$8&" sınır "&IF(HESAPLAMA!$C$8="Yükseltilmiş",HESAPLAMA!$C$43,HESAPLAMA!$C$42)&" sn: "&IF(HESAPLAMA!$C$38<=IF(HESAPLAMA!$C$8="Yükseltilmiş",HESAPLAMA!$C$43,HESAPLAMA!$C$42),"SAĞLANIYOR","AŞILIYOR")&IF(AND(ISNUMBER(HESAPLAMA!$C$41),HESAPLAMA!$C$41>0)," | Şartlı Kabul sınırı "&HESAPLAMA!$C$41&" sn: "&IF(HESAPLAMA!$C$38<=HESAPLAMA!$C$41,"sağlanıyor","aşılıyor")," | bu bina sınıfında şartlı kabul yoktur"))
A33: =HESAPLAMA!C44
A34: =IF(HESAPLAMA!$E$45<>"",HESAPLAMA!$E$45,IF(LEFT(HESAPLAMA!$C$44,5)="Kabul","Bekleme süresi kriteri sağlanmıyor; kabin kapasitesi, hız veya asansör adedi gözden geçirilmelidir.",IF(LEFT(HESAPLAMA!$C$44,6)="Şartlı","Toplamda "&HESAPLAMA!$C$37&" adet "&HESAPLAMA!$C$13&" kişilik ("&HESAPLAMA!$E$13&" kg), "&INT(ROUND(HESAPLAMA!$C$23,2))&","&TEXT(MOD(ROUND(HESAPLAMA!$C$23*100,0),100),"00")&" m/s hızında asansör"&" önerilmektedir. Bekleme süresi "&INT(ROUND(HESAPLAMA!$C$38,1))&","&TEXT(MOD(ROUND(HESAPLAMA!$C$38*10,0),10),"0")&" sn olup MMO/697 Tablo-10 şartlı kabul sınırı "&HESAPLAMA!$C$41&" sn içindedir; taahhütname ile uygundur. Standart sınır ("&HESAPLAMA!$C$42&" sn) için "&ROUNDUP(HESAPLAMA!$C$35/HESAPLAMA!$C$42,0)&" adet gerekir.","Toplamda "&HESAPLAMA!$C$37&" adet "&HESAPLAMA!$C$13&" kişilik ("&HESAPLAMA!$E$13&" kg), "&INT(ROUND(HESAPLAMA!$C$23,2))&","&TEXT(MOD(ROUND(HESAPLAMA!$C$23*100,0),100),"00")&" m/s hızında asansör"&" yapılması uygundur.")))

Sheet NÜFUS GİRİŞİ
A1: MMO/697 NÜFUS KATSAYILARI — YARDIMCI REFERANS
A2: Nüfus girdileri artık HESAPLAMA ve ÇOKLU ASANSÖR sayfalarının altındaki ayrıntılı tablolara girilir. Bu sayfa yalnız katsayı kaynağıdır.
A3: TABLO-1 KATSAYI EŞLEMESİ | E3: KULLANIM NOTLARI
A4: Kalem | B4: Birim | C4: Kişi katsayısı | E4: Konut: Her bağımsız bölümün ilk yatak odasını ve diğer odalarını ayrı miktarlar olarak girin.
A5: KONUT — İlk yatak odası | B5: oda | C5: 2 | E5: İş merkezi / resmî bina: Miktar alanına toplam çalışma alanını m² olarak girin; katsayı 1/12'dir.
A6: KONUT — Diğer oda | B6: oda | C6: 1 | E6: Karma yapı: Her kullanım kalemini ayrı satıra ekleyin. Tablo-9'da k yoksa manuel k zorunludur.
A7: OTEL — Yatak | B7: yatak | C7: 1 | E7: DOĞRUDAN KİŞİ kalemi MMO/697 Tablo-1 dışındaki proje verileri içindir; mühendislik gerekçesini açıklama alanına yazın.
A8: İŞ MERKEZİ — Çalışma alanı | B8: m² | C8: 0.083333333 | E8: HIZLI GİRİŞ: HESAPLAMA ve ÇOKLU ASANSÖR sayfalarındaki ⑤/⑥ kutuları bina tipine göre doğru Tablo-1 kalemini kendisi seçer; bu tabloya yalnız karma/istisnai nüfus için satır eklenir.
A9: HASTANE — Yatak | B9: yatak | C9: 3
A10: RESMİ BİNA — Çalışma alanı | B10: m² | C10: 0.083333333
A11: OTOPARK — Ticari araç | B11: araç | C11: 1.5
A12: OTOPARK — Özel araç | B12: araç | C12: 1
A13: DOĞRUDAN KİŞİ — Tablo-1 dışı | B13: kişi | C13: 1

Sheet KAYNAKLAR
A1: HESAP VE UYUM KAYNAKLARI
A3: Konu | B3: Kaynak | C3: Konum | D3: Uygulama notu
A4: Ana trafik hesabı | B4: MMO/697 — Asansör Avan Projesi Hazırlama Teknik Esasları, 2. Baskı, Ocak 2020 | C4: s.11-17 | D4: TR, R, H, S, p, Tablo 1-10 ve b=Σc
A5: Yüksek bina tanımı | B5: Binaların Yangından Korunması Hakkında Yönetmelik Kılavuzu | C5: md.4 / PDF s.15 | D5: Bina yüksekliği >21,50 m veya yapı yüksekliği >30,50 m ise yüksek bina
A6: Resmî kaynak URL | B6: https://webdosya.csb.gov.tr/v2/meslekihizmetler/2026/05/Binalar-n-Yang-n-Korunmas-Hakk-nda-Y-netmelik-K-lavuzu-20260507112134.pdf | C6: ÇŞİDB Mesleki Hizmetler Genel Müdürlüğü | D6: Yüksek bina ölçütü çalışma kitabında otomatik standarda dönüştürülür
A7: 15 kişi / 1125 kg | B7: MMO/697 örnek proje | C7: s.53-54 | D7: Tablo-7 kaydı değildir; örnek istisnası olarak etiketlenir
A8: Basılı TR₁ aritmetiği | B8: MMO/697 örnek proje | C8: s.54 | D8: Basılı 149,9955 s yerine kitabın eski tp=2,2 s girdileriyle denklem sonucu yaklaşık 174,03 s'dir; güncel tp tablosunda TR değişir
A9: Kişi transfer zamanı (tp) | B9: ISO 8100-32:2020, "Lifts — Part 32: Planning and selection of passenger lifts to be installed in office, hotel and residential buildings", Tablo 6 | C9: Tablo-8 | D9: 800 mm: 1,2 s | 900 mm: 1,1 s | 1000-1100 mm: 1,0 s | 1200-1300 mm: 0,9 s. 800 mm satırı ISO/CD 8100-32 (2017) Tablo 6 ve Barney/Peters (2018) Tablo 3 ile teyitlidir; 1300 mm, 1200 mm değerinin düz devamıdır.
A10: Not: Yükseklik değerleri mimari projeden ayrı ayrı girilmelidir; N×h yaklaşımı bina/yapı yüksekliği tanımlarının yerine kullanılmaz.
A11: Bina yüksekliği nedir | B11: Binanın kot aldığı noktadan saçak seviyesine kadar olan mesafedir; bodrum katlar bu ölçüye girmez. | C11: BYKHY md.4 | D11: HESAPLAMA E8 / ÇOKLU ASANSÖR D8 hücresine yazılır.
A12: Yapı yüksekliği nedir | B12: Bodrum katlar, asma katlar ve çatı arası piyesler dâhil, yapının inşa edilen bütün katlarının toplam yüksekliğidir. Bu nedenle yapı yüksekliği ≥ bina yüksekliği; bodrumsuz binada ikisi eşittir. | C12: BYKHY md.4 | D12: HESAPLAMA E9 / ÇOKLU ASANSÖR D9 hücresine yazılır.
A13: Neden ikisi de soruluyor | B13: Yüksek bina ölçütü iki koşuldan BİRİ aşılınca oluşur: bina yüksekliği > 21,50 m VEYA yapı yüksekliği > 30,50 m. Örnek: 3 bodrum (9 m) + zemin + 6 normal kat (21 m) → bina yüksekliği 21 m ile sınırın altındadır, ancak bir bodrum daha eklenince yapı yüksekliği 33 m olur ve bina yüksek bina sınıfına girer. | C13: BYKHY md.4 | D13: Yüksek binada HESAPLAMA C8 'Yükseltilmiş'e döner: k yüzdesi artar, Tablo-10 bekleme sınırı düşer (kamu binasında 40 → 30 sn); sonuç genelde daha fazla asansördür.
A14: Sık yapılan hata | B14: N × h çarpımı yükseklik yerine kullanılamaz. N yalnızca ana giriş üstündeki kat adedidir, bodrumları içermez; iki yükseklik değeri mimari projeden ayrı ayrı okunur. | C14: MMO/697 + BYKHY | D14: Emin olunamayan durumda büyük değeri yapı yüksekliğine yazın — eksik yazmak kriteri gevşetir.
A16: BU DOSYA NASIL KULLANILIR — KULLANIM SENARYOLARI
A17: Durum | B17: Hangi sayfayı doldurursun | C17: Çıktı (PDF'e basılan) | D17: Not
A18: TEK ASANSÖR | B18: HESAPLAMA | C18: PAFTA | D18: Kabini ve hızı sen verirsin, gereken adedi hesap bulur: n = MAX[taşıma adedi ; bekleme adedi].
A19: BİRDEN FAZLA ASANSÖR | B19: ÇOKLU ASANSÖR | C19: PAFTA-COKLU | D19: Planladığın asansörleri sen girersin, hesap grubu kontrol eder: Reş = ΣR ≥ B·k ve TReş = 1/Σ(1/TR) ≤ Izul (MMO/697 s.12).
A20: FARKLI KAPASİTEDE ASANSÖR | B20: ÇOKLU ASANSÖR (zorunlu) | C20: PAFTA-COKLU | D20: HESAPLAMA'nın verdiği adet, asansörlerin HEPSİNİN aynı kabin ve aynı hızda olduğunu varsayar. Kapasiteler farklıysa grup formülü zorunludur.
A21: ÖNERİLEN SIRA | B21: Önce HESAPLAMA ile kaç adet gerektiğine bak | C21: Tek çıkarsa PAFTA; birden fazla ve farklı kapasiteliyse ÇOKLU ASANSÖR'e geç | D21: İki sayfanın girdileri BAĞIMSIZDIR — birinde yaptığın değişiklik diğerine geçmez. Hangi paftayı basacaksan onun kendi girdilerini doldur.
A22: YENİ PROJEYE BAŞLARKEN KONTROL EDİLECEKLER
A23: Önceki projeden kalıntı | B23: HESAPLAMA E26:E29 (manuel ta / tk / tg / tp) ve C39 (elle asansör adedi) bir önceki işten kalmış olabilir | C23: E30 ve E39 uyarı yazar | D23: Boşalt. Manuel süre girilirse paftada kaynak 'İmalatçı verisi'ne döner ve teknik föy referansı istenir.
A24: Kapsam sınırları | B24: Kabin 6–34 kişi, kat N = 1–30. Kapı genişliği tam hesaplanabilir değerler: 900 / 1100 / 1300 mm (Tablo-4 ∩ Tablo-8). | C24: Tablo-3 / 4 / 5 / 8 | D24: Aralık dışında hesap durur ve EKSİK OLAN DEĞERİ ADIYLA söyler; sessizce yanlış sonuç üretmez. N > 30 için tek bölgeli hesap geçersizdir, bölgeli (zoned) hesap gerekir.
A25: Manuel giriş gereken tipler | B25: Karma Binalar, Poliklinik, Katlı Otopark ve Hastane | C25: Tablo-2 / Tablo-9 | D25: Bu tiplerde hız ve/veya %k tabloda yoktur; E10 (manuel V) ve E5 (manuel k) hücrelerinden girilir.
A26: Bodrum katı | B26: N = ana giriş katının ÜSTÜNDEKİ kat adedidir; bodrum N'e dâhil EDİLMEZ | C26: MMO/697 s.11 | D26: Bodrum durağı seyir mesafesini, kuyu dibini ve durak/kapı adedini etkiler; tur süresine girmez. Bodrumdan yolcu binen bina (kapalı otopark) bu yöntemle modellenmez.
A27: tp değerinin MMO/697 ile ilişkisi | B27: Tablo-8 değerleri MMO/697'nin BASILI tablosu değildir; MMO/697 kendi örneğinde tp = 2,2 s kullanır (eski ISO 4190-6:1984 yaklaşımı 1,75 s idi). Çalışma kitabı güncel ISO 8100-32:2020 Tablo 6 değerlerini kullanır. | C27: ISO 8100-32:2020 | D27: Sıkışık hesaplarda bu fark sonucu değiştirir. İtiraz gelirse dayanak ISO 8100-32:2020 Tablo 6'dır; muhafazakâr konut tasarımı için Barney/Peters +0,3 s konut düzeltmesi E29 hücresinden elle uygulanabilir.
A28: Ondalık ayırıcı | B28: Ondalık yazarken NOKTA değil VİRGÜL kullanın | C28: Türkçe Excel | D28: "17.1" yazarsanız 17 Ocak tarihine (46039) dönüşür ve hesap sessizce bozulur.
A30: Asansör adedinin boyutlandığı sınır | B30: Gereken adet, MMO/697 Tablo-10 STANDART sınırına (yüksek yapıda Yükseltilmiş) göre bulunur; Şartlı Kabul sınırına göre değil. | C30: Tablo-10 | D30: Şartlı Kabul yalnızca sonuç raporlanırken, daha az asansörle de geçilebileceğini göstermek için PAFTA satırında ayrıca yazılır ve taahhütname gerektirir.
A31: Ara hız değerleri (1,75 / 3,00 m/s) | B31: Tablo-6 satır başlığı değildir; tg doğrusal enterpolasyonla bulunur. | C31: Tablo-6 | D31: Paftada kaynak "Tablo-6 (ara değer — enterpolasyon)" olarak basılır.
A32: Öneri bloğu kapı genişliği varsayımı | B32: ISO 8100-32:2020, Ek C, Tablo 8 — beyan yüküne göre varsayılan kapı genişlikleri | C32: HESAPLAMA 6) blok | D32: 630 kg→800 mm, 800 kg→900 mm, 1000/1275/1600 kg→1100 mm, 2000 kg→1300 mm. Yalnız öneri tablosunda kullanılır; kesin hesap ⑨ girdinizle yapılır.

Sheet TABLO-1
A1: Bina Tipi * | C1: b
A2: KONUT ** | B2: her dairede ilk yatak odası için | C2: 2
B3: diğer odaların her biri için | C3: 1
A4: OTEL | B4: Her yatak için | C4: 1
A5: İŞ MERKEZİ | B5: çalışma alanının her 12 m²si için | C5: 1
A6: HASTANE | B6: her yatak için | C6: 3
A7: RESMİ BİNALAR | B7: çalışma alanının 12 m²si için | C7: 1
A8: OTOPARK | B8: ticari amaçlı araç adedi başına | C8: 1,5
B9: özel amaçlı araç adedi başına | C9: 1
A10: * Servis asansörleri bu değerlerin dışındadır.
A11: ** Diğer bölümler ve mutfak hesaba katılmayacaktır.
A12: *** Engelliler için ayrıca hesap yapılmayacaktır.
A13: Tablo –1 Binada sürekli bulunan insan sayısı
A14: Kaynak: MMO/697 "Asansör Avan Projesi Hazırlama Teknik Esasları", 2. Baskı, Ocak 2020, s.13

Sheet TABLO-2
A1: Bina Tipi | B1: Durak Adedi | C1: Hız [m/s]
A2: Konut | B2: 2-9 Durak | C2: 1
B3: 10-14 Durak | C3: 1.6
B4: 15-19 Durak | C4: 2.0
B5: 20 Durak ve üzeri | C5: ≥ 2.5
A6: Büro ve İş Merkezi | B6: 2-5 Durak | C6: 1
B7: 6-10 Durak | C7: 1.6
B8: 11-15 Durak | C8: 2.0
B9: 16-19 Durak | C9: 2.5
B10: 20 Durak ve üzeri | C10: > 2.5
A11: Otel | B11: 2-6 Durak | C11: 1
B12: 7-10 Durak | C12: 1.6
B13: 11-15 Durak | C13: 2.0
B14: 16-19 Durak | C14: 2.5
B15: 20 Durak ve üzeri | C15: > 2.5
A17: Tablo –2 Kabin hızları
A18: Kaynak: MMO/697, 2. Baskı, Ocak 2020, s.13

Sheet TABLO-3
A1: Ana giriş üstündeki kat sayısı (N) | B1: ASANSÖRÜN KAPASİTESİ (KİŞİ)
B2: 6 | C2: 7 | D2: 8 | E2: 9 | F2: 10 | G2: 11 | H2: 12 | I2: 13 | J2: 14 | K2: 15 | L2: 16 | M2: 17 | N2: 18 | O2: 19 | P2: 20 | Q2: 21 | R2: 22 | S2: 23 | T2: 24 | U2: 25 | V2: 26 | W2: 27 | X2: 28 | Y2: 29 | Z2: 30 | AA2: 31 | AB2: 32 | AC2: 33 | AD2: 34 | AG2: i (yardımcı)
A3: 1 | B3: =$A3 - SUMPRODUCT(($AG$3:$AG$31<$A3)*(($AG$3:$AG$31/$A3)^B$2)) | C3: =$A3 - SUMPRODUCT(($AG$3:$AG$31<$A3)*(($AG$3:$AG$31/$A3)^C$2)) | D3: =$A3 - SUMPRODUCT(($AG$3:$AG$31<$A3)*(($AG$3:$AG$31/$A3)^D$2)) | E3: =$A3 - SUMPRODUCT(($AG$3:$AG$31<$A3)*(($AG$3:$AG$31/$A3)^E$2)) | F3: =$A3 - SUMPRODUCT(($AG$3:$AG$31<$A3)*(($AG$3:$AG$31/$A3)^F$2)) | G3: =$A3 - SUMPRODUCT(($AG$3:$AG$31<$A3)*(($AG$3:$AG$31/$A3)^G$2)) | H3: =$A3 - SUMPRODUCT(($AG$3:$AG$31<$A3)*(($AG$3:$AG$31/$A3)^H$2)) | I3: =$A3 - SUMPRODUCT(($AG$3:$AG$31<$A3)*(($AG$3:$AG$31/$A3)^I$2)) | ... AD3: =$A3 - SUMPRODUCT(($AG$3:$AG$31<$A3)*(($AG$3:$AG$31/$A3)^AD$2)) | AG3: 1
A4: 2 | B4: =$A4 - SUMPRODUCT(($AG$3:$AG$31<$A4)*(($AG$3:$AG$31/$A4)^B$2)) | C4: =$A4 - SUMPRODUCT(($AG$3:$AG$31<$A4)*(($AG$3:$AG$31/$A4)^C$2)) | D4: =$A4 - SUMPRODUCT(($AG$3:$AG$31<$A4)*(($AG$3:$AG$31/$A4)^D$2)) | E4: =$A4 - SUMPRODUCT(($AG$3:$AG$31<$A4)*(($AG$3:$AG$31/$A4)^E$2)) | F4: =$A4 - SUMPRODUCT(($AG$3:$AG$31<$A4)*(($AG$3:$AG$31/$A4)^F$2)) | G4: =$A4 - SUMPRODUCT(($AG$3:$AG$31<$A4)*(($AG$3:$AG$31/$A4)^G$2)) | H4: =$A4 - SUMPRODUCT(($AG$3:$AG$31<$A4)*(($AG$3:$AG$31/$A4)^H$2)) | I4: =$A4 - SUMPRODUCT(($AG$3:$AG$31<$A4)*(($AG$3:$AG$31/$A4)^I$2)) | ... AD4: =$A4 - SUMPRODUCT(($AG$3:$AG$31<$A4)*(($AG$3:$AG$31/$A4)^AD$2)) | AG4: 2
A5: 3 | B5: =$A5 - SUMPRODUCT(($AG$3:$AG$31<$A5)*(($AG$3:$AG$31/$A5)^B$2)) | C5: =$A5 - SUMPRODUCT(($AG$3:$AG$31<$A5)*(($AG$3:$AG$31/$A5)^C$2)) | D5: =$A5 - SUMPRODUCT(($AG$3:$AG$31<$A5)*(($AG$3:$AG$31/$A5)^D$2)) | E5: =$A5 - SUMPRODUCT(($AG$3:$AG$31<$A5)*(($AG$3:$AG$31/$A5)^E$2)) | F5: =$A5 - SUMPRODUCT(($AG$3:$AG$31<$A5)*(($AG$3:$AG$31/$A5)^F$2)) | G5: =$A5 - SUMPRODUCT(($AG$3:$AG$31<$A5)*(($AG$3:$AG$31/$A5)^G$2)) | H5: =$A5 - SUMPRODUCT(($AG$3:$AG$31<$A5)*(($AG$3:$AG$31/$A5)^H$2)) | I5: =$A5 - SUMPRODUCT(($AG$3:$AG$31<$A5)*(($AG$3:$AG$31/$A5)^I$2)) | ... AD5: =$A5 - SUMPRODUCT(($AG$3:$AG$31<$A5)*(($AG$3:$AG$31/$A5)^AD$2)) | AG5: 3
A6: 4 | B6: =$A6 - SUMPRODUCT(($AG$3:$AG$31<$A6)*(($AG$3:$AG$31/$A6)^B$2)) | C6: =$A6 - SUMPRODUCT(($AG$3:$AG$31<$A6)*(($AG$3:$AG$31/$A6)^C$2)) | D6: =$A6 - SUMPRODUCT(($AG$3:$AG$31<$A6)*(($AG$3:$AG$31/$A6)^D$2)) | E6: =$A6 - SUMPRODUCT(($AG$3:$AG$31<$A6)*(($AG$3:$AG$31/$A6)^E$2)) | F6: =$A6 - SUMPRODUCT(($AG$3:$AG$31<$A6)*(($AG$3:$AG$31/$A6)^F$2)) | G6: =$A6 - SUMPRODUCT(($AG$3:$AG$31<$A6)*(($AG$3:$AG$31/$A6)^G$2)) | H6: =$A6 - SUMPRODUCT(($AG$3:$AG$31<$A6)*(($AG$3:$AG$31/$A6)^H$2)) | I6: =$A6 - SUMPRODUCT(($AG$3:$AG$31<$A6)*(($AG$3:$AG$31/$A6)^I$2)) | ... AD6: =$A6 - SUMPRODUCT(($AG$3:$AG$31<$A6)*(($AG$3:$AG$31/$A6)^AD$2)) | AG6: 4
A7: 5 | B7: =$A7 - SUMPRODUCT(($AG$3:$AG$31<$A7)*(($AG$3:$AG$31/$A7)^B$2)) | C7: =$A7 - SUMPRODUCT(($AG$3:$AG$31<$A7)*(($AG$3:$AG$31/$A7)^C$2)) | D7: =$A7 - SUMPRODUCT(($AG$3:$AG$31<$A7)*(($AG$3:$AG$31/$A7)^D$2)) | E7: =$A7 - SUMPRODUCT(($AG$3:$AG$31<$A7)*(($AG$3:$AG$31/$A7)^E$2)) | F7: =$A7 - SUMPRODUCT(($AG$3:$AG$31<$A7)*(($AG$3:$AG$31/$A7)^F$2)) | G7: =$A7 - SUMPRODUCT(($AG$3:$AG$31<$A7)*(($AG$3:$AG$31/$A7)^G$2)) | H7: =$A7 - SUMPRODUCT(($AG$3:$AG$31<$A7)*(($AG$3:$AG$31/$A7)^H$2)) | I7: =$A7 - SUMPRODUCT(($AG$3:$AG$31<$A7)*(($AG$3:$AG$31/$A7)^I$2)) | ... AD7: =$A7 - SUMPRODUCT(($AG$3:$AG$31<$A7)*(($AG$3:$AG$31/$A7)^AD$2)) | AG7: 5
A8: 6 | B8: =$A8 - SUMPRODUCT(($AG$3:$AG$31<$A8)*(($AG$3:$AG$31/$A8)^B$2)) | C8: =$A8 - SUMPRODUCT(($AG$3:$AG$31<$A8)*(($AG$3:$AG$31/$A8)^C$2)) | D8: =$A8 - SUMPRODUCT(($AG$3:$AG$31<$A8)*(($AG$3:$AG$31/$A8)^D$2)) | E8: =$A8 - SUMPRODUCT(($AG$3:$AG$31<$A8)*(($AG$3:$AG$31/$A8)^E$2)) | F8: =$A8 - SUMPRODUCT(($AG$3:$AG$31<$A8)*(($AG$3:$AG$31/$A8)^F$2)) | G8: =$A8 - SUMPRODUCT(($AG$3:$AG$31<$A8)*(($AG$3:$AG$31/$A8)^G$2)) | H8: =$A8 - SUMPRODUCT(($AG$3:$AG$31<$A8)*(($AG$3:$AG$31/$A8)^H$2)) | I8: =$A8 - SUMPRODUCT(($AG$3:$AG$31<$A8)*(($AG$3:$AG$31/$A8)^I$2)) | ... AD8: =$A8 - SUMPRODUCT(($AG$3:$AG$31<$A8)*(($AG$3:$AG$31/$A8)^AD$2)) | AG8: 6
A9: 7 | B9: =$A9 - SUMPRODUCT(($AG$3:$AG$31<$A9)*(($AG$3:$AG$31/$A9)^B$2)) | C9: =$A9 - SUMPRODUCT(($AG$3:$AG$31<$A9)*(($AG$3:$AG$31/$A9)^C$2)) | D9: =$A9 - SUMPRODUCT(($AG$3:$AG$31<$A9)*(($AG$3:$AG$31/$A9)^D$2)) | E9: =$A9 - SUMPRODUCT(($AG$3:$AG$31<$A9)*(($AG$3:$AG$31/$A9)^E$2)) | F9: =$A9 - SUMPRODUCT(($AG$3:$AG$31<$A9)*(($AG$3:$AG$31/$A9)^F$2)) | G9: =$A9 - SUMPRODUCT(($AG$3:$AG$31<$A9)*(($AG$3:$AG$31/$A9)^G$2)) | H9: =$A9 - SUMPRODUCT(($AG$3:$AG$31<$A9)*(($AG$3:$AG$31/$A9)^H$2)) | I9: =$A9 - SUMPRODUCT(($AG$3:$AG$31<$A9)*(($AG$3:$AG$31/$A9)^I$2)) | ... AD9: =$A9 - SUMPRODUCT(($AG$3:$AG$31<$A9)*(($AG$3:$AG$31/$A9)^AD$2)) | AG9: 7
A10: 8 | B10: =$A10 - SUMPRODUCT(($AG$3:$AG$31<$A10)*(($AG$3:$AG$31/$A10)^B$2)) | C10: =$A10 - SUMPRODUCT(($AG$3:$AG$31<$A10)*(($AG$3:$AG$31/$A10)^C$2)) | D10: =$A10 - SUMPRODUCT(($AG$3:$AG$31<$A10)*(($AG$3:$AG$31/$A10)^D$2)) | E10: =$A10 - SUMPRODUCT(($AG$3:$AG$31<$A10)*(($AG$3:$AG$31/$A10)^E$2)) | F10: =$A10 - SUMPRODUCT(($AG$3:$AG$31<$A10)*(($AG$3:$AG$31/$A10)^F$2)) | G10: =$A10 - SUMPRODUCT(($AG$3:$AG$31<$A10)*(($AG$3:$AG$31/$A10)^G$2)) | H10: =$A10 - SUMPRODUCT(($AG$3:$AG$31<$A10)*(($AG$3:$AG$31/$A10)^H$2)) | I10: =$A10 - SUMPRODUCT(($AG$3:$AG$31<$A10)*(($AG$3:$AG$31/$A10)^I$2)) | ... AD10: =$A10 - SUMPRODUCT(($AG$3:$AG$31<$A10)*(($AG$3:$AG$31/$A10)^AD$2)) | AG10: 8
A11: 9 | B11: =$A11 - SUMPRODUCT(($AG$3:$AG$31<$A11)*(($AG$3:$AG$31/$A11)^B$2)) | C11: =$A11 - SUMPRODUCT(($AG$3:$AG$31<$A11)*(($AG$3:$AG$31/$A11)^C$2)) | D11: =$A11 - SUMPRODUCT(($AG$3:$AG$31<$A11)*(($AG$3:$AG$31/$A11)^D$2)) | E11: =$A11 - SUMPRODUCT(($AG$3:$AG$31<$A11)*(($AG$3:$AG$31/$A11)^E$2)) | F11: =$A11 - SUMPRODUCT(($AG$3:$AG$31<$A11)*(($AG$3:$AG$31/$A11)^F$2)) | G11: =$A11 - SUMPRODUCT(($AG$3:$AG$31<$A11)*(($AG$3:$AG$31/$A11)^G$2)) | H11: =$A11 - SUMPRODUCT(($AG$3:$AG$31<$A11)*(($AG$3:$AG$31/$A11)^H$2)) | I11: =$A11 - SUMPRODUCT(($AG$3:$AG$31<$A11)*(($AG$3:$AG$31/$A11)^I$2)) | ... AD11: =$A11 - SUMPRODUCT(($AG$3:$AG$31<$A11)*(($AG$3:$AG$31/$A11)^AD$2)) | AG11: 9
A12: 10 | B12: =$A12 - SUMPRODUCT(($AG$3:$AG$31<$A12)*(($AG$3:$AG$31/$A12)^B$2)) | C12: =$A12 - SUMPRODUCT(($AG$3:$AG$31<$A12)*(($AG$3:$AG$31/$A12)^C$2)) | D12: =$A12 - SUMPRODUCT(($AG$3:$AG$31<$A12)*(($AG$3:$AG$31/$A12)^D$2)) | E12: =$A12 - SUMPRODUCT(($AG$3:$AG$31<$A12)*(($AG$3:$AG$31/$A12)^E$2)) | F12: =$A12 - SUMPRODUCT(($AG$3:$AG$31<$A12)*(($AG$3:$AG$31/$A12)^F$2)) | G12: =$A12 - SUMPRODUCT(($AG$3:$AG$31<$A12)*(($AG$3:$AG$31/$A12)^G$2)) | H12: =$A12 - SUMPRODUCT(($AG$3:$AG$31<$A12)*(($AG$3:$AG$31/$A12)^H$2)) | I12: =$A12 - SUMPRODUCT(($AG$3:$AG$31<$A12)*(($AG$3:$AG$31/$A12)^I$2)) | ... AD12: =$A12 - SUMPRODUCT(($AG$3:$AG$31<$A12)*(($AG$3:$AG$31/$A12)^AD$2)) | AG12: 10
A13: 11 | B13: =$A13 - SUMPRODUCT(($AG$3:$AG$31<$A13)*(($AG$3:$AG$31/$A13)^B$2)) | C13: =$A13 - SUMPRODUCT(($AG$3:$AG$31<$A13)*(($AG$3:$AG$31/$A13)^C$2)) | D13: =$A13 - SUMPRODUCT(($AG$3:$AG$31<$A13)*(($AG$3:$AG$31/$A13)^D$2)) | E13: =$A13 - SUMPRODUCT(($AG$3:$AG$31<$A13)*(($AG$3:$AG$31/$A13)^E$2)) | F13: =$A13 - SUMPRODUCT(($AG$3:$AG$31<$A13)*(($AG$3:$AG$31/$A13)^F$2)) | G13: =$A13 - SUMPRODUCT(($AG$3:$AG$31<$A13)*(($AG$3:$AG$31/$A13)^G$2)) | H13: =$A13 - SUMPRODUCT(($AG$3:$AG$31<$A13)*(($AG$3:$AG$31/$A13)^H$2)) | I13: =$A13 - SUMPRODUCT(($AG$3:$AG$31<$A13)*(($AG$3:$AG$31/$A13)^I$2)) | ... AD13: =$A13 - SUMPRODUCT(($AG$3:$AG$31<$A13)*(($AG$3:$AG$31/$A13)^AD$2)) | AG13: 11
A14: 12 | B14: =$A14 - SUMPRODUCT(($AG$3:$AG$31<$A14)*(($AG$3:$AG$31/$A14)^B$2)) | C14: =$A14 - SUMPRODUCT(($AG$3:$AG$31<$A14)*(($AG$3:$AG$31/$A14)^C$2)) | D14: =$A14 - SUMPRODUCT(($AG$3:$AG$31<$A14)*(($AG$3:$AG$31/$A14)^D$2)) | E14: =$A14 - SUMPRODUCT(($AG$3:$AG$31<$A14)*(($AG$3:$AG$31/$A14)^E$2)) | F14: =$A14 - SUMPRODUCT(($AG$3:$AG$31<$A14)*(($AG$3:$AG$31/$A14)^F$2)) | G14: =$A14 - SUMPRODUCT(($AG$3:$AG$31<$A14)*(($AG$3:$AG$31/$A14)^G$2)) | H14: =$A14 - SUMPRODUCT(($AG$3:$AG$31<$A14)*(($AG$3:$AG$31/$A14)^H$2)) | I14: =$A14 - SUMPRODUCT(($AG$3:$AG$31<$A14)*(($AG$3:$AG$31/$A14)^I$2)) | ... AD14: =$A14 - SUMPRODUCT(($AG$3:$AG$31<$A14)*(($AG$3:$AG$31/$A14)^AD$2)) | AG14: 12
... A31: 29 | B31: =$A31 - SUMPRODUCT(($AG$3:$AG$31<$A31)*(($AG$3:$AG$31/$A31)^B$2)) | C31: =$A31 - SUMPRODUCT(($AG$3:$AG$31<$A31)*(($AG$3:$AG$31/$A31)^C$2)) | D31: =$A31 - SUMPRODUCT(($AG$3:$AG$31<$A31)*(($AG$3:$AG$31/$A31)^D$2)) | E31: =$A31 - SUMPRODUCT(($AG$3:$AG$31<$A31)*(($AG$3:$AG$31/$A31)^E$2)) | F31: =$A31 - SUMPRODUCT(($AG$3:$AG$31<$A31)*(($AG$3:$AG$31/$A31)^F$2)) | G31: =$A31 - SUMPRODUCT(($AG$3:$AG$31<$A31)*(($AG$3:$AG$31/$A31)^G$2)) | H31: =$A31 - SUMPRODUCT(($AG$3:$AG$31<$A31)*(($AG$3:$AG$31/$A31)^H$2)) | I31: =$A31 - SUMPRODUCT(($AG$3:$AG$31<$A31)*(($AG$3:$AG$31/$A31)^I$2)) | ... AD31: =$A31 - SUMPRODUCT(($AG$3:$AG$31<$A31)*(($AG$3:$AG$31/$A31)^AD$2)) | AG31: 29
A32: 30 | B32: =$A32 - SUMPRODUCT(($AG$3:$AG$31<$A32)*(($AG$3:$AG$31/$A32)^B$2)) | C32: =$A32 - SUMPRODUCT(($AG$3:$AG$31<$A32)*(($AG$3:$AG$31/$A32)^C$2)) | D32: =$A32 - SUMPRODUCT(($AG$3:$AG$31<$A32)*(($AG$3:$AG$31/$A32)^D$2)) | E32: =$A32 - SUMPRODUCT(($AG$3:$AG$31<$A32)*(($AG$3:$AG$31/$A32)^E$2)) | F32: =$A32 - SUMPRODUCT(($AG$3:$AG$31<$A32)*(($AG$3:$AG$31/$A32)^F$2)) | G32: =$A32 - SUMPRODUCT(($AG$3:$AG$31<$A32)*(($AG$3:$AG$31/$A32)^G$2)) | H32: =$A32 - SUMPRODUCT(($AG$3:$AG$31<$A32)*(($AG$3:$AG$31/$A32)^H$2)) | I32: =$A32 - SUMPRODUCT(($AG$3:$AG$31<$A32)*(($AG$3:$AG$31/$A32)^I$2)) | ... AD32: =$A32 - SUMPRODUCT(($AG$3:$AG$31<$A32)*(($AG$3:$AG$31/$A32)^AD$2))
A34: TABLO-3 ORTALAMA EN YÜKSEK DÖNÜŞ KATI — H = N − Σ(i/N)^P , i=1..N-1
A35: N = Ana Giriş Üzerindeki Kat Adedi. Kaynak: MMO/697, Ocak 2020, s.14 (Tablo-3, kapasite 6-34 kişi, N=1-30)

Sheet TABLO-4
B1: Kapı Tipi
A2: Kapı Genişliği (mm) | B2: Teleskopik Otomatik | D2: Merkezden Açılan Oto. | F2: Kabin İçi Oto. Kat K.Ç.
B3: ta[s] | C3: tk[s] | D3: ta[s] | E3: tk[s] | F3: ta[s] | G3: tk[s] | I3: ta_num | J3: tk_num | K3: ta_num | L3: tk_num | M3: ta_num | N3: tk_num
A4: 700 | B4: 2,5 | C4: 3 | D4: 2 | E4: 2,5 | F4: 5 | G4: 5 | I4: 2.5 | J4: 3 | K4: 2 | L4: 2.5 | M4: 5 | N4: 5
A5: 800 | B5: 2,5 | C5: 3 | D5: 2 | E5: 2,5 | F5: 5 | G5: 5 | I5: 2.5 | J5: 3 | K5: 2 | L5: 2.5 | M5: 5 | N5: 5
A6: 900 | B6: 2,5 | C6: 3,8 | D6: 2,3 | E6: 2,9 | F6: 5 | G6: 5 | I6: 2.5 | J6: 3.8 | K6: 2.3 | L6: 2.9 | M6: 5 | N6: 5
A7: 1000 | B7: 2,75 | C7: 3,9 | D7: 2,4 | E7: 3,2 | F7: 5,5 | G7: 5,5 | I7: 2.75 | J7: 3.9 | K7: 2.4 | L7: 3.2 | M7: 5.5 | N7: 5.5
A8: 1100 | B8: 3 | C8: 4 | D8: 2,5 | E8: 3,5 | F8: 6 | G8: 6 | I8: 3 | J8: 4 | K8: 2.5 | L8: 3.5 | M8: 6 | N8: 6
A9: 1200 | B9: 3,35 | C9: 4,5 | D9: 2,6 | E9: 3,6 | F9: YOK | G9: YOK | I9: 3.35 | J9: 4.5 | K9: 2.6 | L9: 3.6 | M9: YOK | N9: YOK
A10: 1300 | B10: 3,7 | C10: 5 | D10: 2,7 | E10: 3,7 | F10: YOK | G10: YOK | I10: 3.7 | J10: 5 | K10: 2.7 | L10: 3.7 | M10: YOK | N10: YOK
A11: Tablo –4 Kapı açılma ve kapanma zamanları | Kaynak: MMO/697, Ocak 2020, s.15 (kitapla birebir doğrulandı) | 1000 ve 1200 mm satırları MMO/697 Tablo-4'te BASILI DEĞİLDİR; komşu satırlar arasında doğrusal enterpolasyonla türetilmiştir ( 1000 = (900+1100)/2 , 1200 = (1100+1300)/2 ) — Tablo-6'daki 1,75 ve 3,00 m/s ara değerleriyle aynı yöntem. 'Kabin İçi Oto. Kat K.Ç.' sütunu 1300 mm'de tabloda bulunmadığından 1200 mm için de üretilememiştir; bu iki hücrede imalatçı değeri elle girilmelidir.

Sheet TABLO-5
A1: Ana giriş üstündeki kat sayısı (N) | B1: ASANSÖRÜN KAPASİTESİ (KİŞİ)
B2: 6 | C2: 7 | D2: 8 | E2: 9 | F2: 10 | G2: 11 | H2: 12 | I2: 13 | J2: 14 | K2: 15 | L2: 16 | M2: 17 | N2: 18 | O2: 19 | P2: 20 | Q2: 21 | R2: 22 | S2: 23 | T2: 24 | U2: 25 | V2: 26 | W2: 27 | X2: 28 | Y2: 29 | Z2: 30 | AA2: 31 | AB2: 32 | AC2: 33 | AD2: 34
A3: 1 | B3: =$A3*(1-(($A3-1)/$A3)^B$2) | C3: =$A3*(1-(($A3-1)/$A3)^C$2) | D3: =$A3*(1-(($A3-1)/$A3)^D$2) | E3: =$A3*(1-(($A3-1)/$A3)^E$2) | F3: =$A3*(1-(($A3-1)/$A3)^F$2) | G3: =$A3*(1-(($A3-1)/$A3)^G$2) | H3: =$A3*(1-(($A3-1)/$A3)^H$2) | I3: =$A3*(1-(($A3-1)/$A3)^I$2) | ... AD3: =$A3*(1-(($A3-1)/$A3)^AD$2)
A4: 2 | B4: =$A4*(1-(($A4-1)/$A4)^B$2) | C4: =$A4*(1-(($A4-1)/$A4)^C$2) | D4: =$A4*(1-(($A4-1)/$A4)^D$2) | E4: =$A4*(1-(($A4-1)/$A4)^E$2) | F4: =$A4*(1-(($A4-1)/$A4)^F$2) | G4: =$A4*(1-(($A4-1)/$A4)^G$2) | H4: =$A4*(1-(($A4-1)/$A4)^H$2) | I4: =$A4*(1-(($A4-1)/$A4)^I$2) | ... AD4: =$A4*(1-(($A4-1)/$A4)^AD$2)
A5: 3 | B5: =$A5*(1-(($A5-1)/$A5)^B$2) | C5: =$A5*(1-(($A5-1)/$A5)^C$2) | D5: =$A5*(1-(($A5-1)/$A5)^D$2) | E5: =$A5*(1-(($A5-1)/$A5)^E$2) | F5: =$A5*(1-(($A5-1)/$A5)^F$2) | G5: =$A5*(1-(($A5-1)/$A5)^G$2) | H5: =$A5*(1-(($A5-1)/$A5)^H$2) | I5: =$A5*(1-(($A5-1)/$A5)^I$2) | ... AD5: =$A5*(1-(($A5-1)/$A5)^AD$2)
A6: 4 | B6: =$A6*(1-(($A6-1)/$A6)^B$2) | C6: =$A6*(1-(($A6-1)/$A6)^C$2) | D6: =$A6*(1-(($A6-1)/$A6)^D$2) | E6: =$A6*(1-(($A6-1)/$A6)^E$2) | F6: =$A6*(1-(($A6-1)/$A6)^F$2) | G6: =$A6*(1-(($A6-1)/$A6)^G$2) | H6: =$A6*(1-(($A6-1)/$A6)^H$2) | I6: =$A6*(1-(($A6-1)/$A6)^I$2) | ... AD6: =$A6*(1-(($A6-1)/$A6)^AD$2)
A7: 5 | B7: =$A7*(1-(($A7-1)/$A7)^B$2) | C7: =$A7*(1-(($A7-1)/$A7)^C$2) | D7: =$A7*(1-(($A7-1)/$A7)^D$2) | E7: =$A7*(1-(($A7-1)/$A7)^E$2) | F7: =$A7*(1-(($A7-1)/$A7)^F$2) | G7: =$A7*(1-(($A7-1)/$A7)^G$2) | H7: =$A7*(1-(($A7-1)/$A7)^H$2) | I7: =$A7*(1-(($A7-1)/$A7)^I$2) | ... AD7: =$A7*(1-(($A7-1)/$A7)^AD$2)
A8: 6 | B8: =$A8*(1-(($A8-1)/$A8)^B$2) | C8: =$A8*(1-(($A8-1)/$A8)^C$2) | D8: =$A8*(1-(($A8-1)/$A8)^D$2) | E8: =$A8*(1-(($A8-1)/$A8)^E$2) | F8: =$A8*(1-(($A8-1)/$A8)^F$2) | G8: =$A8*(1-(($A8-1)/$A8)^G$2) | H8: =$A8*(1-(($A8-1)/$A8)^H$2) | I8: =$A8*(1-(($A8-1)/$A8)^I$2) | ... AD8: =$A8*(1-(($A8-1)/$A8)^AD$2)
A9: 7 | B9: =$A9*(1-(($A9-1)/$A9)^B$2) | C9: =$A9*(1-(($A9-1)/$A9)^C$2) | D9: =$A9*(1-(($A9-1)/$A9)^D$2) | E9: =$A9*(1-(($A9-1)/$A9)^E$2) | F9: =$A9*(1-(($A9-1)/$A9)^F$2) | G9: =$A9*(1-(($A9-1)/$A9)^G$2) | H9: =$A9*(1-(($A9-1)/$A9)^H$2) | I9: =$A9*(1-(($A9-1)/$A9)^I$2) | ... AD9: =$A9*(1-(($A9-1)/$A9)^AD$2)
A10: 8 | B10: =$A10*(1-(($A10-1)/$A10)^B$2) | C10: =$A10*(1-(($A10-1)/$A10)^C$2) | D10: =$A10*(1-(($A10-1)/$A10)^D$2) | E10: =$A10*(1-(($A10-1)/$A10)^E$2) | F10: =$A10*(1-(($A10-1)/$A10)^F$2) | G10: =$A10*(1-(($A10-1)/$A10)^G$2) | H10: =$A10*(1-(($A10-1)/$A10)^H$2) | I10: =$A10*(1-(($A10-1)/$A10)^I$2) | ... AD10: =$A10*(1-(($A10-1)/$A10)^AD$2)
A11: 9 | B11: =$A11*(1-(($A11-1)/$A11)^B$2) | C11: =$A11*(1-(($A11-1)/$A11)^C$2) | D11: =$A11*(1-(($A11-1)/$A11)^D$2) | E11: =$A11*(1-(($A11-1)/$A11)^E$2) | F11: =$A11*(1-(($A11-1)/$A11)^F$2) | G11: =$A11*(1-(($A11-1)/$A11)^G$2) | H11: =$A11*(1-(($A11-1)/$A11)^H$2) | I11: =$A11*(1-(($A11-1)/$A11)^I$2) | ... AD11: =$A11*(1-(($A11-1)/$A11)^AD$2)
A12: 10 | B12: =$A12*(1-(($A12-1)/$A12)^B$2) | C12: =$A12*(1-(($A12-1)/$A12)^C$2) | D12: =$A12*(1-(($A12-1)/$A12)^D$2) | E12: =$A12*(1-(($A12-1)/$A12)^E$2) | F12: =$A12*(1-(($A12-1)/$A12)^F$2) | G12: =$A12*(1-(($A12-1)/$A12)^G$2) | H12: =$A12*(1-(($A12-1)/$A12)^H$2) | I12: =$A12*(1-(($A12-1)/$A12)^I$2) | ... AD12: =$A12*(1-(($A12-1)/$A12)^AD$2)
A13: 11 | B13: =$A13*(1-(($A13-1)/$A13)^B$2) | C13: =$A13*(1-(($A13-1)/$A13)^C$2) | D13: =$A13*(1-(($A13-1)/$A13)^D$2) | E13: =$A13*(1-(($A13-1)/$A13)^E$2) | F13: =$A13*(1-(($A13-1)/$A13)^F$2) | G13: =$A13*(1-(($A13-1)/$A13)^G$2) | H13: =$A13*(1-(($A13-1)/$A13)^H$2) | I13: =$A13*(1-(($A13-1)/$A13)^I$2) | ... AD13: =$A13*(1-(($A13-1)/$A13)^AD$2)
A14: 12 | B14: =$A14*(1-(($A14-1)/$A14)^B$2) | C14: =$A14*(1-(($A14-1)/$A14)^C$2) | D14: =$A14*(1-(($A14-1)/$A14)^D$2) | E14: =$A14*(1-(($A14-1)/$A14)^E$2) | F14: =$A14*(1-(($A14-1)/$A14)^F$2) | G14: =$A14*(1-(($A14-1)/$A14)^G$2) | H14: =$A14*(1-(($A14-1)/$A14)^H$2) | I14: =$A14*(1-(($A14-1)/$A14)^I$2) | ... AD14: =$A14*(1-(($A14-1)/$A14)^AD$2)
... A32: 30 | B32: =$A32*(1-(($A32-1)/$A32)^B$2) | C32: =$A32*(1-(($A32-1)/$A32)^C$2) | D32: =$A32*(1-(($A32-1)/$A32)^D$2) | E32: =$A32*(1-(($A32-1)/$A32)^E$2) | F32: =$A32*(1-(($A32-1)/$A32)^F$2) | G32: =$A32*(1-(($A32-1)/$A32)^G$2) | H32: =$A32*(1-(($A32-1)/$A32)^H$2) | I32: =$A32*(1-(($A32-1)/$A32)^I$2) | ... AD32: =$A32*(1-(($A32-1)/$A32)^AD$2)
A34: TABLO-5 ORTALAMA DURAK ADEDİ — S = N·(1−((N−1)/N)^P)
A35: N = Ana Giriş Üzerindeki Kat Adedi. Kaynak: MMO/697, Ocak 2020, s.16 (Tablo-5, kapasite 6-34 kişi, N=1-30)

Sheet TABLO-6
A1: Hız [m/s] | B1: <1 | C1: 1 | D1: 1,6 | E1: 2 | F1: 2,5 | G1: 3,5 | H1: 5 | I1: >5,00
A2: tg [s] | B2: 10 | C2: 7 | D2: 6 | E2: 5,7 | F2: 5,5 | G2: 5 | H2: 4,5 | I2: 4,3
A3: Tablo –6 Tek katı geçme zamanı | Kaynak: MMO/697, Ocak 2020, s.17 (kitapla birebir doğrulandı)
A4: Ara değerler: 1,75 m/s → tg = 5,8875 s ve 3,00 m/s → tg = 5,25 s, komşu tablo noktaları arasında doğrusal enterpolasyonla türetilmiştir. MMO/697 Tablo-6 satır başlığı değildir; paftada kaynak "Tablo-6 (ara değer — enterpolasyon)" olarak yazılır.

Sheet TABLO-7
A1: Kabin Kapasitesi (P)
A2: 6 kişi | B2: 8 kişi | C2: 10 kişi | D2: 13 kişi | E2: 16 kişi | F2: 20 kişi | G2: 25 kişi | H2: 30 kişi
A3: 450 kg | B3: 630 kg | C3: 800 kg | D3: 1000 kg | E3: 1275 kg | F3: 1600 kg | G3: 2000 kg | H3: 2500 kg
A4: Tablo –7 Kabin kapasitesi | Kaynak: MMO/697, Ocak 2020, s.17
A5: Not: 15 kişi / 1125 kg bu Tablo-7'de yer almaz; MMO/697'nin s.53-54 örnek projesinde kullanıldığı için hesap sayfalarında açıkça 'örnek istisnası' olarak desteklenir.
A6: Kaynak ayrımı: Tablo-7 s.17 | 15 kişi / 1125 kg örneği s.53-54

Sheet TABLO-8
A1: Kapı Genişliği [mm] | B1: 700 | C1: 800 | D1: 900 | E1: 1000 | F1: 1100 | G1: 1200 | H1: 1300
A2: tp [s] | B2: 1.3 | C2: 1.2 | D2: 1.1 | E2: 1 | F2: 1 | G2: 0.9 | H2: 0.9
A3: Tablo –8 Kişi transfer zamanı (tp) — kapı tipinden bağımsız, net kapı genişliğine göre. tp = tek yolcunun kabine giriş VEYA çıkış süresidir; TR denkleminde 2·p·tp olarak kullanılır.
A5: Kaynak: ISO 8100-32:2020 "Planning and selection of passenger lifts…", Tablo 6 — 900 mm: 1,1 s | 1000 mm: 1,0 s | 1100 mm: 1,0 s | 1200 mm: 0,9 s.
A6: 800 mm: 1,2 s — ISO/CD 8100-32 (2017 komite taslağı) Tablo 6'nın 800 mm satırından; ayrıca Barney & Peters, "Expert Systems for Lift Traffic Design", 9th Symposium on Lift & Escalator Technology (2018), Tablo 3 (450-800 kg / 800 mm → 1,2 s) ile birebir aynıdır. 800 mm, EN 81-70'in erişilebilir asansör için istediği asgari net kapı genişliğidir.
A7: 1300 mm: 0,9 s — ISO tablosu 1200 mm'de biter; 1200 mm değeri düz devam ettirilmiştir. Barney/Peters >1100 mm için 0,8 s verdiğinden bu değer güvenli taraftadır.
A8: 700 mm ISO 8100-32:2020 Tablo 6'da ve Barney/Peters tablolarında YOKTUR (tablo 800 mm'de başlar, ayrıca 700 mm TS EN 81-70 erişilebilirlik asgarisi olan 800 mm'nin altındadır). Buradaki 1,3 s değeri 800→900 mm eğiminden ( −0,1 s / 100 mm ) DOĞRUSAL DIŞ DEĞERLEME ile bulunmuştur; büyük tp, TR'yi büyüttüğü için emniyetli taraftadır. İmalatçı verisi varsa manuel tp girilmelidir.
A10: NOT — bina tipi düzeltmesi: Barney/Peters Tablo 3 ofis değerleri içindir ve konut için +0,3 s, otel için +0,5 s eklenmesini önerir. ISO 8100-32:2020 Tablo 6 böyle bir ayrım yapmaz ve MMO/697 de yapmaz; bu çalışma kitabı ISO değerlerini olduğu gibi kullanır. Muhafazakâr bir konut tasarımı isteniyorsa HESAPLAMA E29 hücresine tp + 0,3 s elle girilebilir.

Sheet TABLO-9
A1: Bina Tipi | B1: Standart | C1: Yükseltilmiş 1) | D1: Standart_num | E1: Yükseltilmiş_num
A2: Konut | B2: % 7.5 | C2: % 10 | D2: 0.075 | E2: 0.1
A3: Otel | B3: % 12 | C3: % 15 | D3: 0.12 | E3: 0.15
A4: İş Merkezi | B4: % 15 | C4: % 17 | D4: 0.15 | E4: 0.17
A5: Hastane | B5: % 10 | C5: % 20 | D5: 0.1 | E5: 0.2
A6: Otopark | B6: % 10 | C6: % 20 | D6: 0.1 | E6: 0.2
A8: 1) Yüksek yapılardaki asansörlerin hesabı için yükseltilmiş değerlerin seçilmelidir.
A9: Tablo –9 Taşınacak insan yüzdesi (% k)
A10: Kaynak: MMO/697, Ocak 2020, s.17
A11: Otomatik yüksek bina kontrolü: bina yüksekliği >21,50 m veya yapı yüksekliği >30,50 m ise Yükseltilmiş seçilir (BYKHY md.4; kaynak KAYNAKLAR).
A12: Kamu binaları Tablo-9'da yoktur; çalışma kitabı İş Merkezi yüzdesini (%15 / yükseltilmiş %17) varsayar ve bunu HESAPLAMA E6 hücresinde belirtir.

Sheet TABLO-10
A1: Sınıf | B1: Kabul Edilemez | C1: Şartlı Kabul 2) | D1: Standart | E1: Yükseltilmiş 3) | F1: Sartli_num | G1: Standart_num | H1: Yukseltilmis_num | J1: Bina Tipi (ana seçim) | K1: → Tablo-2 hız grubu | L1: → Tablo-9 %k tipi
A2: Konut | B2: 120 sn. üzeri | C2: 120 sn. | D2: 100 sn. | E2: 80 sn. | F2: 120 | G2: 100 | H2: 80 | J2: Konut | K2: Konut | L2: Konut
A3: Karma Binalar (İşyeri ve Konut) | B3: 60 sn. üzeri | C3: 60 sn. | D3: 50 sn. | E3: 30 sn. | F3: 60 | G3: 50 | H3: 30 | J3: Karma Binalar (İşyeri ve Konut) | K3: Manuel hız gerekli | L3: Manuel k gerekli
A4: İş Merkezi (Tek Firmalı) | B4: 60 sn. üzeri | C4: 60 sn. | D4: 50 sn. | E4: 40 sn. | F4: 60 | G4: 50 | H4: 40 | J4: İş Merkezi (Tek Firmalı) | K4: Büro ve İş Merkezi | L4: İş Merkezi
A5: İş Merkezi (Çok Firmalı) | B5: 50 sn. üzeri | C5: 50 sn. | D5: 40 sn. | E5: 30 sn. | F5: 50 | G5: 40 | H5: 30 | J5: İş Merkezi (Çok Firmalı) | K5: Büro ve İş Merkezi | L5: İş Merkezi
A6: Otel (3* ve altı) | B6: 60 sn. üzeri | C6: 60 sn. | D6: 50 sn. | E6: 40 sn. | F6: 60 | G6: 50 | H6: 40 | J6: Otel (3* ve altı) | K6: Otel | L6: Otel
A7: Otel (4* ve üzeri) | B7: 50 sn. üzeri | C7: 50 sn. | D7: 40 sn. | E7: 30 sn. | F7: 50 | G7: 40 | H7: 30 | J7: Otel (4* ve üzeri) | K7: Otel | L7: Otel
A8: Kamu Binaları | B8: 40 sn. üzeri | C8: -- | D8: 40 sn. | E8: 30 sn. | G8: 40 | H8: 30 | J8: Kamu Binaları | K8: Büro ve İş Merkezi | L8: İş Merkezi
A9: Hastane | B9: 40 sn. üzeri | C9: -- | D9: 40 sn. | E9: 30 sn. | G9: 40 | H9: 30 | J9: Hastane | K9: Manuel hız gerekli | L9: Hastane
A10: Poliklinik Binaları ve Yaşlı Bakım Ev. | B10: 60 sn. üzeri | C10: 60 sn. | D10: 50 sn. | E10: 40 sn. | F10: 60 | G10: 50 | H10: 40 | J10: Poliklinik Binaları ve Yaşlı Bakım Ev. | K10: Manuel hız gerekli | L10: Manuel k gerekli
A11: Katlı Otopark | B11: 60 sn. üzeri | C11: 60 sn. | D11: 50 sn. | E11: 40 sn. | F11: 60 | G11: 50 | H11: 40 | J11: Katlı Otopark | K11: Manuel hız gerekli | L11: Otopark
A12: 2) Sadece asansör yaptırıcısı/bina sorumlusu onayı ile (Taahhütname)
A13: 3) Yüksek yapılardaki asansörlerin hesabı için yükseltilmiş standart seçilmelidir. | J13: EŞLEME TABLOSU — Yalnız MMO/697 Tablo-2 ve Tablo-9'da açıkça bulunan değerler otomatik seçilir.
A14: Tablo-10 İzin verilen en fazla bekleme zamanı (Izul) | J14: Tabloda bulunmayan bina sınıflarında hız ve/veya k değeri kullanıcı tarafından proje verisine göre girilmeden hesap yapılmaz.
A15: Kaynak: MMO/697, Ocak 2020, s.17
J16: Kamu Binaları: MMO/697 Tablo-2'de hız, Tablo-9'da %k verilmemiştir. Kullanım karakteri büro olduğundan Büro/İş Merkezi değerleri varsayılan alınır; V (E10) ve k (E5) hücrelerinden değiştirilebilir. Bekleme sınırı Tablo-10'un kendi Kamu satırından (40/30 sn) okunur.
