Workbook
Name PALANGA: TABLOLAR!$A$91:$A$92
Name KAPASITE: TABLOLAR!$A$41:$A$49

Sheet GİRİŞ
A1: ASANSÖR AVAN PROJE HESAPLARI — VERİ GİRİŞİ
A2: SARI hücreler doldurulur. Beyaz hücreler formülle gelir, üzerine yazmayın. Kullanılmayan asansörün kolonunu tamamen boş bırakın — o asansörün hesap sayfaları kendini devre dışı bırakır. Tüm asansörlerde ortak olan ofis standardı değerleri SABİTLER sayfasının B bölümündedir. Trafik hesabı bu dosyada DEĞİLDİR (Asansor_Trafik_Hesabi.xlsx → PAFTA sayfası kullanılır).
A4: 1) ORTAK GİRDİLER — şebeke / topraklama / makine dairesi
A5: Sembol | B5: Büyüklük | C5: Değer | D5: Birim | E5: Açıklama / Kaynak
A6: U | B6: Şebeke gerilimi (fazlar arası) | C6: 380 | D6: V | E6: Klasik 0,0124 katsayısı 380 V içindir. 400 V yazarsanız gerilim düşümü ≈ %10 azalır.
A7: κ | B7: İletken iletkenliği | C7: 56 | D7: m/Ω·mm² | E7: Bakır 56 / Alüminyum 35
A8: εmax | B8: İzin verilen gerilim düşümü | C8: 3 | D8: % | E8: Elektrik İç Tesisleri Yönetmeliği — motor devresi
A10: a | B10: Temel uzunluğu | C10: 26.55 | D10: m | E10: Topraklama — temel dış ölçüsü
A11: b | B11: Temel genişliği | C11: 16.4 | D11: m | E11: Topraklama — temel dış ölçüsü
A12: β | B12: Toprak özgül direnci | C12: 150 | D12: Ω·m | E12: Zemin etüdünden alınır; yoksa 150 Ω·m kabul edilir
A13: L | B13: Temel / şerit iletken uzunluğu | C13: 58.5 | D13: m | E13: Temele gömülen toplam şerit boyu
A14: Is | B14: Çubuk topraklayıcı sayısı | C14: 4 | D14: adet | E14: Paralel bağlı çubuk adedi
A15: — | B15: Makine dairesi YOK ( MRL — makine kuyu içinde ) | C15: Hayır | D15: — | E15: 'Evet' ise makine dairesi aydınlatma hesabı yapılmaz. 'Hayır' ise aşağıdaki A ve B ölçüleri zorunludur.
A16: A | B16: Makine dairesi uzunluğu | C16: 0 | D16: mm | E16: Makine dairesi yoksa üstteki kutuyu 'Evet' yapın; ölçü aranmaz.
A17: B | B17: Makine dairesi genişliği | C17: 0 | D17: mm | E17: Makine dairesi yoksa üstteki kutuyu 'Evet' yapın; ölçü aranmaz.
A18: A | B18: → Temel alanı = a · b | C18: =$C$10*$C$11 | D18: m² | E18: Otomatik
A20: 2) ASANSÖR BAZLI GİRDİLER — her asansör kendi kolonunda
A21: Sembol | B21: Büyüklük | C21: 1 NOLU ASANSÖR | D21: 2 NOLU ASANSÖR | E21: 3 NOLU ASANSÖR | F21: 4 NOLU ASANSÖR | G21: Birim | H21: Açıklama / Kaynak
A22: GENEL
A23: — | B23: Asansör tanımı | C23: İnsan | D23: Sedye + Yük | G23: — | H23: Kullanılmayacak asansörün TÜM satırlarını boş bırakın
A24: P | B24: Kabin kapasitesi | C24: 10 | D24: 16 | G24: kişi | H24: Trafik hesabından gelir
A25: Q0 | B25: → Anma yükü (kapasiteden — Tablo-7) | C25: =IF(C24="","",IFERROR(INDEX(TABLOLAR!$B$41:$B$49,MATCH(C24,TABLOLAR!$A$41:$A$49,0)),"TABLO-7 DIŞI")) | D25: =IF(D24="","",IFERROR(INDEX(TABLOLAR!$B$41:$B$49,MATCH(D24,TABLOLAR!$A$41:$A$49,0)),"TABLO-7 DIŞI")) | E25: =IF(E24="","",IFERROR(INDEX(TABLOLAR!$B$41:$B$49,MATCH(E24,TABLOLAR!$A$41:$A$49,0)),"TABLO-7 DIŞI")) | F25: =IF(F24="","",IFERROR(INDEX(TABLOLAR!$B$41:$B$49,MATCH(F24,TABLOLAR!$A$41:$A$49,0)),"TABLO-7 DIŞI")) | G25: kg | H25: Otomatik
A26: Q | B26: Anma yükü — elle ( boş = Tablo-7 ) | G26: kg | H26: Yalnız Tablo-7 dışı kapasitede doldurun
A27: Q | B27: → KULLANILAN anma yükü | C27: =IF(ISNUMBER(C26),C26,IF(ISNUMBER(C25),C25,"")) | D27: =IF(ISNUMBER(D26),D26,IF(ISNUMBER(D25),D25,"")) | E27: =IF(ISNUMBER(E26),E26,IF(ISNUMBER(E25),E25,"")) | F27: =IF(ISNUMBER(F26),F26,IF(ISNUMBER(F25),F25,"")) | G27: kg | H27: Otomatik — tüm hesaplar bunu kullanır
A28: V | B28: Kabin hızı | C28: 1.6 | D28: 1 | G28: m/s | H28: Trafik hesabından gelir
A29: η | B29: Makine verimi | C29: 0.85 | D29: 0.85 | G29: — | H29: Dişlisiz 0,85 / Dişli 0,50 (MMO/697 s.21)
A30: BOYUTLAR
A31: Hk | B31: Kuyu yüksekliği (toplam) | C31: 32.85 | D31: 32.85 | G31: m | H31: Ray, flexbil ve kuyu aydınlatması bu ölçüyü kullanır
A32: b | B32: Kuyu genişliği (plan) | C32: 1800 | D32: 2650 | G32: mm | H32: Kuyu aydınlatması
A33: a | B33: Kabin boyu | C33: 1450 | D33: 1350 | G33: mm | H33: Kabin aydınlatması
A34: b | B34: Kabin genişliği | C34: 1300 | D34: 2100 | G34: mm | H34: Kabin aydınlatması
A35: AĞIRLIKLAR
A36: Gk0 | B36: → Boş kabin kütlesi ( Tablo-11 ) | C36: =IF(C27="","",IFERROR(ROUND(IF(C27<=INDEX(TABLOLAR!$A$70:$A$78,1),INDEX(TABLOLAR!$B$70:$B$78,1),IF(C27>=INDEX(TABLOLAR!$A$70:$A$78,COUNT(TABLOLAR!$A$70:$A$78)),INDEX(TABLOLAR!$B$70:$B$78,COUNT(TABLOLAR!$A$70:$A$78)),INDEX(TABLOLAR!$B$70:$B$78,MATCH(C27,TABLOLAR!$A$70:$A$78,1))+(C27-INDEX(TABLOLAR!$A$70:$A$78,MATCH(C27,TABLOLAR!$A$70:$A$78,1)))*(INDEX(TABLOLAR!$B$70:$B$78,MATCH(C27,TABLOLAR!$A$70:$A$78,1)+1)-INDEX(TABLOLAR!$B$70:$B$78,MATCH(C27,TABLOLAR!$A$70:$A$78,1)))/(INDEX(TABLOLAR!$A$70:$A$78,MATCH(C27,TABLOLAR!$A$70:$A$78,1)+1)-INDEX(TABLOLAR!$A$70:$A$78,MATCH(C27,TABLOLAR!$A$70:$A$78,1))))),-1),"")) | D36: =IF(D27="","",IFERROR(ROUND(IF(D27<=INDEX(TABLOLAR!$A$70:$A$78,1),INDEX(TABLOLAR!$B$70:$B$78,1),IF(D27>=INDEX(TABLOLAR!$A$70:$A$78,COUNT(TABLOLAR!$A$70:$A$78)),INDEX(TABLOLAR!$B$70:$B$78,COUNT(TABLOLAR!$A$70:$A$78)),INDEX(TABLOLAR!$B$70:$B$78,MATCH(D27,TABLOLAR!$A$70:$A$78,1))+(D27-INDEX(TABLOLAR!$A$70:$A$78,MATCH(D27,TABLOLAR!$A$70:$A$78,1)))*(INDEX(TABLOLAR!$B$70:$B$78,MATCH(D27,TABLOLAR!$A$70:$A$78,1)+1)-INDEX(TABLOLAR!$B$70:$B$78,MATCH(D27,TABLOLAR!$A$70:$A$78,1)))/(INDEX(TABLOLAR!$A$70:$A$78,MATCH(D27,TABLOLAR!$A$70:$A$78,1)+1)-INDEX(TABLOLAR!$A$70:$A$78,MATCH(D27,TABLOLAR!$A$70:$A$78,1))))),-1),"")) | E36: =IF(E27="","",IFERROR(ROUND(IF(E27<=INDEX(TABLOLAR!$A$70:$A$78,1),INDEX(TABLOLAR!$B$70:$B$78,1),IF(E27>=INDEX(TABLOLAR!$A$70:$A$78,COUNT(TABLOLAR!$A$70:$A$78)),INDEX(TABLOLAR!$B$70:$B$78,COUNT(TABLOLAR!$A$70:$A$78)),INDEX(TABLOLAR!$B$70:$B$78,MATCH(E27,TABLOLAR!$A$70:$A$78,1))+(E27-INDEX(TABLOLAR!$A$70:$A$78,MATCH(E27,TABLOLAR!$A$70:$A$78,1)))*(INDEX(TABLOLAR!$B$70:$B$78,MATCH(E27,TABLOLAR!$A$70:$A$78,1)+1)-INDEX(TABLOLAR!$B$70:$B$78,MATCH(E27,TABLOLAR!$A$70:$A$78,1)))/(INDEX(TABLOLAR!$A$70:$A$78,MATCH(E27,TABLOLAR!$A$70:$A$78,1)+1)-INDEX(TABLOLAR!$A$70:$A$78,MATCH(E27,TABLOLAR!$A$70:$A$78,1))))),-1),"")) | F36: =IF(F27="","",IFERROR(ROUND(IF(F27<=INDEX(TABLOLAR!$A$70:$A$78,1),INDEX(TABLOLAR!$B$70:$B$78,1),IF(F27>=INDEX(TABLOLAR!$A$70:$A$78,COUNT(TABLOLAR!$A$70:$A$78)),INDEX(TABLOLAR!$B$70:$B$78,COUNT(TABLOLAR!$A$70:$A$78)),INDEX(TABLOLAR!$B$70:$B$78,MATCH(F27,TABLOLAR!$A$70:$A$78,1))+(F27-INDEX(TABLOLAR!$A$70:$A$78,MATCH(F27,TABLOLAR!$A$70:$A$78,1)))*(INDEX(TABLOLAR!$B$70:$B$78,MATCH(F27,TABLOLAR!$A$70:$A$78,1)+1)-INDEX(TABLOLAR!$B$70:$B$78,MATCH(F27,TABLOLAR!$A$70:$A$78,1)))/(INDEX(TABLOLAR!$A$70:$A$78,MATCH(F27,TABLOLAR!$A$70:$A$78,1)+1)-INDEX(TABLOLAR!$A$70:$A$78,MATCH(F27,TABLOLAR!$A$70:$A$78,1))))),-1),"")) | G36: kg | H36: Otomatik — ortalama değer
A37: Gk | B37: Boş kabin kütlesi — elle ( boş = Tablo-11 ) | G37: kg | H37: İmalatçı verisi varsa doldurun
A38: Gk | B38: → KULLANILAN boş kabin kütlesi | C38: =IF(ISNUMBER(C37),C37,IF(ISNUMBER(C36),C36,"")) | D38: =IF(ISNUMBER(D37),D37,IF(ISNUMBER(D36),D36,"")) | E38: =IF(ISNUMBER(E37),E37,IF(ISNUMBER(E36),E36,"")) | F38: =IF(ISNUMBER(F37),F37,IF(ISNUMBER(F36),F36,"")) | G38: kg | H38: Otomatik — kuvvet hesapları bunu kullanır
A39: gr | B39: Kılavuz ray birim kütlesi | C39: 17.91 | D39: 17.91 | G39: kg/m | H39: T89 ≈ 8,9 / T127-1/B ≈ 17,9 kg/m
A40: Fmk | B40: Makine ağırlığı | C40: 350 | D40: 350 | G40: kg | H40: İmalatçı verisi
A41: Fsh | B41: Makine sehpası / konstrüksiyon ağırlığı | C41: 100 | D41: 100 | G41: kg | H41: Makine daireli sistemde betonarme kaide ağırlığı buraya yazılır
A42: ELEKTRİK
A43: Nsç | B43: SEÇİLEN motor gücü | C43: 11 | D43: 11 | G43: kW | H43: Hesaplananın üstündeki standart motor — MOTOR sayfası kontrol eder
...

Sheet ÖZET
A1: ASANSÖR AVAN PROJE HESAPLARI — SONUÇ ÖZETİ
A3: Hesapların ayrıntısı ve formülleri ilgili sayfalardadır. Trafik hesabı ayrı dosyadadır.
A5: Sembol | B5: Büyüklük | C5: 1 NOLU ASANSÖR | D5: 2 NOLU ASANSÖR | E5: 3 NOLU ASANSÖR | F5: 4 NOLU ASANSÖR | G5: Birim
A6: TANIM
A7: — | B7: Asansör tanımı | C7: =IF(GİRİŞ!$C$27="","—",GİRİŞ!$C$23) | D7: =IF(GİRİŞ!$D$27="","—",GİRİŞ!$D$23) | E7: =IF(GİRİŞ!$E$27="","—",GİRİŞ!$E$23) | F7: =IF(GİRİŞ!$F$27="","—",GİRİŞ!$F$23)
A8: P | B8: Kabin kapasitesi | C8: =IF(GİRİŞ!$C$27="","",GİRİŞ!$C$24) | D8: =IF(GİRİŞ!$D$27="","",GİRİŞ!$D$24) | E8: =IF(GİRİŞ!$E$27="","",GİRİŞ!$E$24) | F8: =IF(GİRİŞ!$F$27="","",GİRİŞ!$F$24) | G8: kişi
A9: Q | B9: Anma yükü | C9: =IF(GİRİŞ!$C$27="","",GİRİŞ!$C$27) | D9: =IF(GİRİŞ!$D$27="","",GİRİŞ!$D$27) | E9: =IF(GİRİŞ!$E$27="","",GİRİŞ!$E$27) | F9: =IF(GİRİŞ!$F$27="","",GİRİŞ!$F$27) | G9: kg
A10: V | B10: Kabin hızı | C10: =IF(GİRİŞ!$C$27="","",GİRİŞ!$C$28) | D10: =IF(GİRİŞ!$D$27="","",GİRİŞ!$D$28) | E10: =IF(GİRİŞ!$E$27="","",GİRİŞ!$E$28) | F10: =IF(GİRİŞ!$F$27="","",GİRİŞ!$F$28) | G10: m/s
A11: MOTOR
A12: N | B12: Hesaplanan motor gücü | C12: =IF(GİRİŞ!$C$27="","",'1 NOLU ASANSÖR'!E14) | D12: =IF(GİRİŞ!$D$27="","",'2 NOLU ASANSÖR'!E14) | E12: =IF(GİRİŞ!$E$27="","",'3 NOLU ASANSÖR'!E14) | F12: =IF(GİRİŞ!$F$27="","",'4 NOLU ASANSÖR'!E14) | G12: kW
A13: Nsç | B13: SEÇİLEN motor gücü | C13: =IF(GİRİŞ!$C$27="","",'1 NOLU ASANSÖR'!E15) | D13: =IF(GİRİŞ!$D$27="","",'2 NOLU ASANSÖR'!E15) | E13: =IF(GİRİŞ!$E$27="","",'3 NOLU ASANSÖR'!E15) | F13: =IF(GİRİŞ!$F$27="","",'4 NOLU ASANSÖR'!E15) | G13: kW
A14: — | B14: Kontrol ( Nsç ≥ N ) | C14: =IF(GİRİŞ!$C$27="","",'1 NOLU ASANSÖR'!E16) | D14: =IF(GİRİŞ!$D$27="","",'2 NOLU ASANSÖR'!E16) | E14: =IF(GİRİŞ!$E$27="","",'3 NOLU ASANSÖR'!E16) | F14: =IF(GİRİŞ!$F$27="","",'4 NOLU ASANSÖR'!E16)
A15: KUVVETLER
A16: P1 | B16: Kuyu alt boşluğu tabanına ( tampon ) | C16: =IF(GİRİŞ!$C$27="","",'1 NOLU ASANSÖR'!E40) | D16: =IF(GİRİŞ!$D$27="","",'2 NOLU ASANSÖR'!E40) | E16: =IF(GİRİŞ!$E$27="","",'3 NOLU ASANSÖR'!E40) | F16: =IF(GİRİŞ!$F$27="","",'4 NOLU ASANSÖR'!E40) | G16: N
A17: P2 | B17: Karşı ağırlık tamponu altındaki zemine | C17: =IF(GİRİŞ!$C$27="","",'1 NOLU ASANSÖR'!E44) | D17: =IF(GİRİŞ!$D$27="","",'2 NOLU ASANSÖR'!E44) | E17: =IF(GİRİŞ!$E$27="","",'3 NOLU ASANSÖR'!E44) | F17: =IF(GİRİŞ!$F$27="","",'4 NOLU ASANSÖR'!E44) | G17: N
A18: PR | B18: Bir kabin kılavuz rayına ( düşey ) | C18: =IF(GİRİŞ!$C$27="","",'1 NOLU ASANSÖR'!E48) | D18: =IF(GİRİŞ!$D$27="","",'2 NOLU ASANSÖR'!E48) | E18: =IF(GİRİŞ!$E$27="","",'3 NOLU ASANSÖR'!E48) | F18: =IF(GİRİŞ!$F$27="","",'4 NOLU ASANSÖR'!E48) | G18: N
A19: PK | B19: Bir karşı ağırlık rayına ( düşey ) | C19: =IF(GİRİŞ!$C$27="","",'1 NOLU ASANSÖR'!E52) | D19: =IF(GİRİŞ!$D$27="","",'2 NOLU ASANSÖR'!E52) | E19: =IF(GİRİŞ!$E$27="","",'3 NOLU ASANSÖR'!E52) | F19: =IF(GİRİŞ!$F$27="","",'4 NOLU ASANSÖR'!E52) | G19: N
A20: Fs | B20: Kuyu üstü betonuna | C20: =IF(GİRİŞ!$C$27="","",'1 NOLU ASANSÖR'!E56) | D20: =IF(GİRİŞ!$D$27="","",'2 NOLU ASANSÖR'!E56) | E20: =IF(GİRİŞ!$E$27="","",'3 NOLU ASANSÖR'!E56) | F20: =IF(GİRİŞ!$F$27="","",'4 NOLU ASANSÖR'!E56) | G20: N
A21: AYDINLATMA
A22: n | B22: Kabin armatür sayısı | C22: =IF(GİRİŞ!$C$27="","",'1 NOLU ASANSÖR'!E76) | D22: =IF(GİRİŞ!$D$27="","",'2 NOLU ASANSÖR'!E76) | E22: =IF(GİRİŞ!$E$27="","",'3 NOLU ASANSÖR'!E76) | F22: =IF(GİRİŞ!$F$27="","",'4 NOLU ASANSÖR'!E76) | G22: adet
A23: n | B23: Kuyu armatür sayısı | C23: =IF(GİRİŞ!$C$27="","",'1 NOLU ASANSÖR'!E97) | D23: =IF(GİRİŞ!$D$27="","",'2 NOLU ASANSÖR'!E97) | E23: =IF(GİRİŞ!$E$27="","",'3 NOLU ASANSÖR'!E97) | F23: =IF(GİRİŞ!$F$27="","",'4 NOLU ASANSÖR'!E97) | G23: adet
A24: ELEKTRİK
A25: P | B25: Asansörün kurulu gücü | C25: =IF(GİRİŞ!$C$27="","",'1 NOLU ASANSÖR'!E106) | D25: =IF(GİRİŞ!$D$27="","",'2 NOLU ASANSÖR'!E106) | E25: =IF(GİRİŞ!$E$27="","",'3 NOLU ASANSÖR'!E106) | F25: =IF(GİRİŞ!$F$27="","",'4 NOLU ASANSÖR'!E106) | G25: W
A26: ε | B26: Toplam gerilim düşümü | C26: =IF(GİRİŞ!$C$27="","",'1 NOLU ASANSÖR'!E132) | D26: =IF(GİRİŞ!$D$27="","",'2 NOLU ASANSÖR'!E132) | E26: =IF(GİRİŞ!$E$27="","",'3 NOLU ASANSÖR'!E132) | F26: =IF(GİRİŞ!$F$27="","",'4 NOLU ASANSÖR'!E132) | G26: %
A27: — | B27: Kontrol ( ε ≤ εmax ) | C27: =IF(GİRİŞ!$C$27="","",IF('1 NOLU ASANSÖR'!E132<=GİRİŞ!$C$8,"UYGUN","UYGUN DEĞİL")) | D27: =IF(GİRİŞ!$D$27="","",IF('2 NOLU ASANSÖR'!E132<=GİRİŞ!$C$8,"UYGUN","UYGUN DEĞİL")) | E27: =IF(GİRİŞ!$E$27="","",IF('3 NOLU ASANSÖR'!E132<=GİRİŞ!$C$8,"UYGUN","UYGUN DEĞİL")) | F27: =IF(GİRİŞ!$F$27="","",IF('4 NOLU ASANSÖR'!E132<=GİRİŞ!$C$8,"UYGUN","UYGUN DEĞİL"))
A29: TESİS GENELİ
A30: P | B30: Tesisin toplam kurulu gücü | C30: =N('1 NOLU ASANSÖR'!E106)+N('2 NOLU ASANSÖR'!E106)+N('3 NOLU ASANSÖR'!E106)+N('4 NOLU ASANSÖR'!E106) | G30: W
A31: Re | B31: Temel topraklama direnci | C31: =TOPRAKLAMA!E25 | G31: Ω
A32: — | B32: Topraklama kontrolü ( Re ≤ UL / IΔn ) | C32: =IF(OR(NOT(ISNUMBER(TOPRAKLAMA!E25)),NOT(ISNUMBER(TOPRAKLAMA!E29))),"GİRDİ EKSİK",IF(TOPRAKLAMA!E25<=TOPRAKLAMA!E29,"UYGUN","UYGUN DEĞİL"))

Sheet 1 NOLU ASANSÖR
A1: 1 NOLU ASANSÖR — AVAN PROJE HESAPLARI
A3: =IF(GİRİŞ!$C$27<>"",IF(GİRİŞ!$C$23="","","Asansör tanımı : "&GİRİŞ!$C$23),IF(GİRİŞ!$C$24="","!!! BU ASANSÖR GİRİŞ SAYFASINDA TANIMLANMAMIŞ — hesaplar boştur !!!","!!! KAPASİTE TABLO-7 DIŞI — GİRİŞ sayfasında 'Anma yükü — elle' satırını doldurun !!!"))
A5: 1 - MOTOR GÜCÜ HESABI ( MMO / 697 — s.21 )
A6: Q | B6: : | C6: Anma yükü | D6: = | E6: =IF(GİRİŞ!$C$27="","",GİRİŞ!$C$27) | F6: kg | G6: GİRİŞ
A7: V | B7: : | C7: Kabin hızı | D7: = | E7: =IF(GİRİŞ!$C$27="","",GİRİŞ!$C$28) | F7: m/s | G7: GİRİŞ
A8: q | B8: : | C8: Denge faktörü ( karşı ağırlığın dengelediği oran ) | D8: = | E8: =IF(GİRİŞ!$C$27="","",IF(ISNUMBER(GİRİŞ!$C$54),GİRİŞ!$C$54,SABİTLER!$C$23)) | F8: — | G8: =IF(ISNUMBER(GİRİŞ!$C$54),"GİRİŞ — asansör bazında","SABİTLER B")
A9: i | B9: : | C9: Palanga ( askı ) katsayısı | D9: = | E9: =IF(GİRİŞ!$C$27="","",IF(ISNUMBER(GİRİŞ!$C$53),GİRİŞ!$C$53,SABİTLER!$C$22)) | F9: — | G9: =IF(ISNUMBER(GİRİŞ!$C$53),"GİRİŞ — asansör bazında","SABİTLER B")
A10: η | B10: : | C10: Makine verimi | D10: = | E10: =IF(GİRİŞ!$C$27="","",GİRİŞ!$C$29) | F10: — | G10: GİRİŞ
A11: η′ | B11: : | C11: =IF(GİRİŞ!$C$27="","",IF(GİRİŞ!$C$56="Evet","Girilen değer TOPLAM sistem verimidir — palanga düşüşü uygulanmaz","Palangalı sistemde verim ( i > 1 ise η − 0,10 )")) | D11: = | E11: =IF(GİRİŞ!$C$27="","",IF(GİRİŞ!$C$56="Evet",GİRİŞ!$C$29,IF(IF(ISNUMBER(GİRİŞ!$C$53),GİRİŞ!$C$53,SABİTLER!$C$22)>1,GİRİŞ!$C$29-SABİTLER!$C$11,GİRİŞ!$C$29))) | F11: — | G11: =IF(GİRİŞ!$C$56="Evet","GİRİŞ — toplam sistem verimi","SABİTLER A / MMO/697 §2.4")
C13: N = ( 1 − q ) · Q · V / ( 102 · η′ )
C14: =IF(GİRİŞ!$C$27="","","= "&IF(1-IF(ISNUMBER(GİRİŞ!$C$54),GİRİŞ!$C$54,SABİTLER!$C$23)>=IF(ISNUMBER(GİRİŞ!$C$54),GİRİŞ!$C$54,SABİTLER!$C$23),"( 1 − "&ROUND(IF(ISNUMBER(GİRİŞ!$C$54),GİRİŞ!$C$54,SABİTLER!$C$23),2)&" )",ROUND(IF(ISNUMBER(GİRİŞ!$C$54),GİRİŞ!$C$54,SABİTLER!$C$23),2))&" · "&ROUND(GİRİŞ!$C$27,0)&" · "&ROUND(GİRİŞ!$C$28,2)&" / ( 102 · "&ROUND(E11,2)&" )") | E14: =IF(GİRİŞ!$C$27="","",IF(E11<=0,"",MAX(1-IF(ISNUMBER(GİRİŞ!$C$54),GİRİŞ!$C$54,SABİTLER!$C$23),IF(ISNUMBER(GİRİŞ!$C$54),GİRİŞ!$C$54,SABİTLER!$C$23))*GİRİŞ!$C$27*GİRİŞ!$C$28/(SABİTLER!$C$10*E11))) | F14: kW | G14: hesaplanan
A15: Nsç | B15: : | C15: SEÇİLEN motor gücü | D15: = | E15: =IF(GİRİŞ!$C$27="","",GİRİŞ!$C$43) | F15: kW | G15: GİRİŞ
C16: KONTROL Nsç ≥ N | E16: =IF(GİRİŞ!$C$27="","",IF(NOT(ISNUMBER(E14)),"η GİRDİSİ HATALI",IF(GİRİŞ!$C$43>=E14,"UYGUN","UYGUN DEĞİL — motoru büyütün")))
A18: 2 - KUVVET HESAPLARI ( MMO / 697 s.18-20 / TS EN 81-20 )
A19: ORTAK BÜYÜKLÜKLER
A20: gn | B20: : | C20: Yerçekimi ivmesi | D20: = | E20: =IF(GİRİŞ!$C$27="","",SABİTLER!$C$5) | F20: m/s² | G20: SABİTLER A
A21: Gk | B21: : | C21: Boş kabin kütlesi | D21: = | E21: =IF(GİRİŞ!$C$27="","",GİRİŞ!$C$38) | F21: kg | G21: GİRİŞ
A22: gf | B22: : | C22: Gezici kablo ( flexbil ) birim kütlesi | D22: = | E22: =IF(GİRİŞ!$C$27="","",SABİTLER!$C$25) | F22: kg/m | G22: SABİTLER B
C23: Gf = gf · ( Hk / 2 + 3 ) ( gezici kablo kütlesi )
C24: =IF(GİRİŞ!$C$27="","","= "&ROUND(SABİTLER!$C$25,2)&" · ( "&ROUND(GİRİŞ!$C$31,2)&" / 2 + 3 )") | E24: =IF(GİRİŞ!$C$27="","",SABİTLER!$C$25*(GİRİŞ!$C$31/2+SABİTLER!$C$19)) | F24: kg
C25: P = Gk + Gf ( kabin tarafından desteklenen toplam kütle )
C26: =IF(GİRİŞ!$C$27="","","= "&ROUND(GİRİŞ!$C$38,0)&" + "&ROUND(E24,2)) | E26: =IF(GİRİŞ!$C$27="","",GİRİŞ!$C$38+E24) | F26: kg
A27: Q | B27: : | C27: Anma yükü | D27: = | E27: =IF(GİRİŞ!$C$27="","",GİRİŞ!$C$27) | F27: kg | G27: GİRİŞ
A28: q | B28: : | C28: Denge faktörü | D28: = | E28: =IF(GİRİŞ!$C$27="","",IF(ISNUMBER(GİRİŞ!$C$54),GİRİŞ!$C$54,SABİTLER!$C$23)) | F28: — | G28: =IF(ISNUMBER(GİRİŞ!$C$54),"GİRİŞ — asansör bazında","SABİTLER B")
C29: Ga = P + q · Q ( karşı ağırlık kütlesi )
C30: =IF(GİRİŞ!$C$27="","","= "&ROUND(E26,2)&" + "&ROUND(IF(ISNUMBER(GİRİŞ!$C$54),GİRİŞ!$C$54,SABİTLER!$C$23),2)&" · "&ROUND(GİRİŞ!$C$27,0)) | E30: =IF(GİRİŞ!$C$27="","",E26+IF(ISNUMBER(GİRİŞ!$C$54),GİRİŞ!$C$54,SABİTLER!$C$23)*GİRİŞ!$C$27) | F30: kg
A31: k1 | B31: : | C31: Darbe faktörü ( V > 1 → 2 / V > 0,63 → 3 / V ≤ 0,63 → 5 ) | D31: = | E31: =IF(GİRİŞ!$C$27="","",IF(GİRİŞ!$C$28>1,SABİTLER!$C$7,IF(GİRİŞ!$C$28>0.63,SABİTLER!$C$8,SABİTLER!$C$9))) | F31: — | G31: SABİTLER A / MMO/697 Çiz-1
A32: n | B32: : | C32: Kabin kılavuz ray sayısı | D32: = | E32: =IF(GİRİŞ!$C$27="","",SABİTLER!$C$24) | F32: adet | G32: SABİTLER B
A33: gr | B33: : | C33: 1 m kılavuz rayın kütlesi | D33: = | E33: =IF(GİRİŞ!$C$27="","",GİRİŞ!$C$39) | F33: kg/m | G33: GİRİŞ
A34: Lr | B34: : | C34: Kılavuz ray uzunluğu ( Hk − 0,20 ) | D34: = | E34: =IF(GİRİŞ!$C$27="","",GİRİŞ!$C$31-SABİTLER!$C$18) | F34: m
C35: Mg = Lr · gr ( bir kılavuz ray hattının kütlesi )
C36: =IF(GİRİŞ!$C$27="","","= "&ROUND(E34,2)&" · "&ROUND(GİRİŞ!$C$39,2)) | E36: =IF(GİRİŞ!$C$27="","",E34*GİRİŞ!$C$39) | F36: kg
A38: A - KUYU ALT BOŞLUĞU TABANINA GELEN KUVVET ( kabin tamponu altı )
C39: P1 = 4 · gn · ( P + Q )
C40: =IF(GİRİŞ!$C$27="","","= "&ROUND(SABİTLER!$C$6,0)&" · "&ROUND(SABİTLER!$C$5,2)&" · ( "&ROUND(E26,2)&" + "&ROUND(GİRİŞ!$C$27,0)&" )") | E40: =IF(GİRİŞ!$C$27="","",CEILING(SABİTLER!$C$6*SABİTLER!$C$5*(E26+GİRİŞ!$C$27),10)) | F40: N
A42: B - KARŞI AĞIRLIK TAMPONU ALTINDAKİ ZEMİNE GELEN KUVVET
C43: P2 = 4 · gn · ( P + q · Q ) = 4 · gn · Ga
C44: =IF(GİRİŞ!$C$27="","","= "&ROUND(SABİTLER!$C$6,0)&" · "&ROUND(SABİTLER!$C$5,2)&" · "&ROUND(E30,2)) | E44: =IF(GİRİŞ!$C$27="","",CEILING(SABİTLER!$C$6*SABİTLER!$C$5*E30,10)) | F44: N
A46: C - KABİN KILAVUZ RAYLARINA GELEN DÜŞEY KUVVET
C47: PR = k1 · gn · ( P + Q ) / n + Mg · gn
...

Sheet 2 NOLU ASANSÖR
A1: 2 NOLU ASANSÖR — AVAN PROJE HESAPLARI
A3: =IF(GİRİŞ!$D$27<>"",IF(GİRİŞ!$D$23="","","Asansör tanımı : "&GİRİŞ!$D$23),IF(GİRİŞ!$D$24="","!!! BU ASANSÖR GİRİŞ SAYFASINDA TANIMLANMAMIŞ — hesaplar boştur !!!","!!! KAPASİTE TABLO-7 DIŞI — GİRİŞ sayfasında 'Anma yükü — elle' satırını doldurun !!!"))
A5: 1 - MOTOR GÜCÜ HESABI ( MMO / 697 — s.21 )
A6: Q | B6: : | C6: Anma yükü | D6: = | E6: =IF(GİRİŞ!$D$27="","",GİRİŞ!$D$27) | F6: kg | G6: GİRİŞ
A7: V | B7: : | C7: Kabin hızı | D7: = | E7: =IF(GİRİŞ!$D$27="","",GİRİŞ!$D$28) | F7: m/s | G7: GİRİŞ
A8: q | B8: : | C8: Denge faktörü ( karşı ağırlığın dengelediği oran ) | D8: = | E8: =IF(GİRİŞ!$D$27="","",IF(ISNUMBER(GİRİŞ!$D$54),GİRİŞ!$D$54,SABİTLER!$C$23)) | F8: — | G8: =IF(ISNUMBER(GİRİŞ!$D$54),"GİRİŞ — asansör bazında","SABİTLER B")
A9: i | B9: : | C9: Palanga ( askı ) katsayısı | D9: = | E9: =IF(GİRİŞ!$D$27="","",IF(ISNUMBER(GİRİŞ!$D$53),GİRİŞ!$D$53,SABİTLER!$C$22)) | F9: — | G9: =IF(ISNUMBER(GİRİŞ!$D$53),"GİRİŞ — asansör bazında","SABİTLER B")
A10: η | B10: : | C10: Makine verimi | D10: = | E10: =IF(GİRİŞ!$D$27="","",GİRİŞ!$D$29) | F10: — | G10: GİRİŞ
A11: η′ | B11: : | C11: =IF(GİRİŞ!$D$27="","",IF(GİRİŞ!$D$56="Evet","Girilen değer TOPLAM sistem verimidir — palanga düşüşü uygulanmaz","Palangalı sistemde verim ( i > 1 ise η − 0,10 )")) | D11: = | E11: =IF(GİRİŞ!$D$27="","",IF(GİRİŞ!$D$56="Evet",GİRİŞ!$D$29,IF(IF(ISNUMBER(GİRİŞ!$D$53),GİRİŞ!$D$53,SABİTLER!$C$22)>1,GİRİŞ!$D$29-SABİTLER!$C$11,GİRİŞ!$D$29))) | F11: — | G11: =IF(GİRİŞ!$D$56="Evet","GİRİŞ — toplam sistem verimi","SABİTLER A / MMO/697 §2.4")
C13: N = ( 1 − q ) · Q · V / ( 102 · η′ )
C14: =IF(GİRİŞ!$D$27="","","= "&IF(1-IF(ISNUMBER(GİRİŞ!$D$54),GİRİŞ!$D$54,SABİTLER!$C$23)>=IF(ISNUMBER(GİRİŞ!$D$54),GİRİŞ!$D$54,SABİTLER!$C$23),"( 1 − "&ROUND(IF(ISNUMBER(GİRİŞ!$D$54),GİRİŞ!$D$54,SABİTLER!$C$23),2)&" )",ROUND(IF(ISNUMBER(GİRİŞ!$D$54),GİRİŞ!$D$54,SABİTLER!$C$23),2))&" · "&ROUND(GİRİŞ!$D$27,0)&" · "&ROUND(GİRİŞ!$D$28,2)&" / ( 102 · "&ROUND(E11,2)&" )") | E14: =IF(GİRİŞ!$D$27="","",IF(E11<=0,"",MAX(1-IF(ISNUMBER(GİRİŞ!$D$54),GİRİŞ!$D$54,SABİTLER!$C$23),IF(ISNUMBER(GİRİŞ!$D$54),GİRİŞ!$D$54,SABİTLER!$C$23))*GİRİŞ!$D$27*GİRİŞ!$D$28/(SABİTLER!$C$10*E11))) | F14: kW | G14: hesaplanan
A15: Nsç | B15: : | C15: SEÇİLEN motor gücü | D15: = | E15: =IF(GİRİŞ!$D$27="","",GİRİŞ!$D$43) | F15: kW | G15: GİRİŞ
C16: KONTROL Nsç ≥ N | E16: =IF(GİRİŞ!$D$27="","",IF(NOT(ISNUMBER(E14)),"η GİRDİSİ HATALI",IF(GİRİŞ!$D$43>=E14,"UYGUN","UYGUN DEĞİL — motoru büyütün")))
A18: 2 - KUVVET HESAPLARI ( MMO / 697 s.18-20 / TS EN 81-20 )
A19: ORTAK BÜYÜKLÜKLER
A20: gn | B20: : | C20: Yerçekimi ivmesi | D20: = | E20: =IF(GİRİŞ!$D$27="","",SABİTLER!$C$5) | F20: m/s² | G20: SABİTLER A
A21: Gk | B21: : | C21: Boş kabin kütlesi | D21: = | E21: =IF(GİRİŞ!$D$27="","",GİRİŞ!$D$38) | F21: kg | G21: GİRİŞ
A22: gf | B22: : | C22: Gezici kablo ( flexbil ) birim kütlesi | D22: = | E22: =IF(GİRİŞ!$D$27="","",SABİTLER!$C$25) | F22: kg/m | G22: SABİTLER B
C23: Gf = gf · ( Hk / 2 + 3 ) ( gezici kablo kütlesi )
C24: =IF(GİRİŞ!$D$27="","","= "&ROUND(SABİTLER!$C$25,2)&" · ( "&ROUND(GİRİŞ!$D$31,2)&" / 2 + 3 )") | E24: =IF(GİRİŞ!$D$27="","",SABİTLER!$C$25*(GİRİŞ!$D$31/2+SABİTLER!$C$19)) | F24: kg
C25: P = Gk + Gf ( kabin tarafından desteklenen toplam kütle )
C26: =IF(GİRİŞ!$D$27="","","= "&ROUND(GİRİŞ!$D$38,0)&" + "&ROUND(E24,2)) | E26: =IF(GİRİŞ!$D$27="","",GİRİŞ!$D$38+E24) | F26: kg
A27: Q | B27: : | C27: Anma yükü | D27: = | E27: =IF(GİRİŞ!$D$27="","",GİRİŞ!$D$27) | F27: kg | G27: GİRİŞ
A28: q | B28: : | C28: Denge faktörü | D28: = | E28: =IF(GİRİŞ!$D$27="","",IF(ISNUMBER(GİRİŞ!$D$54),GİRİŞ!$D$54,SABİTLER!$C$23)) | F28: — | G28: =IF(ISNUMBER(GİRİŞ!$D$54),"GİRİŞ — asansör bazında","SABİTLER B")
C29: Ga = P + q · Q ( karşı ağırlık kütlesi )
C30: =IF(GİRİŞ!$D$27="","","= "&ROUND(E26,2)&" + "&ROUND(IF(ISNUMBER(GİRİŞ!$D$54),GİRİŞ!$D$54,SABİTLER!$C$23),2)&" · "&ROUND(GİRİŞ!$D$27,0)) | E30: =IF(GİRİŞ!$D$27="","",E26+IF(ISNUMBER(GİRİŞ!$D$54),GİRİŞ!$D$54,SABİTLER!$C$23)*GİRİŞ!$D$27) | F30: kg
A31: k1 | B31: : | C31: Darbe faktörü ( V > 1 → 2 / V > 0,63 → 3 / V ≤ 0,63 → 5 ) | D31: = | E31: =IF(GİRİŞ!$D$27="","",IF(GİRİŞ!$D$28>1,SABİTLER!$C$7,IF(GİRİŞ!$D$28>0.63,SABİTLER!$C$8,SABİTLER!$C$9))) | F31: — | G31: SABİTLER A / MMO/697 Çiz-1
A32: n | B32: : | C32: Kabin kılavuz ray sayısı | D32: = | E32: =IF(GİRİŞ!$D$27="","",SABİTLER!$C$24) | F32: adet | G32: SABİTLER B
A33: gr | B33: : | C33: 1 m kılavuz rayın kütlesi | D33: = | E33: =IF(GİRİŞ!$D$27="","",GİRİŞ!$D$39) | F33: kg/m | G33: GİRİŞ
A34: Lr | B34: : | C34: Kılavuz ray uzunluğu ( Hk − 0,20 ) | D34: = | E34: =IF(GİRİŞ!$D$27="","",GİRİŞ!$D$31-SABİTLER!$C$18) | F34: m
C35: Mg = Lr · gr ( bir kılavuz ray hattının kütlesi )
C36: =IF(GİRİŞ!$D$27="","","= "&ROUND(E34,2)&" · "&ROUND(GİRİŞ!$D$39,2)) | E36: =IF(GİRİŞ!$D$27="","",E34*GİRİŞ!$D$39) | F36: kg
A38: A - KUYU ALT BOŞLUĞU TABANINA GELEN KUVVET ( kabin tamponu altı )
C39: P1 = 4 · gn · ( P + Q )
C40: =IF(GİRİŞ!$D$27="","","= "&ROUND(SABİTLER!$C$6,0)&" · "&ROUND(SABİTLER!$C$5,2)&" · ( "&ROUND(E26,2)&" + "&ROUND(GİRİŞ!$D$27,0)&" )") | E40: =IF(GİRİŞ!$D$27="","",CEILING(SABİTLER!$C$6*SABİTLER!$C$5*(E26+GİRİŞ!$D$27),10)) | F40: N
A42: B - KARŞI AĞIRLIK TAMPONU ALTINDAKİ ZEMİNE GELEN KUVVET
C43: P2 = 4 · gn · ( P + q · Q ) = 4 · gn · Ga
C44: =IF(GİRİŞ!$D$27="","","= "&ROUND(SABİTLER!$C$6,0)&" · "&ROUND(SABİTLER!$C$5,2)&" · "&ROUND(E30,2)) | E44: =IF(GİRİŞ!$D$27="","",CEILING(SABİTLER!$C$6*SABİTLER!$C$5*E30,10)) | F44: N
A46: C - KABİN KILAVUZ RAYLARINA GELEN DÜŞEY KUVVET
C47: PR = k1 · gn · ( P + Q ) / n + Mg · gn
...

Sheet 3 NOLU ASANSÖR
A1: 3 NOLU ASANSÖR — AVAN PROJE HESAPLARI
A3: =IF(GİRİŞ!$E$27<>"",IF(GİRİŞ!$E$23="","","Asansör tanımı : "&GİRİŞ!$E$23),IF(GİRİŞ!$E$24="","!!! BU ASANSÖR GİRİŞ SAYFASINDA TANIMLANMAMIŞ — hesaplar boştur !!!","!!! KAPASİTE TABLO-7 DIŞI — GİRİŞ sayfasında 'Anma yükü — elle' satırını doldurun !!!"))
A5: 1 - MOTOR GÜCÜ HESABI ( MMO / 697 — s.21 )
A6: Q | B6: : | C6: Anma yükü | D6: = | E6: =IF(GİRİŞ!$E$27="","",GİRİŞ!$E$27) | F6: kg | G6: GİRİŞ
A7: V | B7: : | C7: Kabin hızı | D7: = | E7: =IF(GİRİŞ!$E$27="","",GİRİŞ!$E$28) | F7: m/s | G7: GİRİŞ
A8: q | B8: : | C8: Denge faktörü ( karşı ağırlığın dengelediği oran ) | D8: = | E8: =IF(GİRİŞ!$E$27="","",IF(ISNUMBER(GİRİŞ!$E$54),GİRİŞ!$E$54,SABİTLER!$C$23)) | F8: — | G8: =IF(ISNUMBER(GİRİŞ!$E$54),"GİRİŞ — asansör bazında","SABİTLER B")
A9: i | B9: : | C9: Palanga ( askı ) katsayısı | D9: = | E9: =IF(GİRİŞ!$E$27="","",IF(ISNUMBER(GİRİŞ!$E$53),GİRİŞ!$E$53,SABİTLER!$C$22)) | F9: — | G9: =IF(ISNUMBER(GİRİŞ!$E$53),"GİRİŞ — asansör bazında","SABİTLER B")
A10: η | B10: : | C10: Makine verimi | D10: = | E10: =IF(GİRİŞ!$E$27="","",GİRİŞ!$E$29) | F10: — | G10: GİRİŞ
A11: η′ | B11: : | C11: =IF(GİRİŞ!$E$27="","",IF(GİRİŞ!$E$56="Evet","Girilen değer TOPLAM sistem verimidir — palanga düşüşü uygulanmaz","Palangalı sistemde verim ( i > 1 ise η − 0,10 )")) | D11: = | E11: =IF(GİRİŞ!$E$27="","",IF(GİRİŞ!$E$56="Evet",GİRİŞ!$E$29,IF(IF(ISNUMBER(GİRİŞ!$E$53),GİRİŞ!$E$53,SABİTLER!$C$22)>1,GİRİŞ!$E$29-SABİTLER!$C$11,GİRİŞ!$E$29))) | F11: — | G11: =IF(GİRİŞ!$E$56="Evet","GİRİŞ — toplam sistem verimi","SABİTLER A / MMO/697 §2.4")
C13: N = ( 1 − q ) · Q · V / ( 102 · η′ )
C14: =IF(GİRİŞ!$E$27="","","= "&IF(1-IF(ISNUMBER(GİRİŞ!$E$54),GİRİŞ!$E$54,SABİTLER!$C$23)>=IF(ISNUMBER(GİRİŞ!$E$54),GİRİŞ!$E$54,SABİTLER!$C$23),"( 1 − "&ROUND(IF(ISNUMBER(GİRİŞ!$E$54),GİRİŞ!$E$54,SABİTLER!$C$23),2)&" )",ROUND(IF(ISNUMBER(GİRİŞ!$E$54),GİRİŞ!$E$54,SABİTLER!$C$23),2))&" · "&ROUND(GİRİŞ!$E$27,0)&" · "&ROUND(GİRİŞ!$E$28,2)&" / ( 102 · "&ROUND(E11,2)&" )") | E14: =IF(GİRİŞ!$E$27="","",IF(E11<=0,"",MAX(1-IF(ISNUMBER(GİRİŞ!$E$54),GİRİŞ!$E$54,SABİTLER!$C$23),IF(ISNUMBER(GİRİŞ!$E$54),GİRİŞ!$E$54,SABİTLER!$C$23))*GİRİŞ!$E$27*GİRİŞ!$E$28/(SABİTLER!$C$10*E11))) | F14: kW | G14: hesaplanan
A15: Nsç | B15: : | C15: SEÇİLEN motor gücü | D15: = | E15: =IF(GİRİŞ!$E$27="","",GİRİŞ!$E$43) | F15: kW | G15: GİRİŞ
C16: KONTROL Nsç ≥ N | E16: =IF(GİRİŞ!$E$27="","",IF(NOT(ISNUMBER(E14)),"η GİRDİSİ HATALI",IF(GİRİŞ!$E$43>=E14,"UYGUN","UYGUN DEĞİL — motoru büyütün")))
A18: 2 - KUVVET HESAPLARI ( MMO / 697 s.18-20 / TS EN 81-20 )
A19: ORTAK BÜYÜKLÜKLER
A20: gn | B20: : | C20: Yerçekimi ivmesi | D20: = | E20: =IF(GİRİŞ!$E$27="","",SABİTLER!$C$5) | F20: m/s² | G20: SABİTLER A
A21: Gk | B21: : | C21: Boş kabin kütlesi | D21: = | E21: =IF(GİRİŞ!$E$27="","",GİRİŞ!$E$38) | F21: kg | G21: GİRİŞ
A22: gf | B22: : | C22: Gezici kablo ( flexbil ) birim kütlesi | D22: = | E22: =IF(GİRİŞ!$E$27="","",SABİTLER!$C$25) | F22: kg/m | G22: SABİTLER B
C23: Gf = gf · ( Hk / 2 + 3 ) ( gezici kablo kütlesi )
C24: =IF(GİRİŞ!$E$27="","","= "&ROUND(SABİTLER!$C$25,2)&" · ( "&ROUND(GİRİŞ!$E$31,2)&" / 2 + 3 )") | E24: =IF(GİRİŞ!$E$27="","",SABİTLER!$C$25*(GİRİŞ!$E$31/2+SABİTLER!$C$19)) | F24: kg
C25: P = Gk + Gf ( kabin tarafından desteklenen toplam kütle )
C26: =IF(GİRİŞ!$E$27="","","= "&ROUND(GİRİŞ!$E$38,0)&" + "&ROUND(E24,2)) | E26: =IF(GİRİŞ!$E$27="","",GİRİŞ!$E$38+E24) | F26: kg
A27: Q | B27: : | C27: Anma yükü | D27: = | E27: =IF(GİRİŞ!$E$27="","",GİRİŞ!$E$27) | F27: kg | G27: GİRİŞ
A28: q | B28: : | C28: Denge faktörü | D28: = | E28: =IF(GİRİŞ!$E$27="","",IF(ISNUMBER(GİRİŞ!$E$54),GİRİŞ!$E$54,SABİTLER!$C$23)) | F28: — | G28: =IF(ISNUMBER(GİRİŞ!$E$54),"GİRİŞ — asansör bazında","SABİTLER B")
C29: Ga = P + q · Q ( karşı ağırlık kütlesi )
C30: =IF(GİRİŞ!$E$27="","","= "&ROUND(E26,2)&" + "&ROUND(IF(ISNUMBER(GİRİŞ!$E$54),GİRİŞ!$E$54,SABİTLER!$C$23),2)&" · "&ROUND(GİRİŞ!$E$27,0)) | E30: =IF(GİRİŞ!$E$27="","",E26+IF(ISNUMBER(GİRİŞ!$E$54),GİRİŞ!$E$54,SABİTLER!$C$23)*GİRİŞ!$E$27) | F30: kg
A31: k1 | B31: : | C31: Darbe faktörü ( V > 1 → 2 / V > 0,63 → 3 / V ≤ 0,63 → 5 ) | D31: = | E31: =IF(GİRİŞ!$E$27="","",IF(GİRİŞ!$E$28>1,SABİTLER!$C$7,IF(GİRİŞ!$E$28>0.63,SABİTLER!$C$8,SABİTLER!$C$9))) | F31: — | G31: SABİTLER A / MMO/697 Çiz-1
A32: n | B32: : | C32: Kabin kılavuz ray sayısı | D32: = | E32: =IF(GİRİŞ!$E$27="","",SABİTLER!$C$24) | F32: adet | G32: SABİTLER B
A33: gr | B33: : | C33: 1 m kılavuz rayın kütlesi | D33: = | E33: =IF(GİRİŞ!$E$27="","",GİRİŞ!$E$39) | F33: kg/m | G33: GİRİŞ
A34: Lr | B34: : | C34: Kılavuz ray uzunluğu ( Hk − 0,20 ) | D34: = | E34: =IF(GİRİŞ!$E$27="","",GİRİŞ!$E$31-SABİTLER!$C$18) | F34: m
C35: Mg = Lr · gr ( bir kılavuz ray hattının kütlesi )
C36: =IF(GİRİŞ!$E$27="","","= "&ROUND(E34,2)&" · "&ROUND(GİRİŞ!$E$39,2)) | E36: =IF(GİRİŞ!$E$27="","",E34*GİRİŞ!$E$39) | F36: kg
A38: A - KUYU ALT BOŞLUĞU TABANINA GELEN KUVVET ( kabin tamponu altı )
C39: P1 = 4 · gn · ( P + Q )
C40: =IF(GİRİŞ!$E$27="","","= "&ROUND(SABİTLER!$C$6,0)&" · "&ROUND(SABİTLER!$C$5,2)&" · ( "&ROUND(E26,2)&" + "&ROUND(GİRİŞ!$E$27,0)&" )") | E40: =IF(GİRİŞ!$E$27="","",CEILING(SABİTLER!$C$6*SABİTLER!$C$5*(E26+GİRİŞ!$E$27),10)) | F40: N
A42: B - KARŞI AĞIRLIK TAMPONU ALTINDAKİ ZEMİNE GELEN KUVVET
C43: P2 = 4 · gn · ( P + q · Q ) = 4 · gn · Ga
C44: =IF(GİRİŞ!$E$27="","","= "&ROUND(SABİTLER!$C$6,0)&" · "&ROUND(SABİTLER!$C$5,2)&" · "&ROUND(E30,2)) | E44: =IF(GİRİŞ!$E$27="","",CEILING(SABİTLER!$C$6*SABİTLER!$C$5*E30,10)) | F44: N
A46: C - KABİN KILAVUZ RAYLARINA GELEN DÜŞEY KUVVET
C47: PR = k1 · gn · ( P + Q ) / n + Mg · gn
...

Sheet 4 NOLU ASANSÖR
A1: 4 NOLU ASANSÖR — AVAN PROJE HESAPLARI
A3: =IF(GİRİŞ!$F$27<>"",IF(GİRİŞ!$F$23="","","Asansör tanımı : "&GİRİŞ!$F$23),IF(GİRİŞ!$F$24="","!!! BU ASANSÖR GİRİŞ SAYFASINDA TANIMLANMAMIŞ — hesaplar boştur !!!","!!! KAPASİTE TABLO-7 DIŞI — GİRİŞ sayfasında 'Anma yükü — elle' satırını doldurun !!!"))
A5: 1 - MOTOR GÜCÜ HESABI ( MMO / 697 — s.21 )
A6: Q | B6: : | C6: Anma yükü | D6: = | E6: =IF(GİRİŞ!$F$27="","",GİRİŞ!$F$27) | F6: kg | G6: GİRİŞ
A7: V | B7: : | C7: Kabin hızı | D7: = | E7: =IF(GİRİŞ!$F$27="","",GİRİŞ!$F$28) | F7: m/s | G7: GİRİŞ
A8: q | B8: : | C8: Denge faktörü ( karşı ağırlığın dengelediği oran ) | D8: = | E8: =IF(GİRİŞ!$F$27="","",IF(ISNUMBER(GİRİŞ!$F$54),GİRİŞ!$F$54,SABİTLER!$C$23)) | F8: — | G8: =IF(ISNUMBER(GİRİŞ!$F$54),"GİRİŞ — asansör bazında","SABİTLER B")
A9: i | B9: : | C9: Palanga ( askı ) katsayısı | D9: = | E9: =IF(GİRİŞ!$F$27="","",IF(ISNUMBER(GİRİŞ!$F$53),GİRİŞ!$F$53,SABİTLER!$C$22)) | F9: — | G9: =IF(ISNUMBER(GİRİŞ!$F$53),"GİRİŞ — asansör bazında","SABİTLER B")
A10: η | B10: : | C10: Makine verimi | D10: = | E10: =IF(GİRİŞ!$F$27="","",GİRİŞ!$F$29) | F10: — | G10: GİRİŞ
A11: η′ | B11: : | C11: =IF(GİRİŞ!$F$27="","",IF(GİRİŞ!$F$56="Evet","Girilen değer TOPLAM sistem verimidir — palanga düşüşü uygulanmaz","Palangalı sistemde verim ( i > 1 ise η − 0,10 )")) | D11: = | E11: =IF(GİRİŞ!$F$27="","",IF(GİRİŞ!$F$56="Evet",GİRİŞ!$F$29,IF(IF(ISNUMBER(GİRİŞ!$F$53),GİRİŞ!$F$53,SABİTLER!$C$22)>1,GİRİŞ!$F$29-SABİTLER!$C$11,GİRİŞ!$F$29))) | F11: — | G11: =IF(GİRİŞ!$F$56="Evet","GİRİŞ — toplam sistem verimi","SABİTLER A / MMO/697 §2.4")
C13: N = ( 1 − q ) · Q · V / ( 102 · η′ )
C14: =IF(GİRİŞ!$F$27="","","= "&IF(1-IF(ISNUMBER(GİRİŞ!$F$54),GİRİŞ!$F$54,SABİTLER!$C$23)>=IF(ISNUMBER(GİRİŞ!$F$54),GİRİŞ!$F$54,SABİTLER!$C$23),"( 1 − "&ROUND(IF(ISNUMBER(GİRİŞ!$F$54),GİRİŞ!$F$54,SABİTLER!$C$23),2)&" )",ROUND(IF(ISNUMBER(GİRİŞ!$F$54),GİRİŞ!$F$54,SABİTLER!$C$23),2))&" · "&ROUND(GİRİŞ!$F$27,0)&" · "&ROUND(GİRİŞ!$F$28,2)&" / ( 102 · "&ROUND(E11,2)&" )") | E14: =IF(GİRİŞ!$F$27="","",IF(E11<=0,"",MAX(1-IF(ISNUMBER(GİRİŞ!$F$54),GİRİŞ!$F$54,SABİTLER!$C$23),IF(ISNUMBER(GİRİŞ!$F$54),GİRİŞ!$F$54,SABİTLER!$C$23))*GİRİŞ!$F$27*GİRİŞ!$F$28/(SABİTLER!$C$10*E11))) | F14: kW | G14: hesaplanan
A15: Nsç | B15: : | C15: SEÇİLEN motor gücü | D15: = | E15: =IF(GİRİŞ!$F$27="","",GİRİŞ!$F$43) | F15: kW | G15: GİRİŞ
C16: KONTROL Nsç ≥ N | E16: =IF(GİRİŞ!$F$27="","",IF(NOT(ISNUMBER(E14)),"η GİRDİSİ HATALI",IF(GİRİŞ!$F$43>=E14,"UYGUN","UYGUN DEĞİL — motoru büyütün")))
A18: 2 - KUVVET HESAPLARI ( MMO / 697 s.18-20 / TS EN 81-20 )
A19: ORTAK BÜYÜKLÜKLER
A20: gn | B20: : | C20: Yerçekimi ivmesi | D20: = | E20: =IF(GİRİŞ!$F$27="","",SABİTLER!$C$5) | F20: m/s² | G20: SABİTLER A
A21: Gk | B21: : | C21: Boş kabin kütlesi | D21: = | E21: =IF(GİRİŞ!$F$27="","",GİRİŞ!$F$38) | F21: kg | G21: GİRİŞ
A22: gf | B22: : | C22: Gezici kablo ( flexbil ) birim kütlesi | D22: = | E22: =IF(GİRİŞ!$F$27="","",SABİTLER!$C$25) | F22: kg/m | G22: SABİTLER B
C23: Gf = gf · ( Hk / 2 + 3 ) ( gezici kablo kütlesi )
C24: =IF(GİRİŞ!$F$27="","","= "&ROUND(SABİTLER!$C$25,2)&" · ( "&ROUND(GİRİŞ!$F$31,2)&" / 2 + 3 )") | E24: =IF(GİRİŞ!$F$27="","",SABİTLER!$C$25*(GİRİŞ!$F$31/2+SABİTLER!$C$19)) | F24: kg
C25: P = Gk + Gf ( kabin tarafından desteklenen toplam kütle )
C26: =IF(GİRİŞ!$F$27="","","= "&ROUND(GİRİŞ!$F$38,0)&" + "&ROUND(E24,2)) | E26: =IF(GİRİŞ!$F$27="","",GİRİŞ!$F$38+E24) | F26: kg
A27: Q | B27: : | C27: Anma yükü | D27: = | E27: =IF(GİRİŞ!$F$27="","",GİRİŞ!$F$27) | F27: kg | G27: GİRİŞ
A28: q | B28: : | C28: Denge faktörü | D28: = | E28: =IF(GİRİŞ!$F$27="","",IF(ISNUMBER(GİRİŞ!$F$54),GİRİŞ!$F$54,SABİTLER!$C$23)) | F28: — | G28: =IF(ISNUMBER(GİRİŞ!$F$54),"GİRİŞ — asansör bazında","SABİTLER B")
C29: Ga = P + q · Q ( karşı ağırlık kütlesi )
C30: =IF(GİRİŞ!$F$27="","","= "&ROUND(E26,2)&" + "&ROUND(IF(ISNUMBER(GİRİŞ!$F$54),GİRİŞ!$F$54,SABİTLER!$C$23),2)&" · "&ROUND(GİRİŞ!$F$27,0)) | E30: =IF(GİRİŞ!$F$27="","",E26+IF(ISNUMBER(GİRİŞ!$F$54),GİRİŞ!$F$54,SABİTLER!$C$23)*GİRİŞ!$F$27) | F30: kg
A31: k1 | B31: : | C31: Darbe faktörü ( V > 1 → 2 / V > 0,63 → 3 / V ≤ 0,63 → 5 ) | D31: = | E31: =IF(GİRİŞ!$F$27="","",IF(GİRİŞ!$F$28>1,SABİTLER!$C$7,IF(GİRİŞ!$F$28>0.63,SABİTLER!$C$8,SABİTLER!$C$9))) | F31: — | G31: SABİTLER A / MMO/697 Çiz-1
A32: n | B32: : | C32: Kabin kılavuz ray sayısı | D32: = | E32: =IF(GİRİŞ!$F$27="","",SABİTLER!$C$24) | F32: adet | G32: SABİTLER B
A33: gr | B33: : | C33: 1 m kılavuz rayın kütlesi | D33: = | E33: =IF(GİRİŞ!$F$27="","",GİRİŞ!$F$39) | F33: kg/m | G33: GİRİŞ
A34: Lr | B34: : | C34: Kılavuz ray uzunluğu ( Hk − 0,20 ) | D34: = | E34: =IF(GİRİŞ!$F$27="","",GİRİŞ!$F$31-SABİTLER!$C$18) | F34: m
C35: Mg = Lr · gr ( bir kılavuz ray hattının kütlesi )
C36: =IF(GİRİŞ!$F$27="","","= "&ROUND(E34,2)&" · "&ROUND(GİRİŞ!$F$39,2)) | E36: =IF(GİRİŞ!$F$27="","",E34*GİRİŞ!$F$39) | F36: kg
A38: A - KUYU ALT BOŞLUĞU TABANINA GELEN KUVVET ( kabin tamponu altı )
C39: P1 = 4 · gn · ( P + Q )
C40: =IF(GİRİŞ!$F$27="","","= "&ROUND(SABİTLER!$C$6,0)&" · "&ROUND(SABİTLER!$C$5,2)&" · ( "&ROUND(E26,2)&" + "&ROUND(GİRİŞ!$F$27,0)&" )") | E40: =IF(GİRİŞ!$F$27="","",CEILING(SABİTLER!$C$6*SABİTLER!$C$5*(E26+GİRİŞ!$F$27),10)) | F40: N
A42: B - KARŞI AĞIRLIK TAMPONU ALTINDAKİ ZEMİNE GELEN KUVVET
C43: P2 = 4 · gn · ( P + q · Q ) = 4 · gn · Ga
C44: =IF(GİRİŞ!$F$27="","","= "&ROUND(SABİTLER!$C$6,0)&" · "&ROUND(SABİTLER!$C$5,2)&" · "&ROUND(E30,2)) | E44: =IF(GİRİŞ!$F$27="","",CEILING(SABİTLER!$C$6*SABİTLER!$C$5*E30,10)) | F44: N
A46: C - KABİN KILAVUZ RAYLARINA GELEN DÜŞEY KUVVET
C47: PR = k1 · gn · ( P + Q ) / n + Mg · gn
...

Sheet MK.DAİRESİ AYD.
A1: ASANSÖR MAKİNE DAİRESİ — AYDINLATMA HESABI
A3: =IF(OR(GİRİŞ!$C$15="Evet",GİRİŞ!$C$16=0,GİRİŞ!$C$17=0),"Makine dairesiz ( MRL ) sistem — bu hesap uygulanmaz.","")
A5: MAKİNE DAİRESİ AYDINLATMA HESABI ( TS EN 81-20 )
A6: a | B6: : | C6: Makine dairesi uzunluğu | D6: = | E6: =IF(OR(GİRİŞ!$C$15="Evet",GİRİŞ!$C$16=0,GİRİŞ!$C$17=0),"",GİRİŞ!$C$16/1000) | F6: m | G6: GİRİŞ
A7: b | B7: : | C7: Makine dairesi genişliği | D7: = | E7: =IF(OR(GİRİŞ!$C$15="Evet",GİRİŞ!$C$16=0,GİRİŞ!$C$17=0),"",GİRİŞ!$C$17/1000) | F7: m | G7: GİRİŞ
A8: h | B8: : | C8: Armatür ile çalışma düzlemi arasındaki yükseklik | D8: = | E8: =SABİTLER!$C$17 | F8: m | G8: SABİTLER A
C9: k = a · b / ( h · ( a + b ) ) ( bölge indeksi )
C10: =IF(OR(GİRİŞ!$C$15="Evet",GİRİŞ!$C$16=0,GİRİŞ!$C$17=0),"","= "&ROUND(E6,2)&" · "&ROUND(E7,2)&" / ( "&ROUND(E8,2)&" · ( "&ROUND(E6,2)&" + "&ROUND(E7,2)&" ) )") | E10: =IF(OR(GİRİŞ!$C$15="Evet",GİRİŞ!$C$16=0,GİRİŞ!$C$17=0),"",E6*E7/(E8*(E6+E7))) | F10: —
A11: η | B11: : | C11: Oda aydınlatma verimi | D11: = | E11: =IF(OR(GİRİŞ!$C$15="Evet",GİRİŞ!$C$16=0,GİRİŞ!$C$17=0),"",IFERROR(INDEX(TABLOLAR!$B$8:$K$17,MATCH(MAX(E10,TABLOLAR!$A$8),TABLOLAR!$A$8:$A$17,1),TABLOLAR!$B$19),"")) | F11: — | G11: TABLOLAR T2
A12: E | B12: : | C12: Asgari aydınlatma şiddeti | D12: = | E12: =SABİTLER!$C$13 | F12: lüx | G12: SABİTLER A
A13: d | B13: : | C13: Kirlenme ( bakım ) faktörü | D13: = | E13: =SABİTLER!$C$12 | F13: — | G13: SABİTLER A
C14: T = E · a · b · d / η ( gerekli toplam ışık akısı )
C15: =IF(OR(GİRİŞ!$C$15="Evet",GİRİŞ!$C$16=0,GİRİŞ!$C$17=0),"","= "&ROUND(E12,0)&" · "&ROUND(E6,2)&" · "&ROUND(E7,2)&" · "&ROUND(E13,2)&" / "&ROUND(E11,2)) | E15: =IF(OR(GİRİŞ!$C$15="Evet",GİRİŞ!$C$16=0,GİRİŞ!$C$17=0),"",IFERROR(E12*E6*E7*E13/E11,"")) | F15: lm
A16: ØL | B16: : | C16: Bir armatürün ışık akısı | D16: = | E16: =SABİTLER!$C$31 | F16: lm | G16: SABİTLER B
C17: Z = T / ØL
C18: =IF(OR(GİRİŞ!$C$15="Evet",GİRİŞ!$C$16=0,GİRİŞ!$C$17=0),"","= "&ROUND(E15,2)&" / "&ROUND(E16,0)) | E18: =IF(OR(GİRİŞ!$C$15="Evet",GİRİŞ!$C$16=0,GİRİŞ!$C$17=0),"",IFERROR(E15/E16,"")) | F18: adet
A19: n | B19: : | C19: SEÇİLEN armatür sayısı ( Z yukarı yuvarlanır ) | D19: = | E19: =IF(OR(GİRİŞ!$C$15="Evet",GİRİŞ!$C$16=0,GİRİŞ!$C$17=0),"",IFERROR(ROUNDUP(E18,0),"")) | F19: adet
A20: =IF(OR(GİRİŞ!$C$15="Evet",GİRİŞ!$C$16=0,GİRİŞ!$C$17=0),"",IF(E19="","","SONUÇ : "&E19&" adet "&SABİTLER!$C$30&" W armatür kullanılacaktır."))

Sheet TOPRAKLAMA
A1: TEMEL TOPRAKLAMA HESABI
A3: Temel ( ızgara ) topraklayıcı + paralel çubuk topraklayıcı
A5: 1 - YATAY ( TEMEL ) TOPRAKLAYICI
C6: A = a · b ( temel alanı )
C7: =IF(NOT(AND(GİRİŞ!$C$10>0,GİRİŞ!$C$11>0,GİRİŞ!$C$12>0,GİRİŞ!$C$13>0)),"","= "&ROUND(GİRİŞ!$C$10,2)&" · "&ROUND(GİRİŞ!$C$11,2)) | E7: =IF(NOT(AND(GİRİŞ!$C$10>0,GİRİŞ!$C$11>0,GİRİŞ!$C$12>0,GİRİŞ!$C$13>0)),"",GİRİŞ!$C$10*GİRİŞ!$C$11) | F7: m² | G7: GİRİŞ
C8: r = √ ( A / π ) ( eşdeğer yarıçap )
C9: =IF(NOT(AND(GİRİŞ!$C$10>0,GİRİŞ!$C$11>0,GİRİŞ!$C$12>0,GİRİŞ!$C$13>0)),"","= √ ( "&ROUND(E7,2)&" / 3,1416 )") | E9: =IF(NOT(AND(GİRİŞ!$C$10>0,GİRİŞ!$C$11>0,GİRİŞ!$C$12>0,GİRİŞ!$C$13>0)),"",SQRT(E7/PI())) | F9: m
C10: D = 2 · r ( eşdeğer daire çapı )
C11: =IF(NOT(AND(GİRİŞ!$C$10>0,GİRİŞ!$C$11>0,GİRİŞ!$C$12>0,GİRİŞ!$C$13>0)),"","= 2 · "&ROUND(E9,2)) | E11: =IF(NOT(AND(GİRİŞ!$C$10>0,GİRİŞ!$C$11>0,GİRİŞ!$C$12>0,GİRİŞ!$C$13>0)),"",2*E9) | F11: m
A12: β | B12: : | C12: Toprak özgül direnci | D12: = | E12: =GİRİŞ!$C$12 | F12: Ω·m | G12: GİRİŞ
A13: L | B13: : | C13: Temel / şerit iletken uzunluğu | D13: = | E13: =GİRİŞ!$C$13 | F13: m | G13: GİRİŞ
C14: Ry = β / ( 2 · D ) + β / L
C15: =IF(NOT(AND(GİRİŞ!$C$10>0,GİRİŞ!$C$11>0,GİRİŞ!$C$12>0,GİRİŞ!$C$13>0)),"","= "&ROUND(E12,0)&" / ( 2 · "&ROUND(E11,2)&" ) + "&ROUND(E12,0)&" / "&ROUND(E13,2)) | E15: =IF(NOT(AND(GİRİŞ!$C$10>0,GİRİŞ!$C$11>0,GİRİŞ!$C$12>0,GİRİŞ!$C$13>0)),"",E12/(2*E11)+E12/E13) | F15: Ω | G15: IEEE Std 80
A17: 2 - DİKEY ( ÇUBUK ) TOPRAKLAYICI
A18: lç | B18: : | C18: Bir çubuğun boyu | D18: = | E18: =SABİTLER!$C$38 | F18: m | G18: SABİTLER B
A19: Is | B19: : | C19: Paralel bağlı çubuk sayısı | D19: = | E19: =GİRİŞ!$C$14 | F19: adet | G19: GİRİŞ
C20: Rç = β / ( Is · lç ) ( tek çubuk β/lç — Is adet paralel )
C21: =IF(OR(E19<=0,E18<=0),"— ( çubuk topraklayıcı yok )","= "&ROUND(E12,0)&" / ( "&ROUND(E19,0)&" · "&ROUND(E18,2)&" )") | E21: =IF(OR(E19<=0,E18<=0),"",IF(NOT(AND(GİRİŞ!$C$10>0,GİRİŞ!$C$11>0,GİRİŞ!$C$12>0,GİRİŞ!$C$13>0)),"",E12/(E19*E18))) | F21: Ω
A23: 3 - TOPLAM TOPRAKLAMA DİRENCİ VE KONTROL
C24: Re = ( Ry · Rç ) / ( Ry + Rç ) ( paralel )
C25: =IF(NOT(ISNUMBER(E15)),"",IF(NOT(ISNUMBER(E21)),"= "&ROUND(E15,2)&" ( yalnız temel topraklayıcı )","= ( "&ROUND(E15,2)&" · "&ROUND(E21,2)&" ) / ( "&ROUND(E15,2)&" + "&ROUND(E21,2)&" )")) | E25: =IF(NOT(ISNUMBER(E15)),"",IF(NOT(ISNUMBER(E21)),E15,E15*E21/(E15+E21))) | F25: Ω
A26: UL | B26: : | C26: İzin verilen temas gerilimi | D26: = | E26: =SABİTLER!$C$36 | F26: V | G26: SABİTLER B
A27: IΔn | B27: : | C27: Kaçak akım rölesi anma akımı | D27: = | E27: =SABİTLER!$C$37 | F27: A | G27: SABİTLER B
C28: Re max = UL / IΔn
C29: =IF(E27<=0,"",""&"= "&ROUND(E26,0)&" / "&ROUND(E27,2)) | E29: =IF(E27<=0,"",E26/E27) | F29: Ω
C30: KONTROL Re ≤ Re max | E30: =IF(OR(NOT(ISNUMBER(E25)),NOT(ISNUMBER(E29))),"GİRDİ EKSİK",IF(E25<=E29,"UYGUN","UYGUN DEĞİL"))
A31: =IF(OR(NOT(ISNUMBER(E25)),NOT(ISNUMBER(E29))),"!!! GİRİŞ sayfasında temel ölçüleri / toprak direnci / şerit uzunluğu eksik veya sıfır !!!",IF(E25<=E29,"SONUÇ : Re = "&ROUND(E25,2)&" Ω ≤ "&ROUND(E29,2)&" Ω olduğundan temel topraklaması yeterlidir.","SONUÇ : Re = "&ROUND(E25,2)&" Ω > "&ROUND(E29,2)&" Ω — ek topraklayıcı gereklidir."))
A32: HESAPLANAN TAHMİNİ DEĞERDİR — TESİS TAMAMLANDIKTAN SONRA ÖLÇÜMLE DOĞRULANACAKTIR.
A34: KABULLER : Şebeke sistemi TT, izin verilen temas gerilimi UL = 50 V, kaçak akım rölesi IΔn = 300 mA kabul edilmiştir; şebeke TN sistem ise bu kontrol ölçütü geçerli değildir. Toprak özgül direnci β zemin etüdünden alınmalıdır, yoksa 150 Ω·m kabul edilmiştir. Rç bağıntısı çubuk çapını ve çubuklar arası etkileşimi içermeyen bir ön kabuldür.

Sheet TABLOLAR
A1: HESAPLARDA KULLANILAN TABLOLAR
A3: TABLO 2 — ODA AYDINLATMA VERİMİ ( η )
A4: Tavan | B4: 0.8 | C4: 0.8 | D4: 0.8 | E4: 0.8 | F4: 0.5 | G4: 0.5 | H4: 0.5 | I4: 0.5 | J4: 0.3 | K4: 0.3
A5: Duvar | B5: 0.5 | C5: 0.5 | D5: 0.3 | E5: 0.3 | F5: 0.5 | G5: 0.5 | H5: 0.3 | I5: 0.3 | J5: 0.3 | K5: 0.3
A6: Zemin | B6: 0.3 | C6: 0.1 | D6: 0.3 | E6: 0.1 | F6: 0.3 | G6: 0.1 | H6: 0.3 | I6: 0.1 | J6: 0.3 | K6: 0.1
A7: Sütun | B7: 1 | C7: 2 | D7: 3 | E7: 4 | F7: 5 | G7: 6 | H7: 7 | I7: 8 | J7: 9 | K7: 10
A8: 0.6 | B8: 0.24 | C8: 0.23 | D8: 0.18 | E8: 0.18 | F8: 0.2 | G8: 0.19 | H8: 0.15 | I8: 0.15 | J8: 0.15 | K8: 0.12
A9: 0.8 | B9: 0.31 | C9: 0.29 | D9: 0.24 | E9: 0.23 | F9: 0.25 | G9: 0.24 | H9: 0.2 | I9: 0.19 | J9: 0.17 | K9: 0.16
A10: 1 | B10: 0.36 | C10: 0.33 | D10: 0.29 | E10: 0.28 | F10: 0.29 | G10: 0.28 | H10: 0.24 | I10: 0.23 | J10: 0.2 | K10: 0.2
A11: 1.25 | B11: 0.41 | C11: 0.38 | D11: 0.34 | E11: 0.32 | F11: 0.33 | G11: 0.31 | H11: 0.28 | I11: 0.27 | J11: 0.24 | K11: 0.24
A12: 1.5 | B12: 0.45 | C12: 0.41 | D12: 0.38 | E12: 0.36 | F12: 0.36 | G12: 0.34 | H12: 0.32 | I12: 0.3 | J12: 0.26 | K12: 0.27
A13: 2 | B13: 0.51 | C13: 0.46 | D13: 0.45 | E13: 0.41 | F13: 0.41 | G13: 0.38 | H13: 0.37 | I13: 0.35 | J13: 0.3 | K13: 0.31
A14: 2.5 | B14: 0.56 | C14: 0.49 | D14: 0.5 | E14: 0.45 | F14: 0.45 | G14: 0.41 | H14: 0.41 | I14: 0.38 | J14: 0.34 | K14: 0.35
A15: 3 | B15: 0.59 | C15: 0.52 | D15: 0.54 | E15: 0.48 | F15: 0.47 | G15: 0.43 | H15: 0.43 | I15: 0.4 | J15: 0.36 | K15: 0.38
A16: 4 | B16: 0.63 | C16: 0.55 | D16: 0.58 | E16: 0.51 | F16: 0.5 | G16: 0.46 | H16: 0.47 | I16: 0.44 | J16: 0.39 | K16: 0.41
A17: 5 | B17: 0.66 | C17: 0.57 | D17: 0.62 | E17: 0.54 | F17: 0.53 | G17: 0.48 | H17: 0.5 | I17: 0.46 | J17: 0.4 | K17: 0.44
A19: Kullanılan sütun | B19: 2 | C19: tavan 0,80 / duvar 0,50 / zemin 0,10 — sütun numarasını değiştirerek başka yansıma çiftine geçebilirsiniz
A20: k değeri bir ALT satıra yuvarlanarak okunur (emniyetli taraf) — MATCH(...;1)
A23: TABLO 4 — ARMATÜR IŞIK AKILARI
A24: Armatür tipi | B24: Gücü | C24: Işık akısı (lm)
A25: Akkor telli | B25: 15 W | C25: 120 – 135
A26: Akkor telli | B26: 25 W | C26: 215 – 240
A27: Akkor telli | B27: 40 W | C27: 340 – 480
A28: Akkor telli | B28: 60 W | C28: 620 – 805
A29: Akkor telli | B29: 75 W | C29: 855 – 960
A30: Akkor telli | B30: 100 W | C30: 1250 – 1380
A31: Akkor telli | B31: 150 W | C31: 2100 – 2280
A32: Flüoresan | B32: 20 W | C32: 820
A33: Flüoresan | B33: 32 W | C33: 1400
A34: Flüoresan | B34: 40 W | C34: 2100
A35: Flüoresan | B35: 200 W | C35: 2950 – 3220
A36: LED spot | B36: 5 W | C36: 300
A37: NOT: Tablo 4'te 40 W flüoresan 2100 lm'dir; ofis teamülü 2600 lm'dir. Kullanılan değer SABİTLER sayfasındaki ØL satırındadır.
A39: TABLO 7 — KABİN KAPASİTESİ / ANMA YÜKÜ
A40: Kapasite (kişi) | B40: Anma yükü (kg)
A41: 6 | B41: 450
A42: 8 | B42: 630
A43: 10 | B43: 800
A44: 13 | B44: 1000
A45: 15 | B45: 1125
...

Sheet SABİTLER
A1: SABİTLER VE OFİS STANDARDI
A2: Aşağıdaki A bölümü yönetmelik / standart kaynaklıdır, değiştirilmez. B bölümü ofis standardıdır: tüm asansörler için ortaktır ve gerekirse buradan değiştirilir.
A3: A ) YÖNETMELİK / STANDART SABİTLERİ — değiştirmeyin
A4: Sembol | B4: Büyüklük | C4: Değer | D4: Birim | E4: Kaynak
A5: gn | B5: Yerçekimi ivmesi | C5: 9.81 | D5: m/s² | E5: MMO/697 s.18 — TS EN 81-20
A6: — | B6: Tampon altı zemin kuvvet katsayısı | C6: 4 | D6: — | E6: MMO/697 §2.3.3.1-2 — F = 4·gn·(P+Q)
A7: k1 | B7: Darbe faktörü — V > 1,00 m/s | C7: 2 | D7: — | E7: MMO/697 Çizelge-1 ( TS EN 81-20 Çiz.14 ) — kademeli güvenlik tertibatı / enerji dağıtan tip tampon
A8: k1 | B8: Darbe faktörü — 0,63 < V ≤ 1,00 m/s | C8: 3 | D8: — | E8: MMO/697 Çizelge-1 — enerji biriktiren tip tampon
A9: k1 | B9: Darbe faktörü — 0,15 < V ≤ 0,63 m/s | C9: 5 | D9: — | E9: MMO/697 Çizelge-1 — ani frenlemeli güvenlik tertibatı
A10: — | B10: Motor gücü denklem sabiti | C10: 102 | D10: kg·m/s | E10: MMO/697 §2.4 — N = (1/η)·[(Q/2·V)/102]
A11: Δη | B11: Palangalı sistemde verim düşüşü | C11: 0.1 | D11: — | E11: MMO/697 §2.4 — "Palangalı sistemlerde verim %10 az alınacaktır"
A12: d | B12: Aydınlatmada kirlenme (bakım) faktörü | C12: 1.25 | D12: — | E12: Aydınlatma tekniği teamülü
A13: E | B13: Aydınlatma şiddeti — makine dairesi | C13: 200 | D13: lüx | E13: TS EN 81-20 — MMO/697 kapsamı DIŞINDA
A14: E | B14: Aydınlatma şiddeti — kabin | C14: 100 | D14: lüx | E14: TS EN 81-20 — MMO/697 kapsamı DIŞINDA
A15: E | B15: Aydınlatma şiddeti — kuyu | C15: 50 | D15: lüx | E15: TS EN 81-20 — MMO/697 kapsamı DIŞINDA
A16: — | B16: Kuyu aydınlatmasına eklenen armatür | C16: 2 | D16: adet | E16: Kuyu dibi + kuyu üstü
... A19: — | B19: Flexbil uzunluğu sabiti | C19: 3 | D19: m | E19: Flexbil boyu = Hk / 2 + 3
A21: B ) OFİS STANDARDI — tüm asansörler için ortak, gerekirse buradan değiştirin
A22: i | B22: Palanga ( askı ) katsayısı | C22: 2 | D22: — | E22: Yedek değer. ASKI ORANI asansörün kendi özelliğidir — GİRİŞ sayfası 53. satırdan asansör bazında seçilir; burası yalnız boş bırakılan kolon için kullanılır.
A23: q | B23: Denge faktörü | C23: 0.5 | D23: — | E23: Karşı ağırlığın dengelediği anma yükü oranı — pratikte 0,50. → Asansör bazında GİRİŞ!54. satırdan ezilebilir.
A24: n | B24: Kabin kılavuz ray sayısı | C24: 2 | D24: adet | E24: Kabin daima iki raya oturur
A25: gf | B25: Gezici kablo ( flexbil ) birim kütlesi | C25: 1.5 | D25: kg/m | E25: İki katına çıksa P1 ancak ≈ %1,5 değişir
A26: Fmt | B26: Montör ağırlığı | C26: 150 | D26: kg | E26: Bakım personeli — kuyu üstü yükünde
A27: — | B27: Kabin armatürü — gücü | C27: 5 | D27: W | E27: LED spot
A28: ØL | B28: Kabin armatürü — ışık akısı | C28: 300 | D28: lm | E28: 5 W LED spot ≈ 300 lm ( TABLOLAR — Tablo 4 )
A29: — | B29: Kabin üstü armatür adedi | C29: 1 | D29: adet | E29: Kurulu güce eklenir, aydınlatma hesabına girmez
A30: — | B30: Kuyu armatürü — gücü | C30: 40 | D30: W | E30: Flüoresan
A31: ØL | B31: Kuyu armatürü — ışık akısı | C31: 2100 | D31: lm | E31: Tablo 4'te 40 W flüoresan 2100 lm'dir; ofis teamülü 2600 lm
A32: Dmax | B32: Kuyu armatürü azami aralığı | C32: 7 | D32: m | E32: Geometrik asgari adet kontrolü; 0 yazarsanız kontrol devre dışı kalır
A33: — | B33: Priz adedi | C33: 3 | D33: adet
A34: — | B34: Priz başına güç | C34: 300 | D34: W
A35: cosφ | B35: Güç katsayısı | C35: 0.9 | D35: — | E35: Hat akımı hesabında
A36: UL | B36: İzin verilen temas gerilimi | C36: 50 | D36: V | E36: TT sistem
A37: IΔn | B37: Kaçak akım rölesi anma akımı | C37: 0.3 | D37: A | E37: 300 mA = 0,30 A
A38: lç | B38: Çubuk topraklayıcı boyu | C38: 1.5 | D38: m | E38: Standart çubuk
A39: ηm | B39: Motorun elektrik verimi | C39: 0.85 | D39: — | E39: Şebekeden çekilen güç Pşeb = Nsç / ηm; kolon ve makine besleme hatlarında akan odur
A40: Bu SARI hücreler proje geneli için ORTAKTIR. Palanga katsayısı (i) ve denge faktörü (q) asansör bazında farklı olabildiğinden GİRİŞ sayfasının 53-54. satırından asansöre özel değer girilebilir; boş bırakılırsa buradaki değer kullanılır.
