Workbook
Name firmalistesi: TEKNİK!$U$2:$U$21
Name frenblokmarka: TEKNİK!$X$2:$X$21
Name hızregülatörmarka: TEKNİK!$Y$2:$Y$21
Name kapıkilitmarka: TEKNİK!$V$2:$V$21
Name kumandakartmarka: TEKNİK!$W$2:$W$21
Name rayçeliğirm: TEKNİK!$P$2:$P$4
Name tamponmarka: TEKNİK!$AA$2:$AA$21

Sheet Veri Girişi
B1: ELEKTRİKLİ ASANSÖR MUKAVEMET HESABI DOĞRULAMA (Doküman adı: KON-FR113 / Rev:06)
I2: Kapı İç Yükseklikleri | S2: =TEKNİK!A2 -> 180 | T2: =TEKNİK!F2 -> 0.63 | U2: =TEKNİK!E2 -> 2005 | V2: =TEKNİK!I2 -> Manuel Sağ | W2: =TEKNİK!G2 -> 700 | X2: =TEKNİK!J2 -> Sağ | Y2: =TEKNİK!K2 -> 50 x 50 x 5 | Z2: =TEKNİK!N2 -> Kremayer | AA2: =TABLOLAR!A32 -> 6
S3: =TEKNİK!A3 -> 225 | T3: =TEKNİK!F3 -> 0.8 | U3: =TEKNİK!E3 -> 2006 | V3: =TEKNİK!I3 -> Manuel Sol | W3: =TEKNİK!G3 -> 800 | X3: =TEKNİK!J3 -> Sol | Y3: =TEKNİK!K3 -> 70 x 65 x 9 | Z3: =TEKNİK!N3 -> Otomatik Merkezi | AA3: =TABLOLAR!A33 -> 6.5
A4: DOSYA BİLGİLERİ | E4: GÜVENLİK EKİPMANLARI GİRİŞİ | J4: ŞABLON KULLANIM NOTLARI (sürüm v6) | S4: =TEKNİK!A4 -> 300 | T4: =TEKNİK!F4 -> 1 | U4: =TEKNİK!E4 -> 2007 | V4: =TEKNİK!I4 -> Otomatik Merkezi | W4: =TEKNİK!G4 -> 900 | X4: =TEKNİK!J4 -> Arka | Y4: =TEKNİK!K4 -> 89 x 62 x 15,88 | Z4: =TEKNİK!N4 -> Teleskopik Sağ | AA4: =TABLOLAR!A34 -> 7
A5: DOSYA NO | J5: 1) Proje kimlik alanları (firma, adres, iletişim, yetkili, dosya no, asansör adresi, ada, parsel, seri no, imal yılı, motor marka ve seri no) BOŞALTILMIŞTIR. | S5: =TEKNİK!A5 -> 320 | T5: =TEKNİK!F5 -> 1.2 | U5: =TEKNİK!E5 -> 2008 | V5: =TEKNİK!I5 -> Teleskopik Sağ | W5: =TEKNİK!G5 -> 1000 | Y5: =TEKNİK!K5 -> 90 x 75 x 16 | Z5: =TEKNİK!N5 -> Teleskopik Sol | AA5: =TABLOLAR!A35 -> 8
A6: FİRMA ANTETİ | J6: 2) Mühendislik girdileri örnek değerlerle BIRAKILMIŞTIR - boş bırakılırsa formüller hata verir. Her projede 59-133. satırların tamamını gözden geçirin. | S6: =TEKNİK!A6 -> 375 | T6: =TEKNİK!F6 -> 1.6 | U6: =TEKNİK!E6 -> 2009 | V6: =TEKNİK!I6 -> Teleskopik Sol | W6: =TEKNİK!G6 -> 1100 | Y6: =TEKNİK!K6 -> 125 x 82 x 16 | AA6: =TABLOLAR!A36 -> 9
E7: KİLİTLER | J7: 3) DİKKAT - G36 hücresi 'FREN BLOKLARI / MARKASI' etiketinin yanındadır ama aslında GÜVENLİK TERTİBATI TİPİ girdisidir; k1 darbe katsayısını belirler. | S7: =TEKNİK!A7 -> 400 | T7: =TEKNİK!F7 -> 2 | U7: =TEKNİK!E7 -> 2010 | W7: =TEKNİK!G7 -> 1200 | Y7: =TEKNİK!K7 -> 127 x 89 x 16 | AA7: =TABLOLAR!A37 -> 10
A8: TARİH | E8: MARKASI | J8: Sadece şu üçünden biri yazılabilir: Kaymalı / Ani Frenlemeli Makaralı / Ani Frenlemeli. Marka adı yazılırsa ray hesabı #N/A verir. | S8: =TEKNİK!A8 -> 450 | T8: =TEKNİK!F8 -> 2.5 | U8: =TEKNİK!E8 -> 2011 | W8: =TEKNİK!G8 -> 1300 | AA8: =TABLOLAR!A38 -> 11
E9: MODELİ | J9: 4) F127 (Kabin Kapısı Ağırlığı) ve F128 (Mekanizma Payı) kapı modeline bağlıdır, projeye değil. Kapı üreticinizin kataloğundan bir kez girip sabit tutun. | S9: =TEKNİK!A9 -> 525 | T9: =TEKNİK!F9 -> 3 | U9: =TEKNİK!E9 -> 2012 | W9: =TEKNİK!G9 -> 1400 | AA9: =TABLOLAR!A39 -> 12
A10: FİRMA BİLGİLERİ | E10: KAT NO | G10: YÜK.(mm) | J10: 5) B133 (Acil Frenleme a) GEÇİCİ bir kabuldür ve mukavemet hesabına girer. Makine/fren verisi geldiğinde MUTLAKA güncelleyin. | S10: =TEKNİK!A10 -> 600 | T10: =TEKNİK!F10 -> 4 | U10: =TEKNİK!E10 -> 2013 | AA10: =TABLOLAR!A40 -> 13
J11: 6) TEKNİK sayfası U:AE sütunlarındaki marka ve sertifika listeleri BOŞTUR. Doldurulmadan sertifika alanları dolmaz. | S11: =TEKNİK!A11 -> 630 | T11: =TEKNİK!F11 -> 5 | U11: =TEKNİK!E11 -> 2014 | AA11: =TABLOLAR!A41 -> 14
A12: ASANSÖR MONTE EDEN | E12: 1.DURAK | G12: 3000 | I12: 2000 | J12: KAPSAM SINIRLARI VE AÇIK KALEMLER | S12: =TEKNİK!A12 -> 675 | T12: =TEKNİK!F12 -> 6 | U12: =TEKNİK!E12 -> 2015 | AA12: =TABLOLAR!A42 -> 15
A13: ADRES | E13: 2.DURAK | G13: 3000 | I13: 2100 | J13: 7) Yalnızca TAHRİKLİ (halatlı) asansörler içindir. Hidrolik asansör hesabı yoktur. | S13: =TEKNİK!A13 -> 750 | T13: =TEKNİK!F14 -> 0 | U13: =TEKNİK!E13 -> 2016 | AA13: =TABLOLAR!A43 -> 16
E14: 3.DURAK | G14: 3000 | I14: 2200 | J14: 8) Karşı ağırlık rayları yalnızca 'normal çalışma' yük durumu için hesaplanır. Referans hesapta ayrıca 'karşı ağırlık zıplaması' ve 'emniyet fren | S14: =TEKNİK!A14 -> 800 | T14: =TEKNİK!F15 -> 0 | U14: =TEKNİK!E14 -> 2017
A15: İLETİŞİM NO | E15: 4.DURAK | G15: 3000 | I15: 2300 | J15: çalışması' durumları da vardır - bu dosyada YOKTUR. Karşı ağırlıkta güvenlik tertibatı varsa bu dosya YETERSİZDİR. | S15: =TEKNİK!A15 -> 825 | T15: =TEKNİK!F16 -> 0 | U15: =TEKNİK!E15 -> 2018
A16: YETKİLİ/UNVAN | E16: 5.DURAK | G16: 3000 | I16: Regülatör Halat Çapları | J16: 9) Makine Konstrüksiyonu bölümü makine dairesi kaidesi içindir; makine dairesiz (MRL) tesisatta konsol/şase hesabı ayrıca yapılmalıdır. | S16: =TEKNİK!A16 -> 900 | T16: =TEKNİK!F17 -> 0 | U16: =TEKNİK!E16 -> 2019
E17: 6.DURAK | G17: 3000 | I17: 6 | J17: 10) Ray boynu eğilmesi KAYMALI paten formülüyle hesaplanır ve paydasındaki paten uzunluğu terimi doğrulanamamıştır. Makaralı paten kullanılıyorsa | S17: =TEKNİK!A17 -> 975 | T17: =TEKNİK!F18 -> 0 | U17: =TEKNİK!E17 -> 2020
E18: 7.DURAK | G18: 3000 | I18: 6.5 | J18: formül farklıdır (sigmaF = 1,85 x Fx / c^2). Paten tipini teyit edin. | S18: =TEKNİK!A18 -> 1000 | U18: =TEKNİK!E18 -> 2021
E19: 8.DURAK | G19: 3750 | I19: 8 | J19: 11) Dosyada bulunmayan hesaplar: tampon strok/seçimi, güvenlik tertibatı seçimi, fren momenti, kabin şasesi, ray konsolu ve dübel, kabin ve imdat | S19: 1125 | U19: =TEKNİK!E19 -> 2022
E20: 9.DURAK | J20: aydınlatması, kısa devre, havalandırma, halat spesifik basıncı (p <= pmax). | S20: 1200 | U20: =TEKNİK!E20 -> 2023
A21: PROJE BİLGİLERİ | E21: 10.DURAK | J21: 12) TAKİP: kuyu dibi sığınma hacmi yüksekliğinde marj yalnızca 10 mm'dir. Tampon babası / strok / kuyu dibi kotu değişirse yeniden kontrol edin. | S21: 1275 | U21: =TEKNİK!E21 -> 2024
A22: DOSYA NUMARASI | E22: 11.DURAK | S22: 1600 | U22: =TEKNİK!E22 -> 2025
A23: ASANSÖR ADRESİ | E23: 12.DURAK | J23: ="DOLDURULMAMIŞ PROJE ALANI: "&(COUNTBLANK(C12)+COUNTBLANK(C13)+COUNTBLANK(C15)+COUNTBLANK(C16)+COUNTBLANK(C22)+COUNTBLANK(C23)+COUNTBLANK(C26)+COUNTBLANK(C28)+COUNTBLANK(C57)+COUNTBLANK(C62)+COUNTBLANK(F94)+COUNTBLANK(F96))&" / 12" -> DOLDURULMAMIŞ PROJE ALANI: 11 / 12 | S23: 2000 | U23: =TEKNİK!E23 -> 2026
U24: =TEKNİK!E24 -> 2027
J25: GİRDİ SINIR KONTROLÜ — bu satırlar '!' gösteriyorsa hesapta #N/A çıkar | U25: =TEKNİK!E25 -> 2028
A26: ADA | E26: 13.DURAK | J26: =IF('11-Muk. Hesapları'!AV355>250,"! Kabin rayı narinliği λ="&'11-Muk. Hesapları'!AV355&" > 250. ω çizelgesi 20-250 arasıdır; konsol aralığını (B111) azaltın ya da daha büyük ray seçin.","OK Kabin rayı narinliği λ="&'11-Muk. Hesapları'!AV355&" (sınır 250)") -> OK Kabin rayı narinliği λ=155 (sınır 250) | U26: =TEKNİK!E26 -> 2029
J27: =IF(ISNA(MATCH(C59,TABLOLAR!$F$4:$V$4,0)),"! Beyan yükü "&C59&" kg trafik çizelgesinde yok (çizelge: 180-1000 kg). Trafik hesabı #N/A verir; mukavemet etkilenmez.","OK Beyan yükü trafik çizelgesinde var") -> OK Beyan yükü trafik çizelgesinde var
A28: PARSEL | E28: 14.DURAK | J28: =IF(OR(B129<2,B129>24),"! Ana giriş üstü durak adedi "&B129&" — çizelge 2-24 arasıdır. Trafik hesabı #N/A verir; mukavemet etkilenmez.","OK Ana giriş üstü durak adedi çizelgede") -> OK Ana giriş üstü durak adedi çizelgede
E29: 15.DURAK | J29: =IF(ISNA(MATCH(C66,TABLOLAR!$AT$4:$AX$4,0)),"! Kat kapısı tipi '"&C66&"' trafik çizelgesinde yok (Otomatik Merkezi / Teleskopik Sağ / Teleskopik Sol). Trafik hesabı #N/A verir.","OK Kat kapısı tipi çizelgede") -> OK Kat kapısı tipi çizelgede
E30: 16.DURAK | J30: =IF(ISNA(MATCH(E73,TABLOLAR!$I$60:$I$65,0)),"! Kabin rayı tipi ray çizelgesinde yok.","OK Kabin rayı çizelgede") -> OK Kabin rayı çizelgede
E31: 17.DURAK | J31: =IF(ISNA(MATCH(F73,TABLOLAR!$I$60:$I$65,0)),"! Ağırlık rayı tipi ray çizelgesinde yok.","OK Ağırlık rayı çizelgede") -> OK Ağırlık rayı çizelgede
E32: 18.DURAK | J32: =IF(ISNA(MATCH(G36,TABLOLAR!$H$32:$H$34,0)),"! G36 güvenlik tertibatı tipi geçersiz. Sadece: Kaymalı / Ani Frenlemeli Makaralı / Ani Frenlemeli","OK Güvenlik tertibatı tipi geçerli (k1 okunuyor)") -> OK Güvenlik tertibatı tipi geçerli (k1 okunuyor)
E33: 19.DURAK | J33: =IF(ISNA(MATCH(B99,TABLOLAR!$A$32:$A$43,0)),"! Askı halatı çapı "&B99&" mm halat çizelgesinde yok (6-16 mm).","OK Askı halatı çapı çizelgede") -> OK Askı halatı çapı çizelgede
E34: 20.DURAK | J34: =IF(ISNA(MATCH(B131,TEKNİK!$P$2:$P$4,0)),"! Ray çeliği Rm "&B131&" çizelgede yok (370 / 440 / 520).","OK Ray çeliği Rm çizelgede") -> OK Ray çeliği Rm çizelgede
E35: FREN BLOKLARI | J35: ="TOPLAM UYARI: "&(IF(LEFT(J26,1)="!",1,0)+IF(LEFT(J27,1)="!",1,0)+IF(LEFT(J28,1)="!",1,0)+IF(LEFT(J29,1)="!",1,0)+IF(LEFT(J30,1)="!",1,0)+IF(LEFT(J31,1)="!",1,0)+IF(LEFT(J32,1)="!",1,0)+IF(LEFT(J33,1)="!",1,0)+IF(LEFT(J34,1)="!",1,0))&" / 9" -> TOPLAM UYARI: 0 / 9
E36: MARKASI | G36: Kaymalı
E38: MODELİ
M39: =TEKNİK!I2 -> Manuel Sağ | N39: =TEKNİK!I3 -> Manuel Sol | O39: =TEKNİK!I4 -> Otomatik Merkezi | P39: =TEKNİK!I5 -> Teleskopik Sağ | Q39: =TEKNİK!I6 -> Teleskopik Sol
M40: 12 x 0,75 | N40: 12 x 0,75 | O40: 24 x 0,75 | P40: 24 x 0,75 | Q40: 24 x 0,75
U41: Yükleme | V41: Fren | W41: Bloke | X41: Barit | Y41: Kauçuk | Z41: 700
...

Sheet 10-Trafik Hesap
A1: ASANSÖR TRAFİK HESABI
A4: Binada bulunan insan sayısının hesabı (B) :
A6: B = b + (η . b ) | Z6: B | AA6: = | AB6: =PRODUCT(AB8,SUM(S17,1)) -> 26 | AE6: Kişi
A7: b = Σc
A8: b :Binada Bulunan Toplam İnsan Sayısı | Z8: b | AA8: = | AB8: =PRODUCT(AB13,SUM(AB14,AB15)) -> 20 | AE8: Kişi
A10: c :Bir Bağımsız Bölümde Sürekli Bulunan İnsan Sayısı | AC10: =SUM(AB14,AB15) -> 5 | AE10: Kişi
A12: Katta bulunan daire sayısı | R12: = | S12: ='Veri Girişi'!B93 -> 1
A13: Toplam Daire sayısı | R13: = | S13: =S12*'Veri Girişi'!B94 -> 4 | AB13: =S13 -> 4
A14: Yatak Odası Sayısı | M14: (Tablo 1) | R14: = | S14: =VLOOKUP('Veri Girişi'!B95,TABLOLAR!A5:C12,3,0) -> 2 | AB14: =PRODUCT(S14,2) -> 4
A15: Diğer Oda Sayısı | M15: (Tablo 1) | R15: = | S15: =IF('Veri Girişi'!B95="KONUT",1,0) -> 1 | AB15: =PRODUCT(S15,1) -> 1
A17: η : Yedek Artış Oranı | P17: η | R17: = | S17: =IF(AB8<200,0.3,0.25) -> 0.3
A18: b<200 kişi η = %30
A19: b>200 kişi η = %25
A21: Asansörün bir seferi için gerekli seyir zamanı ( TR ):
A23: TR = 2.H.tv + (S + 1).ts + 2.P.tp | AA23: TR | AC23: = | AE23: =2*AE24*AE25+(AE26+1)*AE27+2*AE28*AE29 -> 135.88 | AI23: s
A24: H | C24: Ortalama en yüksek dönüş katı | Z24: (Tablo3) | AE24: =HLOOKUP('Veri Girişi'!C59,TABLOLAR!F4:X5,2,0) -> 5.7
A25: tv | C25: Katlar arası geçiş zamanı | AE25: =M35 -> 3 | AI25: s
A26: S | C26: Ortalama durak adedi | Z26: (Tablo 5) | AE26: =HLOOKUP('Veri Girişi'!C59,TABLOLAR!Z4:AR5,2,0) -> 4.6
A27: ts | C27: Kabinin her duruştaki zaman kaybı | AE27: =N41 -> 10.3 | AI27: s
A28: P | C28: Kabindeki kişi adedi | AE28: ='Veri Girişi'!C60 -> 10 | AI28: Kişi
A29: tp | C29: Kişi transfer zamanı | Z29: (Tablo 8) | AE29: =IF('Veri Girişi'!C71<1000,2.2,2) -> 2.2 | AI29: s
A30: Sm | C30: Seyir Mesafesi | AE30: ='Veri Girişi'!C63 -> 21 | AI30: m
A31: D | C31: Ana giriş üstü durak adedi | AE31: ='Veri Girişi'!B129 -> 6
A32: h | C32: Katlar arası mesafe | AE32: =AE30/('Veri Girişi'!C65-1) -> 3 | AI32: m
A33: v | C33: Kabin Hızı | AE33: ='Veri Girişi'!C61 -> 1 | AI33: m/s
A35: tv | B35: = | C35: h / v | J35: tv | L35: = | M35: =AE32/AE33 -> 3 | P35: s
A37: ta | B37: : | C37: Kapı açılma zamanı | Z37: (Tablo 4) | AE37: =HLOOKUP('Veri Girişi'!C66,TABLOLAR!AT4:AX5,2,0) -> 2.5 | AI37: s
A38: tk | B38: : | C38: Kapı kapanma zamanı | Z38: (Tablo 4) | AE38: =HLOOKUP('Veri Girişi'!C66,TABLOLAR!AT17:AX18,2,0) -> 3.8 | AI38: s
A39: tg | B39: : | C39: Tek katı geçme zamanı | Z39: (Tablo 6) | AE39: =IF('Veri Girişi'!C61<1,10,VLOOKUP('Veri Girişi'!C61,TABLOLAR!AX5:AY11,2,0)) -> 7 | AI39: s
A41: ts | B41: = | C41: ta | D41: + | E41: tk | F41: + | G41: tg | H41: - | I41: tv | L41: ts | M41: = | N41: =AE37+AE38+AE39-M35 -> 10.3 | Q41: s
A43: Gerekli asansör sayısının hesabı (L) :
A45: Binada 5 dakikada taşınacak insan sayısı ( R ) ;
A46: R | B46: = | C46: 5.60.(0,8.P) / TR | AA46: R | AB46: = | AE46: =5*60*0.8*AE28/AE23 -> 17.662644 | AI46: Kişi
A48: L | B48: = | C48: B.k / R | AA48: L | AB48: = | AE48: =AB6*AE50/AE46/100 -> 0.1104025 | AI48: Adet
A50: k | B50: : | C50: Taşınacak insan yüzdesi | Z50: (Tablo 9) | AE50: =IF('Veri Girişi'!C65<11,7.5,10) -> 7.5 | AI50: %
A52: Binada gerekli asansör sayısı; | P52: =ROUNDUP(AE48,0) -> 1 | R52: 'dir. | AZ52: Sf 1/1
A54: Binada mevcut asansör adedi; | P54: 1
A56: Mevcut asansör adedi ≥ Gerekli asansör adedi olduğundan; | P56: =IF(P54>=P52,"UYGUNDUR.","UYGUN DEĞİLDİR.") -> UYGUNDUR.

Sheet 11-Muk. Hesapları
A1: ASANSÖR MUKAVEMET HESAPLARI
A4: Asansör Motor Gücünün Hesaplanması (MMO 208/7- 2.4)
A6: v | C6: Kabin Hızı | AQ6: ='Veri Girişi'!C61 -> 1 | AU6: m/s
A7: Pm | C7: Makine miline gelen en büyük döndürme kuvveti | AE7: Pm | AG7: = | AH7: F1 | AI7: - | AJ7: Ga | AQ7: =AQ11-AQ13 -> 451.47632 | AU7: kg.
A8: Gs | C8: Sürtünme Yükü | AQ8: 0 | AU8: kg.
A9: Gmax | C9: Maksimum artan yük | AE9: Gmax | AH9: = | AI9: F1 | AJ9: + | AK9: Gs | AL9: - | AM9: Ga | AQ9: =AQ11+AQ8-AQ13 -> 451.47632 | AU9: kg.
A10: Dt | C10: Tahrik kasnak çapı | AQ10: ='Veri Girişi'!F99 -> 240 | AU10: mm.
A11: F1 | C11: Kabin ve aksesuarlarının yükü | AE11: F1 | AG11: = | AH11: P | AI11: + | AJ11: Q | AK11: + | AL11: Gh | AQ11: =AQ14+AQ15+AQ16 -> 1551.4763 | AU11: kg.
A13: Ga | C13: Karşı ağırlık yükü | AE13: Ga | AG13: = | AH13: P | AI13: + | AJ13: 1/2 | AL13: Q | AQ13: =AQ15+(0.5*AQ14) -> 1100 | AU13: kg.
A14: Q | C14: Beyan yükü | AQ14: ='Veri Girişi'!C59 -> 800 | AU14: kg.
A15: P | C15: Boş Kabin Ağırlığı | AQ15: ='Veri Girişi'!C75 -> 700 | AU15: kg.
A16: Gh | C16: Toplam halat ağırlığı | AE16: Gh | AG16: = | AH16: gh | AI16: x | AJ16: lh | AK16: x | AL16: nh | AQ16: =AQ18*AQ19*AQ20 -> 51.47632 | AU16: kg.
A17: dh | C17: Halat çapı | AQ17: ='Veri Girişi'!B99 -> 6.5 | AU17: mm.
A18: gh | C18: Halatın 1 m deki ağırlığı | N18: (TS 12385-5 / 8x19 Lif Özlü) | AQ18: =VLOOKUP('Veri Girişi'!B99,TABLOLAR!A32:C43,2,0) -> 0.152 | AU18: kg.
A19: lh | C19: Halat uzunluğu | AQ19: =IF('Veri Girişi'!B100=1,((('Veri Girişi'!F80-('Veri Girişi'!F119+'Veri Girişi'!B125-'Veri Girişi'!B124+'Veri Girişi'!B128+'Veri Girişi'!B127))/1000)+5),(((('Veri Girişi'!F80-('Veri Girişi'!F119+'Veri Girişi'!B125-'Veri Girişi'!B124+'Veri Girişi'!B128+'Veri Girişi'!B127))/1000)+5)*2)) -> 48.38 | AU19: m.
A20: nh | C20: Halat sayısı | AQ20: ='Veri Girişi'!B98 -> 7 | AU20: adet
A21: M | C21: Moment değeri | AE21: M | AG21: = | AH21: Gmax | AK21: x ( | AL21: Dt | AM21: / 2 ) | AQ21: =AQ9*(AQ10/2000) -> 54.177158 | AU21: kg.m
A22: η | C22: Motor verimi | AQ22: 0.92
A23: N | C23: Hesaplanan asansör motor gücü | AE23: N | AF23: = | AG23: Gmax x V / (η x 102) | AQ23: =AQ9*AQ6/(AQ22*102) -> 4.8111287 | AU23: kW
A25: Binada gerekli asansör için | M25: en az | Q25: =AQ23 -> 4.8111287 | U25: KW, | X25: =Q25*1.34 -> 6.4469125 | AA25: HP gücünde makine motor kullanılacaktır.
A27: Kullanılan motorun gücü | M27: ='Veri Girişi'!F95 -> 4.9 | P27: kW | S27: ≥ | U27: =Q25 -> 4.8111287 | X27: kW | AA27: olduğundan; | AH27: =IF(M27>=U27,"UYGUNDUR.","UYGUN DEĞİLDİR.") -> UYGUNDUR.
AS28: <
A29: Makine Konstrüksiyonunun Hesaplanması (MMO 208/4- m.3.4.6)
A31: k1 | C31: : | D31: Darbe katsayısı (TS EN 81-20 Çizelge 14) | AB31: =VLOOKUP('Veri Girişi'!G36,TABLOLAR!H32:K35,4,0) -> 2
A32: Gm | C32: : | D32: Makine motor ağırlığı | O32: (Üretici kataloğudan) | AB32: ='Veri Girişi'!F126 -> 300 | AG32: kg
A33: L | C33: : | D33: Yan yatak boyu | AB33: ='Veri Girişi'!F104 -> 1400 | AG33: mm
D34: Yan yatak malzemesi | AB34: ='Veri Girişi'!G103 -> NPU | AE34: ='Veri Girişi'!F103 -> 120
A35: L1 | C35: : | D35: Dikine kirişin boyu | AB35: ='Veri Girişi'!F101 -> 1100 | AG35: mm
D36: Dikine kiriş malzemesi | AB36: ='Veri Girişi'!G102 -> NPU | AE36: ='Veri Girişi'!F102 -> 120
A37: A | C37: : | D37: Dikine kirişin kesit alanı | AB37: =VLOOKUP($AE$36,TABLOLAR!M36:AH53,10,0)*100 -> 1700 | AG37: mm2
A38: Imin | C38: : | D38: Dikine kirişin eylemsizlik momenti | AB38: =VLOOKUP($AE$36,TABLOLAR!M36:AH53,14,0)*10 -> 46.2 | AG38: mm
A39: ω | C39: : | D39: Omega değeri | AB39: =VLOOKUP(Z71,TABLOLAR!A47:B177,2,0) -> 1.05
A40: σem | C40: : | D40: Emniyet Gerilmesi (ST 37 için) | AB40: 130 | AG40: N/mm2
A41: Wx | C41: : | D41: Yatay kirişin mukavemet momenti | AB41: =VLOOKUP($AE$34,TABLOLAR!M36:AH53,13,0)*1000 -> 60700 | AG41: mm3
A43: Kaide üzerindeki en büyük kuvvet :
A45: F = k1 * gn * (Q + P + Gh + Ga + Gm ) = | S45: =AB31 -> 2 | U45: * | V45: =9.81 -> 9.81 | Y45: * | Z45: ( | AA45: =AQ14 -> 800 | AD45: + | AE45: =AQ15 -> 700 | AH45: + | AI45: =AQ16 -> 51.47632 | AL45: + | AM45: =AQ13 -> 1100 | AP45: + | AQ45: =AB32 -> 300 | AT45: )
A47: F | B47: = | C47: =(S45*V45*(AA45+AE45+AI45+AM45+AQ45)) -> 57907.965 | H47: N
A49: Yan yatak putreline gelen kuvvet :
A51: F1 | C51: = | E51: F / 2 | H51: = | I51: =C47/2 -> 28953.983 | N51: N
A53: F1 | C53: . | D53: X | E53: = | F53: FB | H53: . | I53: L | L53: FB | N53: = | O53: =I51*K58/AB33 -> 22025.708 | T53: N | X53: FA | Z53: = | AA53: F1 | AC53: - | AD53: FB | AH53: FA | AJ53: = | AK53: =I51-O53 -> 6928.2744 | AO53: N
...

Sheet 12-Elk.Hesapları
A1: ASANSÖR ELEKTRİK HESAPLARI
B3: ASANSÖR YÜKLEME CETVELİ
B4: TABLO ADI | F4: TABLO GÜCÜ (W) | J4: SİGORTA | N4: K.A.K.R | R4: LİNYE NO | U4: SİGORTA | AA4: SORTİ SAYISI | AP4: KABLO KESİTİ (mm2) | AT4: GÜÇ (W) | AY4: AÇIKLAMA
U6: TİP | X6: A | AA6: AYDINLATMA | AF6: MOTOR | AK6: PRİZ
B7: TAS | F7: =AT14 -> 7208.7059 | J7: 3X25 A | N7: 25A, 30mA | R7: 1 | U7: B | X7: 25 | AF7: 1 | AP7: 4 x 4 | AT7: =W36*1000 -> 5764.7059 | AY7: ASANSÖR MOTORU
R8: 2 | U8: B | X8: 16 | AK8: 1 | AP8: 3 x 2,5 | AT8: =AK8*300 -> 300 | AY8: MAKİNA DAİRESİ PRİZ
AK9: 1 | AP9: 3 x 2,5 | AT9: =AK9*300 -> 300 | AY9: KUYU DİBİ PRİZ
AK10: 2 | AP10: 3 x 2,5 | AT10: =AK10*300 -> 600 | AY10: KABİN ÜSTÜ PRİZ
R11: 3 | U11: B | X11: 10 | AA11: =M170 -> 7 | AP11: 2 x 1,5 | AT11: =AA11*R170 -> 84 | AY11: KUYU AYDINLATMA
R12: 4 | U12: B | X12: 10 | AA12: =M211 -> 3 | AP12: 2 x 1,5 | AT12: =AA12*R211 -> 120 | AY12: MAKİNA DAİRESİ AYDINLATMA
R13: 5 | U13: B | X13: 10 | AA13: 1 | AP13: 2 x 1,5 | AT13: =AA13*40 -> 40 | AY13: KABİN AYDINLATMA
R14: - | U14: - | X14: - | AA14: =SUM(AA7:AE13) -> 11 | AF14: =SUM(AF7:AJ13) -> 1 | AK14: =SUM(AK7:AO13) -> 4 | AP14: - | AT14: =SUM(AT7:AX13) -> 7208.7059 | AY14: TABLO CÜGÜ
A16: 1. Asansör Motoru Gerilim Düşümü Hesabı
O18: AT | AF18: TAS | AH18: = | AI18: =W31 -> 7.2087059 | AL18: kW | AU18: Pm | AW18: = | AX18: =W30 -> 4.9 | BA18: kW
S20: 4 | U20: x | V20: =W33 -> 6 | X20: mm2 | AA20: NYM | AI20: 4 | AK20: x | AL20: =W34 -> 4 | AN20: mm2 | AQ20: NYY
A21: ŞEBEKE
T23: L1 | V23: = | W23: =W26 -> 33.85 | AA23: m | AJ23: L2 | AL23: = | AM23: =W27 -> 5 | AQ23: m
A26: L1 | C26: : | D26: AT ile TAS Arası Hat Uzunluğu | W26: =('Veri Girişi'!C63+('Veri Girişi'!F114+'Veri Girişi'!B132)/1000)+7.5 -> 33.85 | AB26: m.
A27: L2 | C27: : | D27: TAS ile Pm Arası Hat Uzunluğu | W27: 5 | AB27: m.
A28: U | C28: : | D28: Şebeke Gerilimi | W28: 400 | AB28: V
A29: e | C29: : | D29: Yüzde Gerilim Düşümü | W29: 3 | AB29: %
A30: Pm | C30: : | D30: Asansör Motor Gücü | W30: ='Veri Girişi'!F95 -> 4.9 | AB30: kW
A31: PTAS | C31: : | D31: Kolon Hattı için Gerekli olan Güç | W31: =AT14/1000 -> 7.2087059 | AB31: kW
A32: K | C32: : | D32: Özgül İletkenlik Katsayısı (Cu) | W32: 56 | AB32: Ω.mm²
A33: S1 | C33: : | D33: AT-TAS Arası Kullanılan Kablo Kesiti | W33: 6 | AB33: mm²
A34: S2 | C34: : | D34: TAS - Motor Arası Kullanılan Kablo Kesiti | W34: 4 | AB34: mm²
A35: ηm | C35: : | D35: Motor verimi (şebekeden çekilen güç için) | W35: 0.85 | AB35: -
A36: Pşeb | C36: : | D36: Motorun şebekeden çektiği güç | W36: =W30/W35 -> 5.7647059 | AB36: kW
A37: AT-TAS Arası % Gerilim Düşümü:
C39: e1 | D39: = | E39: 100 x L1 x P | N39: e1 | O39: = | P39: 100 | R39: x | S39: =W26 -> 33.85 | V39: x | W39: =W31*1000 -> 7208.7059 | AC39: e1 | AD39: = | AE39: =P39*S39*W39/P40/T40/Y40 -> 0.45389638
E40: K x U2 x S1 | P40: =W32 -> 56 | S40: x | T40: =W28*W28 -> 160000 | X40: x | Y40: =W33 -> 6
A42: e | B42: ≥ | C42: e1 | E42: ; | F42: =W29 -> 3 | I42: ≥ | J42: =AE39 -> 0.45389638 | M42: olduğundan; seçilen kablo kesiti | AB42: =W33 -> 6 | AE42: mm² | AH42: =IF(F42>=J42,"UYGUNDUR.","UYGUN DEĞİLDİR.") -> UYGUNDUR.
A44: TAS - Asansör Motoru Arası % Gerilim Düşümü:
C46: e2 | D46: = | E46: 100 x L2 x Pm | N46: e1 | O46: = | P46: 100 | R46: x | S46: =W27 -> 5 | V46: x | W46: =W36*1000 -> 5764.7059 | AC46: e2 | AD46: = | AE46: =P46*S46*W46/P47/T47/Y47 -> 0.080422794
E47: K x U2 x S2 | P47: =W32 -> 56 | S47: x | T47: =W28*W28 -> 160000 | X47: x | Y47: =W34 -> 4
A49: e | B49: ≥ | C49: e1 | E49: ; | F49: =W29 -> 3 | I49: ≥ | J49: =AE46 -> 0.080422794 | M49: olduğundan; seçilen kablo kesiti | AB49: =W34 -> 4 | AE49: mm² | AH49: =IF(F49>=J49,"UYGUNDUR.","UYGUN DEĞİLDİR.") -> UYGUNDUR.
A51: Toplam Gerilim Düşümü:
A53: eT | C53: = | D53: e1 | F53: + | G53: e2 | K53: eT | M53: = | N53: =AE39 -> 0.45389638 | Q53: + | R53: =AE46 -> 0.080422794 | V53: eT | X53: = | Y53: =N53+R53 -> 0.53431917 | AC53: e | AD53: ≥ | AE53: eT | AG53: ; | AH53: =W29 -> 3 | AI53: ≥ | AJ53: =Y53 -> 0.53431917 | AM53: olduğundan; | AS53: =IF(AH53>=AJ53,"UYGUNDUR.","UYGUN DEĞİLDİR.") -> UYGUNDUR.
A55: Akım Kontrolü:
A57: I | C57: = | D57: P | M57: I | O57: = | P57: =W31*1000 -> 7208.7059 | AB57: I | AD57: = | AE57: =P57/P58/T58/X58 -> 13.006088 | AH57: A
...

Sheet RAPOR
B2: ELEKTRİKLİ ASANSÖR MUKAVEMET HESABI DOĞRULAMA RAPORU
B3: KONTEST HİZMET NUMARASI | E3: : | F3: =IF('Veri Girişi'!C22="","",'Veri Girişi'!C22) | H3: ASANSÖR SERİ NO | J3: : | K3: =IF('Veri Girişi'!C57="","",'Veri Girişi'!C57) | M3: ADA/PARSEL | O3: : | P3: =IF('Veri Girişi'!C26="","",'Veri Girişi'!C26) | Q3: =IF('Veri Girişi'!C28="","",'Veri Girişi'!C28)
B4: MONTAJ ADRESİ | E4: : | F4: =IF('Veri Girişi'!C23="","",'Veri Girişi'!C23)
B5: ASANSÖR MONTE EDEN | E5: : | F5: =IF('Veri Girişi'!C12="","",'Veri Girişi'!C12)
B7: N : Asansör motor gücü | H7: ='11-Muk. Hesapları'!AH27 -> UYGUNDUR. | K7: Güvenlik Tertibatının Çalışması :
K8: σc : Birleşik gerilme - Durum 1 x-ekseni | P8: ='11-Muk. Hesapları'!AV365 -> UYGUNDUR.
B9: σe : Kaide yatay kirişlerinde eğilme momenti ve gerilmesi | H9: ='11-Muk. Hesapları'!AH67 -> UYGUNDUR. | K9: σc : Birleşik gerilme - Durum 2 y-ekseni | P9: ='11-Muk. Hesapları'!AV374 -> UYGUNDUR.
B10: σb : Dikine kirişlerin bükülme kontrolü | H10: ='11-Muk. Hesapları'!AH75 -> UYGUNDUR. | K10: σF : Ray boynu eğilmesi - Durum 1 x-ekseni | P10: ='11-Muk. Hesapları'!AL379 -> UYGUNDUR.
K11: σF : Ray boynu eğilmesi - Durum 2 y-ekseni | P11: ='11-Muk. Hesapları'!AL384 -> UYGUNDUR.
B12: Kullanılabilir en büyük kabin alanı | H12: ='11-Muk. Hesapları'!AP84 -> UYGUNDUR. | K12: dx : Eğilme Miktarı - Durum 1 x-ekseni | P12: ='11-Muk. Hesapları'!AQ393 -> UYGUNDUR.
B13: Kullanılabilir en küçük kabin alanı | H13: ='11-Muk. Hesapları'!AP90 -> UYGUNDUR. | K13: dy : Eğilme Miktarı - Durum 1 x-ekseni | P13: ='11-Muk. Hesapları'!AQ396 -> UYGUNDUR.
K14: dx : Eğilme Miktarı - Durum 2 x-ekseni | P14: ='11-Muk. Hesapları'!AQ401 -> UYGUNDUR.
B15: Regülatör kasnağı & halat oranı | H15: ='11-Muk. Hesapları'!X142 -> UYGUNDUR. | K15: dy : Eğilme Miktarı - Durum 2 y-ekseni | P15: ='11-Muk. Hesapları'!AQ404 -> UYGUNDUR.
B16: F'reg : Durdurma tertibatının çalışmasında oluşan gergi kuvveti | H16: ='11-Muk. Hesapları'!AM156 -> UYGUNDUR. | K16: Normal Kullanma, Yükleme :
B17: Regülatör halatı emniyet katsayısı | H17: ='11-Muk. Hesapları'!U161 -> UYGUNDUR. | K17: σ : Birleşik gerilme | P17: ='11-Muk. Hesapları'!AO532 -> UYGUNDUR.
K18: σF : Ray boynu eğilmesi | P18: ='11-Muk. Hesapları'!AL537 -> UYGUNDUR.
B19: Kabinin yüklenmesi (%125 yüklü kabin en alt durakta dururken) | H19: ='11-Muk. Hesapları'!Z242 -> UYGUNDUR. | K19: dx : Eğilme Miktarı | P19: ='11-Muk. Hesapları'!AQ542 -> UYGUNDUR.
B20: Durdurma tertibatının çalışması (%100 yüklü kabin en alt durakta) | H20: ='11-Muk. Hesapları'!Z257 -> UYGUNDUR. | K20: dy : Eğilme Miktarı | P20: ='11-Muk. Hesapları'!AQ545 -> UYGUNDUR.
B21: Durdurma tertibatının çalışması (Boş kabin en üst durakta) | H21: ='11-Muk. Hesapları'!Z271 -> UYGUNDUR.
B22: Kabinin bloke edilmesi (Ağırlık tampona oturduğunda boş kabin en üstte) | H22: ='11-Muk. Hesapları'!Z285 -> UYGUNDUR. | K22: Üst Güvenlik Boşluğu (5.7.1) :
K23: Üst paten - Rayın üst ucu arası | P23: ='11-Muk. Hesapları'!AS635 -> UYGUNDUR.
B24: Normal Kullanma, Hareket(Karşı Ağırlık) : | K24: Kabin üstü - Kuyu tavanının en alt kısmı arası | P24: ='11-Muk. Hesapları'!AS636 -> UYGUNDUR.
B25: σ : Birleşik gerilme | H25: ='11-Muk. Hesapları'!AO590 -> UYGUNDUR. | K25: Revizyon kutusu - Kuyu tavanının en alt kısmı arası | P25: ='11-Muk. Hesapları'!AS637 -> UYGUNDUR.
B26: σF : Ray boynu eğilmesi | H26: ='11-Muk. Hesapları'!AL595 -> UYGUNDUR. | K26: Paten/Halat Bağlantısı - Kuyu tavanının en alt kısmı arası | P26: ='11-Muk. Hesapları'!AS638 -> UYGUNDUR.
B27: dx : Eğilme Miktarı | H27: ='11-Muk. Hesapları'!AQ600 -> UYGUNDUR. | K27: Kabin üstündeki güvenlik boşluğu | P27: =IF('11-Muk. Hesapları'!AV639="U","UYGUNDUR.","UYGUN DEĞİLDİR.") -> UYGUNDUR.
B28: dy : Eğilme Miktarı | H28: ='11-Muk. Hesapları'!AQ603 -> UYGUNDUR. | K28: Karşı ağırlık üst pateni - Rayın üst ucu arası | P28: ='11-Muk. Hesapları'!AS640 -> UYGUNDUR.
B30: Alt Güvenlik Boşluğu (5.7.3) : | K30: Elektriksel Hesaplamalar
B31: Kuyu dibindeki güvenlik boşluğu | H31: =IF('11-Muk. Hesapları'!AS644="U","UYGUNDUR.","UYGUN DEĞİLDİR.") -> UYGUNDUR. | K31: Motor gerilim düşüm hesabı | P31: ='12-Elk.Hesapları'!AH65 -> UYGUNDUR.
B32: Kuyu tabanı - Kabinin en alt kısımları arası (Tam kapanmış tampon yüksekliği) | H32: ='11-Muk. Hesapları'!AS645 -> UYGUNDUR. | K32: Aydınlatma gerilim düşüm hesabı | P32: ='12-Elk.Hesapları'!AC101 -> UYGUNDUR.
B33: Kuyu tabanı - Kabin eteği arası | H33: ='11-Muk. Hesapları'!AS646 -> UYGUNDUR. | K33: Kuyu aydınlatma hesabı | P33: Bakınız Elk. Hesapları
B34: Kuyu tabanı - Kabin kapısı en alt kısmı arası | H34: ='11-Muk. Hesapları'!AS647 -> UYGUNDUR. | K34: Makine dairesi aydınlatma hesabı | P34: Bakınız Elk. Hesapları
B35: Regülatör alt makarası - Kabin en alt kısmı (süspansiyon) arası | H35: ='11-Muk. Hesapları'!AS648 -> UYGUNDUR.
B37: Askı Halatlarının Hesaplanması : | K37: Normal Kullanma, Hareket (Kabin Rayları) :
B38: Tahrik kasnağı & askı halatı oranı (Dt/dh) | H38: ='11-Muk. Hesapları'!Z97 -> UYGUNDUR. | K38: σ : Birleşik gerilme - Durum 1 x-ekseni | P38: ='11-Muk. Hesapları'!AO463 -> UYGUNDUR.
B39: Halat güvenlik katsayısı (Sf ≥ Smin) | H39: ='11-Muk. Hesapları'!AH125 -> UYGUNDUR. | K39: σ : Birleşik gerilme - Durum 2 y-ekseni | P39: ='11-Muk. Hesapları'!AS470 -> UYGUNDUR.
B40: Halat gerçek emniyet katsayısı (n.Tmin/Fmax) | H40: ='11-Muk. Hesapları'!AH126 -> UYGUNDUR. | K40: σF : Ray boynu eğilmesi - Durum 1 x-ekseni | P40: ='11-Muk. Hesapları'!AL476 -> UYGUNDUR.
K41: σF : Ray boynu eğilmesi - Durum 2 y-ekseni | P41: ='11-Muk. Hesapları'!AL481 -> UYGUNDUR.
B42: Trafik Hesabı (MMO 697) : | K42: dx : Eğilme Miktarı - Durum 1 x-ekseni | P42: ='11-Muk. Hesapları'!AQ487 -> UYGUNDUR.
B43: Gerekli asansör adedi kontrolü | H43: ='10-Trafik Hesap'!P56 -> UYGUNDUR. | K43: dy : Eğilme Miktarı - Durum 1 x-ekseni | P43: ='11-Muk. Hesapları'!AQ490 -> UYGUNDUR.
K44: dx : Eğilme Miktarı - Durum 2 y-ekseni | P44: ='11-Muk. Hesapları'!AQ495 -> UYGUNDUR.
...

Sheet TEKNİK
A1: BEYAN YÜKÜ | B1: KİŞİ | C1: KABİN AĞ. | D1: KARŞI A.AĞ. | E1: İMAL YILI | F1: BEYAN HIZI | G1: KAPI G. | H1: KAPI Y. | I1: GİRİŞLER | J1: KARŞI A. YERİ | K1: RAY ÖL. | L1: Max. Em. Ger. | M1: Min. Em. Ger. | N1: KABİN GİRİŞ | P1: Rm (N/mm2) | Q1: σperm normal | R1: σperm güv.tert. | S1: TS EN 81-20 Çizelge 21 | U1: FİRMA LİSTESİ | V1: KAPI KİLİDİ MARKALARI | W1: KUMANDA KARTI MARKALARI | X1: FREN BLOĞU MARKALARI | Y1: HIZ REGÜLATÖRÜ MARKALARI | AA1: TAMPON MARKALARI | AC1: TAMPON MODELİ | AD1: SERTİFİKA NO | AE1: VEREN KURUM | AG1: Bu tablolar BOŞ bırakılmıştır - marka/sertifika bilgilerini buraya girin.
A2: 180 | B2: 2 | C2: 350 | D2: =A2/2+C2 -> 440 | E2: 2005 | F2: 0.63 | G2: 700 | H2: 2000 | I2: Manuel Sağ | J2: Sağ | K2: 50 x 50 x 5 | L2: 205 | M2: 165 | N2: Kremayer | P2: 370 | Q2: 165 | R2: 205
A3: 225 | B3: 3 | C3: 400 | D3: =A3/2+C3 -> 512.5 | E3: 2006 | F3: 0.8 | G3: 800 | H3: 2000 | I3: Manuel Sol | J3: Sol | K3: 70 x 65 x 9 | L3: 205 | M3: 165 | N3: Otomatik Merkezi | P3: 440 | Q3: 195 | R3: 244
A4: 300 | B4: 4 | C4: 500 | D4: =A4/2+C4 -> 650 | E4: 2007 | F4: 1 | G4: 900 | H4: 2000 | I4: Otomatik Merkezi | J4: Arka | K4: 89 x 62 x 15,88 | L4: 205 | M4: 165 | N4: Teleskopik Sağ | P4: 520 | Q4: 230 | R4: 288
A5: 320 | B5: 4 | C5: 500 | D5: =A5/2+C5 -> 660 | E5: 2008 | F5: 1.2 | G5: 1000 | H5: 2000 | I5: Teleskopik Sağ | K5: 90 x 75 x 16 | L5: 205 | M5: 165 | N5: Teleskopik Sol
A6: 375 | B6: 5 | C6: 500 | D6: =A6/2+C6 -> 687.5 | E6: 2009 | F6: 1.6 | G6: 1100 | H6: 2100 | I6: Teleskopik Sol | K6: 125 x 82 x 16 | L6: 290 | M6: 230
A7: 400 | B7: 5 | C7: 500 | D7: =A7/2+C7 -> 700 | E7: 2010 | F7: 2 | G7: 1200 | H7: 2100 | K7: 127 x 89 x 16 | L7: 290 | M7: 230
A8: 450 | B8: 6 | C8: 600 | D8: =A8/2+C8 -> 825 | E8: 2011 | F8: 2.5 | G8: 1300 | H8: 2100
A9: 525 | B9: 7 | C9: 600 | D9: =A9/2+C9 -> 862.5 | E9: 2012 | F9: 3 | G9: 1400 | H9: 2100
A10: 600 | B10: 8 | C10: 650 | D10: =A10/2+C10 -> 950 | E10: 2013 | F10: 4
A11: 630 | B11: 8 | C11: 650 | D11: =A11/2+C11 -> 965 | E11: 2014 | F11: 5
A12: 675 | B12: 9 | C12: 700 | D12: =A12/2+C12 -> 1037.5 | E12: 2015 | F12: 6
A13: 750 | B13: 10 | C13: 700 | D13: =A13/2+C13 -> 1075 | E13: 2016
A14: 800 | B14: 10 | C14: 700 | D14: =A14/2+C14 -> 1100 | E14: 2017
A15: 825 | B15: 11 | C15: 750 | D15: =A15/2+C15 -> 1162.5 | E15: 2018
A16: 900 | B16: 12 | C16: 800 | D16: =A16/2+C16 -> 1250 | E16: 2019
A17: 975 | B17: 13 | C17: 800 | D17: =A17/2+C17 -> 1287.5 | E17: 2020
A18: 1000 | B18: 13 | C18: 850 | D18: =A18/2+C18 -> 1350 | E18: 2021
A19: 1125 | B19: 15 | E19: 2022
A20: 1200 | B20: 16 | E20: 2023
A21: 1275 | B21: 17 | E21: 2024
A22: 1600 | B22: 21 | E22: 2025
A23: 2000 | B23: 27 | E23: 2026
E24: 2027
E25: 2028
E26: 2029

Sheet Askı Tipleri
A100: Durumlar; | M100: Yükleme | N100: Bloke etme | P100: Frenleme
A101: I | B101: : yalnız en üst konumda duran kabinde; | L101: Normal | M101: %125 Yüklü kabin en altta | N101: %100 Yüklü Kabin Tampona oturduğunda | O101: Karşı A. Tampona Oturduğunda Boş Kabin En Üstte | P101: % 100 Yüklü Kabin En Altta | Q101: Boş Kabin En üstte
A102: II | B102: : saptırma kasnağı kabin veya karşı ağırlık tarafında;
A103: III | B103: : yalnız halat askı oranı > 1 ise;
A104: IV | B104: : yalnız en üst konumda duran karşı ağırlıkta;
A105: V | B105: : yalnız halat askı oranı > 1 ise.
A107: mPcar | B107: : Kabin tarafındaki kasnağın indirgenmiş kütlesi JPcar / R2 (kg); | L107: 0 | M107: 0 | N107: 0 | O107: 0 | P107: 0 | Q107: 0
A108: mPcwt | B108: : Karşı ağırlık tarafındaki kasnağın indirgenmiş kütlesi JPcwt / R2 (kg); | L108: 0 | M108: 0 | N108: 0 | O108: 0 | P108: 0 | Q108: 0
A109: mPTD | B109: : Dengeleme halatı gergi tertibatı kasnaklarının (2 adet kasnak) indirgenmiş kütlesi JPDT / R2 (kg); | L109: 0 | M109: 0 | N109: 0 | O109: 0 | P109: 0 | Q109: 0
A110: mDP | B110: : Kabin / karşı ağırlık tarafındaki saptırma kasnağının indirgenmiş kütlesi JDP / R2 (kg); | L110: 0 | M110: 0 | N110: 0 | O110: 0 | P110: 0 | Q110: 0
A111: ns | B111: : Askı halatlarının sayısı; | L111: ='Veri Girişi'!$B$98 -> 7 | M111: ='Veri Girişi'!$B$98 -> 7 | N111: ='Veri Girişi'!$B$98 -> 7 | O111: ='Veri Girişi'!$B$98 -> 7 | P111: ='Veri Girişi'!$B$98 -> 7 | Q111: ='Veri Girişi'!$B$98 -> 7
A112: nc | B112: : Dengeleme halatlarının/ zincirlerinin sayısı; | L112: 0 | M112: 0 | N112: 0 | O112: 0 | P112: 0 | Q112: 0
A113: nt | B113: : Kabin bükülgen kablolarının sayısı; | L113: 1 | M113: 1 | N113: 1 | O113: 1 | P113: 1 | Q113: 1
A114: P | B114: : Boş kabin ve kabine asılı parçaların, meselâ: kabin bükülme kablosunun kabin tarafından taşınan kısmı ve | L114: ='Veri Girişi'!$C$75 -> 700 | M114: ='Veri Girişi'!$C$75 -> 700 | N114: 0 | O114: ='Veri Girişi'!$C$75 -> 700 | P114: ='Veri Girişi'!$C$75 -> 700 | Q114: ='Veri Girişi'!$C$75 -> 700
B115: varsa dengeleme halatları/zincirlerinin vb. kütlelerinin toplamı (kg);
A116: Q | B116: : Beyan yükü (kg); | L116: ='Veri Girişi'!$C$59 -> 800 | M116: =L116*1.25 -> 1000 | N116: 0 | O116: 0 | P116: ='Veri Girişi'!$C$59 -> 800 | Q116: 0
A117: Mcwt | B117: : Kasnaklar dahil karşı ağırlığın kütlesi (kg); | L117: ='Veri Girişi'!$C$80 -> 1100 | M117: ='Veri Girişi'!$C$80 -> 1100 | N117: ='Veri Girişi'!$C$80 -> 1100 | O117: 0 | P117: ='Veri Girişi'!$C$80 -> 1100 | Q117: ='Veri Girişi'!$C$80 -> 1100
A118: MSR | B118: : Askı halatlarının gerçek kütlesi ([0,5 H ± y] ⋅ ns ⋅ askı halatının birim uzunluk başına kütlesi) (kg); | L118: =(0.5*L130+L131)*'Veri Girişi'!$B$98*'11-Muk. Hesapları'!$AQ$18 -> 11.172 | M118: =(0.5*M130+M131)*'Veri Girişi'!$B$98*'11-Muk. Hesapları'!$AQ$18 -> 22.344 | N118: =(0.5*N130+N131)*'Veri Girişi'!$B$98*'11-Muk. Hesapları'!$AQ$18 -> 22.344 | O118: =(0.5*O130+O131)*'Veri Girişi'!$B$98*'11-Muk. Hesapları'!$AQ$18 -> 22.344 | P118: =(0.5*P130+P131)*'Veri Girişi'!$B$98*'11-Muk. Hesapları'!$AQ$18 -> 22.344 | Q118: =(0.5*Q130+Q131)*'Veri Girişi'!$B$98*'11-Muk. Hesapları'!$AQ$18 -> 22.344
A119: MSRcar | B119: : Kabin tarafındaki kütle MSR (kg); | M119: =(0.5*M130-M131)*'Veri Girişi'!$B$98*'11-Muk. Hesapları'!$AQ$18 -> 0 | N119: =(0.5*N130-N131)*'Veri Girişi'!$B$98*'11-Muk. Hesapları'!$AQ$18 -> 0 | O119: =(0.5*O130-O131)*'Veri Girişi'!$B$98*'11-Muk. Hesapları'!$AQ$18 -> 0 | P119: =(0.5*P130-P131)*'Veri Girişi'!$B$98*'11-Muk. Hesapları'!$AQ$18 -> 0 | Q119: =(0.5*Q130+Q131)*'Veri Girişi'!$B$98*'11-Muk. Hesapları'!$AQ$18 -> 22.344
A120: MSRcwt | B120: : Karşı ağırlık tarafındaki kütle MSR (kg); | M120: =(0.5*M130+M132)*'Veri Girişi'!$B$98*'11-Muk. Hesapları'!$AQ$18 -> 22.344 | N120: =(0.5*N130+N132)*'Veri Girişi'!$B$98*'11-Muk. Hesapları'!$AQ$18 -> 22.344 | O120: =('Veri Girişi'!B98)*('Veri Girişi'!C63)*(VLOOKUP('Veri Girişi'!B99,TABLOLAR!A32:C43,2,0)) -> 22.344 | P120: =(0.5*P130+P132)*'Veri Girişi'!$B$98*'11-Muk. Hesapları'!$AQ$18 -> 22.344 | Q120: =(0.5*Q130-Q132)*'Veri Girişi'!$B$98*'11-Muk. Hesapları'!$AQ$18 -> 0
A121: MCR | B121: : Dengeleme halatlarının/ zincirlerinin gerçek kütlesi ([0,5 H ± y] ⋅ nc ⋅ halatın/ zincirin birim uzunluk başına | L121: 0 | M121: 0 | N121: 0 | O121: 0 | P121: 0 | Q121: 0
B122: kütlesi) (kg);
A123: MCRcar | B123: : Kabin tarafındaki kütle MCR (kg); | L123: 0 | M123: 0 | N123: 0 | O123: 0 | P123: 0 | Q123: 0
A124: MCRcwt | B124: : Karşı ağırlık tarafındaki kütle MCR (kg); | L124: 0 | M124: 0 | N124: 0 | O124: 0 | P124: 0 | Q124: 0
A125: MTrav | B125: : Kabin bükülgen kablolarının gerçek kütlesi ([0,25 H ± 0,5 y] ⋅ nt ⋅ bükülgen kablonun birim uzunluk başına | L125: =(0.25*$L$130+L131)*VLOOKUP('Veri Girişi'!$B$108,TABLOLAR!$D$61:$G$64,4,0)+((0.25*$L$130+L131)*TABLOLAR!$G$62) -> 6.741 | M125: 0 | N125: 0 | O125: =(0.25*$L$130+0.5*O131)*VLOOKUP('Veri Girişi'!$B$108,TABLOLAR!$D$61:$G$64,4,0)+((0.25*$L$130+0.5*O131)*TABLOLAR!$G$62) -> 13.482 | P125: 0 | Q125: =(0.25*$L$130+0.5*Q131)*VLOOKUP('Veri Girişi'!$B$108,TABLOLAR!$D$61:$G$64,4,0)+((0.25*$L$130+0.5*Q131)*TABLOLAR!$G$62) -> 13.482
B126: kütlesi) (kg);
A127: MComp | B127: : Kasnaklar dahil dengeleme halatı gergi tertibatının kütlesi (kg); | L127: 0 | M127: 0 | N127: 0 | O127: 0 | P127: 0 | Q127: 0
A128: FRcar | B128: : Kuyudaki sürtünme kuvveti (kabin tarafındaki yatakların verimleri, raylardaki sürtünme, vb. ) (N); | M128: 0 | N128: 0 | O128: 0 | P128: =0.02*('11-Muk. Hesapları'!D250+'11-Muk. Hesapları'!I250+'11-Muk. Hesapları'!L250) -> 135.15 | Q128: =0.02*('11-Muk. Hesapları'!D264+'11-Muk. Hesapları'!I264+'11-Muk. Hesapları'!L264-'11-Muk. Hesapları'!P264+'11-Muk. Hesapları'!S264+'11-Muk. Hesapları'!V264) -> 80.799341
A129: FRcwt | B129: : Kuyudaki sürtünme kuvveti (karşı ağırlık tarafındaki yatakların verimleri, raylardaki sürtünme, vb. ) (N); | M129: 0 | N129: 0 | O129: 0 | P129: =0.015*('11-Muk. Hesapları'!D255+'11-Muk. Hesapları'!I255-'11-Muk. Hesapları'!L255) -> 83.708324 | Q129: =0.015*('11-Muk. Hesapları'!D269+'11-Muk. Hesapları'!I269+'11-Muk. Hesapları'!L269+'11-Muk. Hesapları'!P269+'11-Muk. Hesapları'!S269+'11-Muk. Hesapları'!V269) -> 74.3325
A130: H | B130: : Seyir mesafesi (m); | L130: ='Veri Girişi'!$C$63 -> 21 | M130: ='Veri Girişi'!$C$63 -> 21 | N130: ='Veri Girişi'!$C$63 -> 21 | O130: ='Veri Girişi'!$C$63 -> 21 | P130: ='Veri Girişi'!$C$63 -> 21 | Q130: ='Veri Girişi'!$C$63 -> 21
A131: ycar | B131: : Kabinin seyir mesafesinin ortasına olan uzaklığı (m), (0,5 H seviyesinde y=0); | L131: 0 | M131: =M130/2 -> 10.5 | N131: =N130/2 -> 10.5 | O131: =O130/2 -> 10.5 | P131: =P130/2 -> 10.5 | Q131: =(Q130/2) -> 10.5
A132: ycwt | B132: : Karşı ağırlığın seyir mesafesinin ortasına olan uzaklığı (m), (0,5 H seviyesinde y=0); | L132: 0 | M132: =M130/2 -> 10.5 | N132: =N130/2 -> 10.5 | O132: =O130/2 -> 10.5 | P132: =P130/2 -> 10.5 | Q132: =Q130/2 -> 10.5
A133: r | B133: : Halat askı katsayısı | L133: ='Veri Girişi'!$B$100 -> 2 | M133: ='Veri Girişi'!$B$100 -> 2 | N133: ='Veri Girişi'!$B$100 -> 2 | O133: ='Veri Girişi'!$B$100 -> 2 | P133: ='Veri Girişi'!$B$100 -> 2 | Q133: ='Veri Girişi'!$B$100 -> 2
A134: a | B134: : Kabinin frenleme ivmesi (pozitif değer) (m/s2); | L134: 0 | M134: 0 | N134: 0 | O134: 0 | P134: ='Veri Girişi'!$B$133 -> 0.8 | Q134: ='Veri Girişi'!$B$133 -> 0.8
A135: gn | B135: : Standard yerçekimi ivmesi (m/s2); | L135: 9.81 | M135: 9.81 | N135: 9.81 | O135: 9.81 | P135: 9.81 | Q135: 9.81
A136: iPcar | B136: : Kabin tarafındaki kasnakların sayısı (saptırma kasnağı hariç); | L136: 0 | M136: 0 | N136: 0 | O136: 0 | P136: 0 | Q136: 0
A137: iPcwt | B137: : Karşı ağırlık tarafındaki kasnakların sayısı (saptırma kasnağı hariç); | L137: 1 | M137: 1 | N137: 1 | O137: 1 | P137: 1 | Q137: 1
A138: iPDT | B138: : Gergi tertibatı için makara sayısı; | L138: 0 | M138: 0 | N138: 0 | O138: 0 | P138: 0 | Q138: 0

Sheet TABLOLAR
A1: TRAFİK HESAP TABLOLARI
A2: Tablo--1 | E2: Tablo--2 | X2: Tablo--3 | AQ2: Tablo--5.1 Ta(s) | AX2: Tablo--6
A3: Bina Tipi | C3: b | E3: Ana giriş üzerindeki kat adedi | F3: Kabin Kapasitesi (P) | X3: Ana giriş üzerindeki kat adedi | Y3: Kabin Kapasitesi (P) | AR3: Kapı Tipi | AX3: Hız (m/s) | AY3: Tg (s)
B4: diğer odaların her biri için | C4: 1 | F4: 180 | G4: 225 | H4: 300 | I4: 320 | J4: 375 | K4: 400 | L4: 450 | M4: 525 | N4: 600 | O4: 630 | P4: 675 | Q4: 750 | R4: 800 | S4: 825 | T4: 900 | U4: 975 | V4: 1000 | Y4: 180 | Z4: 225 | AA4: 300 | AB4: 320 | AC4: 375 | AD4: 400 | AE4: 450 | AF4: 525 | AG4: 600 | AH4: 630 | AI4: 675 | AJ4: 750 | AK4: 800 | AL4: 825 | AM4: 900 | AN4: 975 | AO4: 1000 | AR4: Manuel Sağ | AS4: Manuel Sol | AT4: Otomatik Merkezi | AU4: Teleskopik Sağ | AV4: Teleskopik Sol | AX4: <1 | AY4: 10
A5: KONUT | B5: her daire bir yatak odasi için | C5: 2 | F5: =IF('Veri Girişi'!$C$59=TABLOLAR!F4,VLOOKUP('Veri Girişi'!$B$129,TABLOLAR!$E$6:$V$28,2,0)) -> FALSE | G5: =IF('Veri Girişi'!$C$59=TABLOLAR!G4,VLOOKUP('Veri Girişi'!$B$129,TABLOLAR!$E$6:$V$28,3,0)) -> FALSE | H5: =IF('Veri Girişi'!$C$59=TABLOLAR!H4,VLOOKUP('Veri Girişi'!$B$129,TABLOLAR!$E$6:$V$28,4,0)) -> FALSE | I5: =IF('Veri Girişi'!$C$59=TABLOLAR!I4,VLOOKUP('Veri Girişi'!$B$129,TABLOLAR!$E$6:$V$28,5,0)) -> FALSE | J5: =IF('Veri Girişi'!$C$59=TABLOLAR!J4,VLOOKUP('Veri Girişi'!$B$129,TABLOLAR!$E$6:$V$28,6,0)) -> FALSE | K5: =IF('Veri Girişi'!$C$59=TABLOLAR!K4,VLOOKUP('Veri Girişi'!$B$129,TABLOLAR!$E$6:$V$28,7,0)) -> FALSE | L5: =IF('Veri Girişi'!$C$59=TABLOLAR!L4,VLOOKUP('Veri Girişi'!$B$129,TABLOLAR!$E$6:$V$28,8,0)) -> FALSE | M5: =IF('Veri Girişi'!$C$59=TABLOLAR!M4,VLOOKUP('Veri Girişi'!$B$129,TABLOLAR!$E$6:$V$28,9,0)) -> FALSE | N5: =IF('Veri Girişi'!$C$59=TABLOLAR!N4,VLOOKUP('Veri Girişi'!$B$129,TABLOLAR!$E$6:$V$28,10,0)) -> FALSE | O5: =IF('Veri Girişi'!$C$59=TABLOLAR!O4,VLOOKUP('Veri Girişi'!$B$129,TABLOLAR!$E$6:$V$28,11,0)) -> FALSE | P5: =IF('Veri Girişi'!$C$59=TABLOLAR!P4,VLOOKUP('Veri Girişi'!$B$129,TABLOLAR!$E$6:$V$28,12,0)) -> FALSE | Q5: =IF('Veri Girişi'!$C$59=TABLOLAR!Q4,VLOOKUP('Veri Girişi'!$B$129,TABLOLAR!$E$6:$V$28,13,0)) -> FALSE | R5: =IF('Veri Girişi'!$C$59=TABLOLAR!R4,VLOOKUP('Veri Girişi'!$B$129,TABLOLAR!$E$6:$V$28,14,0)) -> 5.7 | S5: =IF('Veri Girişi'!$C$59=TABLOLAR!S4,VLOOKUP('Veri Girişi'!$B$129,TABLOLAR!$E$6:$V$28,15,0)) -> FALSE | T5: =IF('Veri Girişi'!$C$59=TABLOLAR!T4,VLOOKUP('Veri Girişi'!$B$129,TABLOLAR!$E$6:$V$28,16,0)) -> FALSE | U5: =IF('Veri Girişi'!$C$59=TABLOLAR!U4,VLOOKUP('Veri Girişi'!$B$129,TABLOLAR!$E$6:$V$28,17,0)) -> FALSE | V5: =IF('Veri Girişi'!$C$59=TABLOLAR!V4,VLOOKUP('Veri Girişi'!$B$129,TABLOLAR!$E$6:$V$28,18,0)) -> FALSE | Y5: =IF('Veri Girişi'!$C$59=TABLOLAR!Y4,VLOOKUP('Veri Girişi'!$B$129,TABLOLAR!$X$6:$AO$28,2,0)) -> FALSE | Z5: =IF('Veri Girişi'!$C$59=TABLOLAR!Z4,VLOOKUP('Veri Girişi'!$B$129,TABLOLAR!$X$6:$AO$28,3,0)) -> FALSE | AA5: =IF('Veri Girişi'!$C$59=TABLOLAR!AA4,VLOOKUP('Veri Girişi'!$B$129,TABLOLAR!$X$6:$AO$28,4,0)) -> FALSE | AB5: =IF('Veri Girişi'!$C$59=TABLOLAR!AB4,VLOOKUP('Veri Girişi'!$B$129,TABLOLAR!$X$6:$AO$28,5,0)) -> FALSE | AC5: =IF('Veri Girişi'!$C$59=TABLOLAR!AC4,VLOOKUP('Veri Girişi'!$B$129,TABLOLAR!$X$6:$AO$28,6,0)) -> FALSE | AD5: =IF('Veri Girişi'!$C$59=TABLOLAR!AD4,VLOOKUP('Veri Girişi'!$B$129,TABLOLAR!$X$6:$AO$28,7,0)) -> FALSE | AE5: =IF('Veri Girişi'!$C$59=TABLOLAR!AE4,VLOOKUP('Veri Girişi'!$B$129,TABLOLAR!$X$6:$AO$28,8,0)) -> FALSE | AF5: =IF('Veri Girişi'!$C$59=TABLOLAR!AF4,VLOOKUP('Veri Girişi'!$B$129,TABLOLAR!$X$6:$AO$28,9,0)) -> FALSE | AG5: =IF('Veri Girişi'!$C$59=TABLOLAR!AG4,VLOOKUP('Veri Girişi'!$B$129,TABLOLAR!$X$6:$AO$28,10,0)) -> FALSE | AH5: =IF('Veri Girişi'!$C$59=TABLOLAR!AH4,VLOOKUP('Veri Girişi'!$B$129,TABLOLAR!$X$6:$AO$28,11,0)) -> FALSE | AI5: =IF('Veri Girişi'!$C$59=TABLOLAR!AI4,VLOOKUP('Veri Girişi'!$B$129,TABLOLAR!$X$6:$AO$28,12,0)) -> FALSE | AJ5: =IF('Veri Girişi'!$C$59=TABLOLAR!AJ4,VLOOKUP('Veri Girişi'!$B$129,TABLOLAR!$X$6:$AO$28,13,0)) -> FALSE | AK5: =IF('Veri Girişi'!$C$59=TABLOLAR!AK4,VLOOKUP('Veri Girişi'!$B$129,TABLOLAR!$X$6:$AO$28,14,0)) -> 4.6 | AL5: =IF('Veri Girişi'!$C$59=TABLOLAR!AL4,VLOOKUP('Veri Girişi'!$B$129,TABLOLAR!$X$6:$AO$28,15,0)) -> FALSE | AM5: =IF('Veri Girişi'!$C$59=TABLOLAR!AM4,VLOOKUP('Veri Girişi'!$B$129,TABLOLAR!$X$6:$AO$28,16,0)) -> FALSE | AN5: =IF('Veri Girişi'!$C$59=TABLOLAR!AN4,VLOOKUP('Veri Girişi'!$B$129,TABLOLAR!$X$6:$AO$28,17,0)) -> FALSE | AO5: =IF('Veri Girişi'!$C$59=TABLOLAR!AO4,VLOOKUP('Veri Girişi'!$B$129,TABLOLAR!$X$6:$AO$28,18,0)) -> FALSE | AQ5: Genişlik (mm) | AR5: =IF('Veri Girişi'!$C$66=TABLOLAR!AR4,VLOOKUP('Veri Girişi'!$C$71,$AQ$6:$AV$13,2,0)) -> FALSE | AS5: =IF('Veri Girişi'!$C$66=TABLOLAR!AS4,VLOOKUP('Veri Girişi'!$C$71,$AQ$6:$AV$13,3,0)) -> FALSE | AT5: =IF('Veri Girişi'!$C$66=TABLOLAR!AT4,VLOOKUP('Veri Girişi'!$C$71,$AQ$6:$AV$13,4,0)) -> FALSE | AU5: =IF('Veri Girişi'!$C$66=TABLOLAR!AU4,VLOOKUP('Veri Girişi'!$C$71,$AQ$6:$AV$13,5,0)) -> FALSE | AV5: =IF('Veri Girişi'!$C$66=TABLOLAR!AV4,VLOOKUP('Veri Girişi'!$C$71,$AQ$6:$AV$13,6,0)) -> 2.5 | AX5: 1 | AY5: 7
A6: OTEL | B6: Her yatak için | C6: 1 | E6: 2 | F6: 1.9 | G6: 1.9 | H6: 2 | I6: 2 | J6: 2.1 | K6: 2.1 | L6: 2.2 | M6: 2.2 | N6: 2.3 | O6: 2.3 | P6: 2.3 | Q6: 2.4 | R6: 2.4 | S6: 2.4 | T6: 2.5 | U6: 2.5 | V6: 2.5 | X6: 2 | Y6: 1.8 | Z6: 1.9 | AA6: 2.1 | AB6: 2.1 | AC6: 2.3 | AD6: 2.3 | AE6: 2.5 | AF6: 2.7 | AG6: 2.8 | AH6: 2.9 | AI6: 3 | AJ6: 3.2 | AK6: 3.2 | AL6: 3.3 | AM6: 3.2 | AN6: 3.3 | AO6: 3.4 | AQ6: 700 | AR6: 5 | AS6: 5 | AT6: 2 | AU6: 2.4 | AV6: 2.4 | AX6: 1.2 | AY6: 6.5
A7: İŞ MERKEZİ | B7: Çalışma Alanının her 12 m2 si için | C7: 1 | E7: 3 | F7: 2.7 | G7: 2.7 | H7: 2.8 | I7: 2.8 | J7: 2.9 | K7: 2.9 | L7: 3 | M7: 3 | N7: 3.1 | O7: 3.1 | P7: 3.1 | Q7: 3.2 | R7: 3.2 | S7: 3.2 | T7: 3.3 | U7: 3.3 | V7: 3.3 | X7: 3 | Y7: 2 | Z7: 2.1 | AA7: 2.3 | AB7: 2.3 | AC7: 2.5 | AD7: 2.5 | AE7: 2.7 | AF7: 2.9 | AG7: 3.2 | AH7: 3.3 | AI7: 3.4 | AJ7: 3.6 | AK7: 3.6 | AL7: 3.7 | AM7: 3.6 | AN7: 3.7 | AO7: 3.8 | AQ7: 800 | AR7: 5 | AS7: 5 | AT7: 2 | AU7: 2.5 | AV7: 2.5 | AX7: 1.6 | AY7: 6
A8: OKUL | B8: Sınıf odasının her 10 m2 si için | C8: 8 | E8: 4 | F8: 3.5 | G8: 3.5 | H8: 3.6 | I8: 3.6 | J8: 3.7 | K8: 3.7 | L8: 3.8 | M8: 3.8 | N8: 3.9 | O8: 3.9 | P8: 3.9 | Q8: 4 | R8: 4 | S8: 4 | T8: 4.1 | U8: 4.1 | V8: 4.1 | X8: 4 | Y8: 2.2 | Z8: 2.3 | AA8: 2.5 | AB8: 2.5 | AC8: 2.7 | AD8: 2.7 | AE8: 2.9 | AF8: 3.1 | AG8: 3.4 | AH8: 3.5 | AI8: 3.6 | AJ8: 3.8 | AK8: 3.8 | AL8: 3.9 | AM8: 4 | AN8: 4.1 | AO8: 4.2 | AQ8: 900 | AR8: 5 | AS8: 5 | AT8: 2.3 | AU8: 2.5 | AV8: 2.5 | AX8: 2.5 | AY8: 5.5
A9: HASTANE | B9: Her yatak için | C9: 3 | E9: 5 | F9: 4.3 | G9: 4.3 | H9: 4.4 | I9: 4.4 | J9: 4.5 | K9: 4.5 | L9: 4.6 | M9: 4.6 | N9: 4.7 | O9: 4.7 | P9: 4.7 | Q9: 4.8 | R9: 4.8 | S9: 4.8 | T9: 4.9 | U9: 4.9 | V9: 4.9 | X9: 5 | Y9: 2.6 | Z9: 2.7 | AA9: 2.9 | AB9: 2.9 | AC9: 3.1 | AD9: 3.1 | AE9: 3.3 | AF9: 3.5 | AG9: 3.8 | AH9: 3.9 | AI9: 4 | AJ9: 4.2 | AK9: 4.2 | AL9: 4.3 | AM9: 4.4 | AN9: 4.5 | AO9: 4.6 | AQ9: 1000 | AR9: 6 | AS9: 6 | AT9: 2.5 | AU9: 2.9 | AV9: 2.9 | AX9: 3.5 | AY9: 5
A10: RESMİ BİNA | B10: Tek kullanımlı her 12 m2 si için | C10: 1 | E10: 6 | F10: 5 | G10: 5.1 | H10: 5.2 | I10: 5.2 | J10: 5.3 | K10: 5.3 | L10: 5.4 | M10: 5.5 | N10: 5.6 | O10: 5.6 | P10: 5.6 | Q10: 5.7 | R10: 5.7 | S10: 5.7 | T10: 5.8 | U10: 5.8 | V10: 5.8 | X10: 6 | Y10: 2.8 | Z10: 2.9 | AA10: 3.1 | AB10: 3.1 | AC10: 3.3 | AD10: 3.3 | AE10: 3.5 | AF10: 3.7 | AG10: 4.1 | AH10: 4.2 | AI10: 4.3 | AJ10: 4.6 | AK10: 4.6 | AL10: 4.8 | AM10: 5 | AN10: 5.2 | AO10: 5.4 | AQ10: 1100 | AR10: 6 | AS10: 6 | AT10: 2.5 | AU10: 3 | AV10: 3 | AX10: 5 | AY10: 4.5
A11: OTOPARK TİCARİ | B11: Ticari amaçlı araç adedi başına | C11: 1.5 | E11: 7 | F11: 5.9 | G11: 6 | H11: 6.1 | I11: 6.1 | J11: 6.1 | K11: 6.1 | L11: 6.2 | M11: 6.3 | N11: 6.5 | O11: 6.5 | P11: 6.5 | Q11: 6.6 | R11: 6.6 | S11: 6.6 | T11: 6.7 | U11: 6.7 | V11: 6.7 | X11: 7 | Y11: 2.9 | Z11: 3 | AA11: 3.2 | AB11: 3.2 | AC11: 3.5 | AD11: 3.5 | AE11: 3.7 | AF11: 4 | AG11: 4.4 | AH11: 4.5 | AI11: 4.7 | AJ11: 5 | AK11: 5 | AL11: 5.2 | AM11: 5.4 | AN11: 5.6 | AO11: 5.8 | AQ11: 1200 | AR11: 6 | AS11: 6 | AT11: 2.6 | AU11: 3.2 | AV11: 3.2 | AX11: 6 | AY11: 4.3
A12: OTOPARK ÖZEL | B12: Özel amaçlı araç adedi başına | C12: 1 | E12: 8 | F12: 6.7 | G12: 6.8 | H12: 6.9 | I12: 6.9 | J12: 7 | K12: 7 | L12: 7.1 | M12: 7.2 | N12: 7.4 | O12: 7.4 | P12: 7.4 | Q12: 7.5 | R12: 7.5 | S12: 7.5 | T12: 7.6 | U12: 7.6 | V12: 7.6 | X12: 8 | Y12: 3 | Z12: 3.1 | AA12: 3.3 | AB12: 3.3 | AC12: 3.5 | AD12: 3.5 | AE12: 3.8 | AF12: 4.2 | AG12: 4.6 | AH12: 4.7 | AI12: 4.9 | AJ12: 5.3 | AK12: 5.3 | AL12: 5.5 | AM12: 5.8 | AN12: 6.1 | AO12: 6.4 | AQ12: 1300 | AR12: 6 | AS12: 6 | AT12: 2.6 | AU12: 3.5 | AV12: 3.5
E13: 9 | F13: 7.5 | G13: 7.6 | H13: 7.7 | I13: 7.7 | J13: 7.8 | K13: 7.8 | L13: 7.9 | M13: 8 | N13: 8.2 | O13: 8.2 | P13: 8.3 | Q13: 8.4 | R13: 8.4 | S13: 8.5 | T13: 8.6 | U13: 8.6 | V13: 8.6 | X13: 9 | Y13: 3 | Z13: 3.1 | AA13: 3.4 | AB13: 3.4 | AC13: 3.6 | AD13: 3.6 | AE13: 3.9 | AF13: 4.3 | AG13: 4.8 | AH13: 4.9 | AI13: 5.1 | AJ13: 5.5 | AK13: 5.5 | AL13: 5.8 | AM13: 6.1 | AN13: 6.4 | AO13: 6.8 | AQ13: 1400 | AR13: 6 | AS13: 6 | AT13: 2.7 | AU13: 3.7 | AV13: 3.7 | AX13: Tablo--9
A14: Tablo--10 | E14: 10 | F14: 8.3 | G14: 8.4 | H14: 8.5 | I14: 8.5 | J14: 8.6 | K14: 8.6 | L14: 8.7 | M14: 8.9 | N14: 9.1 | O14: 9.1 | P14: 9.2 | Q14: 9.3 | R14: 9.3 | S14: 9.4 | T14: 9.5 | U14: 9.5 | V14: 9.5 | X14: 10 | Y14: 3 | Z14: 3.1 | AA14: 3.4 | AB14: 3.4 | AC14: 3.7 | AD14: 3.7 | AE14: 4 | AF14: 4.4 | AG14: 4.9 | AH14: 5 | AI14: 5.3 | AJ14: 5.7 | AK14: 5.7 | AL14: 6 | AM14: 6.4 | AN14: 6.8 | AO14: 7.2 | AX14: Bina Tipi | AZ14: Standart | BA14: Yükseltilmiş
A15: Sınıf | B15: Standart | C15: Yükseltilmiş | E15: 11 | F15: 9.1 | G15: 9.2 | H15: 9.3 | I15: 9.3 | J15: 9.4 | K15: 9.4 | L15: 9.6 | M15: 9.8 | N15: 10.1 | O15: 10.1 | P15: 10.1 | Q15: 10.2 | R15: 10.2 | S15: 10.3 | T15: 10.4 | U15: 10.4 | V15: 10.4 | X15: 11 | Y15: 3.1 | Z15: 3.2 | AA15: 3.5 | AB15: 3.5 | AC15: 3.7 | AD15: 3.7 | AE15: 4 | AF15: 4.5 | AG15: 5 | AH15: 5.1 | AI15: 5.4 | AJ15: 5.9 | AK15: 5.9 | AL15: 6.2 | AM15: 6.6 | AN15: 7 | AO15: 7.4 | AQ15: Tablo--5.2 Tk(s) | AX15: Konut | AZ15: 0.075 | BA15: 0.1
A16: KONUT | B16: 120 | C16: 80 | E16: 12 | F16: 9.9 | G16: 10 | H16: 10.1 | I16: 10.1 | J16: 10.2 | K16: 10.2 | L16: 10.4 | M16: 10.6 | N16: 10.8 | O16: 10.8 | P16: 10.9 | Q16: 11.1 | R16: 11.1 | S16: 11.2 | T16: 11.3 | U16: 11.3 | V16: 11.3 | X16: 12 | Y16: 3.1 | Z16: 3.2 | AA16: 3.5 | AB16: 3.5 | AC16: 3.8 | AD16: 3.8 | AE16: 4.1 | AF16: 4.6 | AG16: 5.1 | AH16: 5.2 | AI16: 5.5 | AJ16: 6 | AK16: 6 | AL16: 6.4 | AM16: 6.8 | AN16: 7.2 | AO16: 7.6 | AR16: Kapı Tipi | AX16: Otel | AZ16: 0.12 | BA16: 0.15
A17: OTEL | B17: 40 | C17: 30 | E17: 13 | F17: 10.7 | G17: 10.8 | H17: 10.9 | I17: 10.9 | J17: 11 | K17: 11 | L17: 11.2 | M17: 11.5 | N17: 11.7 | O17: 11.7 | P17: 11.8 | Q17: 12 | R17: 12 | S17: 11 | T17: 12.2 | U17: 12.2 | V17: 12.2 | X17: 13 | Y17: 3.2 | Z17: 3.3 | AA17: 3.6 | AB17: 3.6 | AC17: 3.8 | AD17: 3.8 | AE17: 4.1 | AF17: 4.6 | AG17: 5.2 | AH17: 5.3 | AI17: 5.6 | AJ17: 6.1 | AK17: 6.1 | AL17: 6.5 | AM17: 7 | AN17: 7.5 | AO17: 7.9 | AR17: Manuel Sağ | AS17: Manuel Sol | AT17: Otomatik Merkezi | AU17: Teleskopik Sağ | AV17: Teleskopik Sol | AX17: İş Merkezi | AY17: Çoklu | AZ17: 0.15 | BA17: 0.17
A18: İŞ MERKEZİ | B18: 40 | C18: 30 | E18: 14 | F18: 11.4 | G18: 11.5 | H18: 11.7 | I18: 11.7 | J18: 11.9 | K18: 11.9 | L18: 12.1 | M18: 12.4 | N18: 12.6 | O18: 12.6 | P18: 12.7 | Q18: 12.9 | R18: 12.9 | S18: 13 | T18: 13.1 | U18: 13.1 | V18: 13.1 | X18: 14 | Y18: 3.2 | Z18: 3.3 | AA18: 3.6 | AB18: 3.6 | AC18: 3.9 | AD18: 3.9 | AE18: 4.2 | AF18: 4.7 | AG18: 5.3 | AH18: 5.4 | AI18: 5.8 | AJ18: 6.3 | AK18: 6.3 | AL18: 6.7 | AM18: 7.1 | AN18: 7.5 | AO18: 7.9 | AQ18: Genişlik (mm) | AR18: =IF('Veri Girişi'!$C$66=TABLOLAR!AR17,VLOOKUP('Veri Girişi'!$C$71,$AQ$19:$AV$26,2,0)) -> FALSE | AS18: =IF('Veri Girişi'!$C$66=TABLOLAR!AS17,VLOOKUP('Veri Girişi'!$C$71,$AQ$19:$AV$26,3,0)) -> FALSE | AT18: =IF('Veri Girişi'!$C$66=TABLOLAR!AT17,VLOOKUP('Veri Girişi'!$C$71,$AQ$19:$AV$26,4,0)) -> FALSE | AU18: =IF('Veri Girişi'!$C$66=TABLOLAR!AU17,VLOOKUP('Veri Girişi'!$C$71,$AQ$19:$AV$26,5,0)) -> FALSE | AV18: =IF('Veri Girişi'!$C$66=TABLOLAR!AV17,VLOOKUP('Veri Girişi'!$C$71,$AQ$19:$AV$26,6,0)) -> 3.8 | AY18: Tekil | AZ18: 0.15 | BA18: 0.25
A19: OKUL | B19: 40 | C19: 30 | E19: 15 | F19: 12.2 | G19: 12.3 | H19: 12.5 | I19: 12.5 | J19: 12.7 | K19: 12.7 | L19: 12.9 | M19: 13.1 | N19: 13.4 | O19: 13.4 | P19: 13.6 | Q19: 13.8 | R19: 13.8 | S19: 13.9 | T19: 14 | U19: 14 | V19: 14 | X19: 15 | Y19: 3.2 | Z19: 3.3 | AA19: 3.6 | AB19: 3.6 | AC19: 3.9 | AD19: 3.9 | AE19: 4.2 | AF19: 4.8 | AG19: 5.4 | AH19: 5.5 | AI19: 5.9 | AJ19: 6.4 | AK19: 6.4 | AL19: 6.8 | AM19: 7.3 | AN19: 7.8 | AO19: 8.3 | AQ19: 700 | AR19: 5 | AS19: 5 | AT19: 2.3 | AU19: 3 | AV19: 3 | AX19: Okul | AZ19: 0.15 | BA19: 0.2
A20: HASTANE | B20: 40 | C20: 30 | E20: 16 | F20: 13.1 | G20: 13.2 | H20: 13.3 | I20: 13.3 | J20: 13.4 | K20: 13.4 | L20: 13.7 | M20: 14 | N20: 14.3 | O20: 14.3 | P20: 14.5 | Q20: 14.7 | R20: 14.7 | S20: 14.8 | T20: 14.9 | U20: 14.9 | V20: 14.9 | X20: 16 | Y20: 3.2 | Z20: 3.3 | AA20: 3.6 | AB20: 3.6 | AC20: 3.9 | AD20: 3.9 | AE20: 4.3 | AF20: 4.9 | AG20: 5.4 | AH20: 5.5 | AI20: 5.9 | AJ20: 6.5 | AK20: 6.5 | AL20: 6.9 | AM20: 7.4 | AN20: 7.9 | AO20: 8.4 | AQ20: 800 | AR20: 5 | AS20: 5 | AT20: 2.5 | AU20: 3 | AV20: 3 | AX20: Hastane | AZ20: 0.1 | BA20: 0.2
A21: RESMİ BİNA | B21: 40 | C21: 30 | E21: 17 | F21: 13.8 | G21: 13.9 | H21: 14.1 | I21: 14.1 | J21: 14.3 | K21: 14.3 | L21: 14.5 | M21: 14.8 | N21: 15.2 | O21: 15.2 | P21: 15.4 | Q21: 15.6 | R21: 15.6 | S21: 15.7 | T21: 15.8 | U21: 15.8 | V21: 15.8 | X21: 17 | Y21: 3.3 | Z21: 3.4 | AA21: 3.7 | AB21: 3.7 | AC21: 4 | AD21: 4 | AE21: 4.3 | AF21: 4.9 | AG21: 5.5 | AH21: 5.6 | AI21: 6 | AJ21: 6.5 | AK21: 6.5 | AL21: 7 | AM21: 7.5 | AN21: 8 | AO21: 8.5 | AQ21: 900 | AR21: 5 | AS21: 5 | AT21: 2.9 | AU21: 3.8 | AV21: 3.8 | AX21: Otopark | AZ21: 0.1 | BA21: 0.2
A22: OTOPARK TİCARİ | B22: 40 | C22: 30 | E22: 18 | F22: 14.5 | G22: 14.6 | H22: 14.9 | I22: 14.9 | J22: 15.2 | K22: 15.2 | L22: 15.4 | M22: 15.7 | N22: 16 | O22: 16 | P22: 16.2 | Q22: 16.5 | R22: 16.5 | S22: 16.7 | T22: 16.8 | U22: 16.8 | V22: 16.8 | X22: 18 | Y22: 3.3 | Z22: 3.4 | AA22: 3.7 | AB22: 3.7 | AC22: 4 | AD22: 4 | AE22: 4.3 | AF22: 4.9 | AG22: 5.5 | AH22: 5.6 | AI22: 6 | AJ22: 6.6 | AK22: 6.6 | AL22: 7.1 | AM22: 7.6 | AN22: 8.1 | AO22: 8.6 | AQ22: 1000 | AR22: 6 | AS22: 6 | AT22: 3.3 | AU22: 4 | AV22: 4 | AX22: Yüksek bina asansörlerinin hesabı için yükleltilmiş değerlerin seçilmesi tavsiye edilir.
A23: OTOPARK ÖZEL | B23: 40 | C23: 30 | E23: 19 | F23: 15.3 | G23: 15.4 | H23: 15.7 | I23: 15.7 | J23: 16 | K23: 16 | L23: 16.2 | M23: 16.5 | N23: 16.9 | O23: 16.9 | P23: 17.1 | Q23: 17.4 | R23: 17.4 | S23: 17.5 | T23: 17.7 | U23: 17.7 | V23: 17.7 | X23: 19 | Y23: 3.3 | Z23: 3.4 | AA23: 3.7 | AB23: 3.7 | AC23: 4 | AD23: 4 | AE23: 4.3 | AF23: 4.9 | AG23: 5.6 | AH23: 5.7 | AI23: 6.1 | AJ23: 6.7 | AK23: 6.7 | AL23: 7.2 | AM23: 7.7 | AN23: 8.2 | AO23: 8.7 | AQ23: 1100 | AR23: 6 | AS23: 6 | AT23: 3.5 | AU23: 4 | AV23: 4
E24: 20 | F24: 16.3 | G24: 16.4 | H24: 16.5 | I24: 16.5 | J24: 16.7 | K24: 16.7 | L24: 17 | M24: 17.4 | N24: 17.8 | O24: 17.8 | P24: 18 | Q24: 18.2 | R24: 18.2 | S24: 18.4 | T24: 18.6 | U24: 18.6 | V24: 18.6 | X24: 20 | Y24: 3.3 | Z24: 3.4 | AA24: 3.7 | AB24: 3.7 | AC24: 4.1 | AD24: 4.1 | AE24: 4.4 | AF24: 5 | AG24: 5.6 | AH24: 5.7 | AI24: 6.1 | AJ24: 6.7 | AK24: 6.7 | AL24: 7.2 | AM24: 7.8 | AN24: 8.4 | AO24: 9 | AQ24: 1200 | AR24: 6 | AS24: 6 | AT24: 3.5 | AU24: 4.4 | AV24: 4.4
E25: 21 | F25: 16.8 | G25: 17 | H25: 17.3 | I25: 17.3 | J25: 17.6 | K25: 17.6 | L25: 17.9 | M25: 18.2 | N25: 18.6 | O25: 18.6 | P25: 18.8 | Q25: 19.1 | R25: 19.1 | S25: 19.3 | T25: 19.5 | U25: 19.5 | V25: 19.5 | X25: 21 | Y25: 3.3 | Z25: 3.4 | AA25: 3.7 | AB25: 3.7 | AC25: 4.1 | AD25: 4.1 | AE25: 4.4 | AF25: 5 | AG25: 5.6 | AH25: 5.7 | AI25: 6.2 | AJ25: 6.8 | AK25: 6.8 | AL25: 7.3 | AM25: 7.9 | AN25: 8.5 | AO25: 9.1 | AQ25: 1300 | AR25: 6 | AS25: 6 | AT25: 3.6 | AU25: 4.7 | AV25: 4.7 | AX25: Tablo--8
E26: 22 | F26: 17.7 | G26: 17.8 | H26: 18.1 | I26: 18.1 | J26: 18.4 | K26: 18.4 | L26: 18.7 | M26: 19.1 | N26: 19.5 | O26: 19.5 | P26: 19.7 | Q26: 20 | R26: 20 | S26: 20.2 | T26: 20.4 | U26: 20.4 | V26: 20.4 | X26: 22 | Y26: 3.3 | Z26: 3.4 | AA26: 3.7 | AB26: 3.7 | AC26: 4.1 | AD26: 4.1 | AE26: 4.4 | AF26: 5 | AG26: 5.7 | AH26: 5.8 | AI26: 6.2 | AJ26: 6.8 | AK26: 6.8 | AL26: 7.3 | AM26: 7.9 | AN26: 8.5 | AO26: 9.1 | AQ26: 1400 | AR26: 6 | AS26: 6 | AT26: 3.7 | AU26: 5 | AV26: 5 | AX26: Kapı Genişliği (m) | AZ26: Tp(s)
E27: 23 | F27: 18.4 | G27: 18.6 | H27: 18.9 | I27: 18.9 | J27: 19.2 | K27: 19.2 | L27: 19.5 | M27: 19.9 | N27: 20.4 | O27: 20.4 | P27: 20.6 | Q27: 20.9 | R27: 20.9 | S27: 21.1 | T27: 21.3 | U27: 21.3 | V27: 21.3 | X27: 23 | Y27: 3.4 | Z27: 3.5 | AA27: 3.8 | AB27: 3.8 | AC27: 4.2 | AD27: 4.2 | AE27: 4.4 | AF27: 5 | AG27: 5.7 | AH27: 5.8 | AI27: 6.3 | AJ27: 6.9 | AK27: 6.9 | AL27: 7.4 | AM27: 8 | AN27: 8.6 | AO27: 9.2 | AX27: <1 | AZ27: 2.2
E28: 24 | F28: 19.2 | G28: 19.4 | H28: 19.7 | I28: 19.7 | J28: 20 | K28: 20 | L28: 20.3 | M28: 20.7 | N28: 21.2 | O28: 21.2 | P28: 21.4 | Q28: 21.8 | R28: 21.8 | S28: 22 | T28: 22.2 | U28: 22.2 | V28: 22.2 | X28: 24 | Y28: 3.4 | Z28: 3.5 | AA28: 3.8 | AB28: 3.8 | AC28: 4.2 | AD28: 4.2 | AE28: 4.4 | AF28: 5 | AG28: 5.7 | AH28: 5.8 | AI28: 6.3 | AJ28: 6.9 | AK28: 6.9 | AL28: 7.4 | AM28: 8 | AN28: 8.6 | AO28: 9.2 | AX28: >=1 | AZ28: 2
A30: ASKI HALATLAR (TS 12385-5) | H30: EN 81-1 Çizelge G.2 | M30: U Profil | AJ30: I Profil
A31: ÇAP | B31: 1 m AĞIRLIĞI | C31: KOPMA MUK. | E31: TİPİ | F31: SINIFI | H31: Darbe Tipi | J31: k1 | K31: Değer | M31: l | N31: Ölçüler - mm | V31: F cm2 | W31: G kg/m | AD31: ey cm | AE31: xm cm | AF31: Sx cm | AG31: Flanş Delikleri DIN 997 | AJ31: l | AK31: Ölçüler - mm | AS31: F cm2 | AT31: G kg/m | BA31: Sx cm | BB31: Flaş Delikleri DIN 997
A32: 6 | B32: 0.129 | C32: 23100 | E32: 6x19 Lif Özlü | F32: 1770 | H32: Kaymalı | J32: k1 | K32: 2 | X32: x-x | AA32: y-y | AU32: x-x | AX32: y-y
A33: 6.5 | B33: 0.152 | C33: 24700 | E33: 6x19 Lif Özlü | F33: 1770 | H33: Ani Frenlemeli Makaralı | J33: k1 | K33: 3 | N33: h | O33: b | P33: s r1 | Q33: t | R33: r2 | S33: c | T33: h-2c | U33: t1 | X33: Jx cm4 | Y33: Wx cm3 | Z33: Ix cm | AA33: Jy cm4 | AB33: Wy cm3 | AC33: Iy cm | AG33: d1 | AH33: W1 | AK33: h | AL33: b | AM33: s r1 | AN33: t | AO33: r2 | AP33: c | AQ33: n-2c | AR33: t1 | AU33: Jx cm4 | AV33: Wx cm3 | AW33: Ix cm | AX33: Jy cm4 | AY33: Wy cm3 | AZ33: Iy cm | BB33: d1 | BC33: W1
A34: 7 | B34: =(B35+B32)/2 -> 0.1795 | C34: =(C35+C32)/2 -> 27400 | E34: 6x19 Lif Özlü | F34: 1770 | H34: Ani Frenlemeli | J34: k1 | K34: 5 | N34: Yuvarlatılmış kenarlı U - profili (Sıcak Haddelenmiş) DIN 1026 | AK34: Flanş iç yüzeyleri eğik Dar Flaşlı I profilleri I serisi,sıcak haddelenmiş Dın 1025 Bölüm 1
A35: 8 | B35: 0.23 | C35: 31700 | E35: 6x19 Lif Özlü | F35: 1370/1770 | BE35: U Profil | BF35: I Profil
A36: 9 | B36: 0.291 | C36: 40100 | E36: 6x19 Lif Özlü | F36: 1370/1770 | H36: Hareket halinde | J36: k2 | K36: 1.2 | M36: 30x15 | N36: 30 | O36: 15 | P36: 4 | Q36: 4.5 | R36: 2 | S36: 9 | T36: 12 | V36: 2.21 | W36: 1.74 | X36: 2.21 | Y36: 1.69 | Z36: 1.07 | AA36: 0.38 | AB36: 0.39 | AC36: 0.42 | AD36: 0.52 | AE36: 0.74 | AG36: 4.3 | AH36: 10 | AJ36: 80 | AK36: 80 | AL36: 42 | AM36: 3.9 | AN36: 5.9 | AO36: 2.3 | AP36: 10.5 | AQ36: 59 | AR36: 4.4 | AS36: 7.57 | AT36: 5.94 | AU36: 77.8 | AV36: 19.5 | AW36: 3.2 | AX36: 6.29 | AY36: 3 | AZ36: 0.91 | BA36: 6.84 | BB36: 6.4 | BC36: 22 | BE36: 30x15 | BF36: 80
A37: 10 | B37: 0.34 | C37: 49500 | E37: 6x19 Lif Özlü | F37: 1370/1770 | M37: 30 | N37: 30 | O37: 33 | P37: 5 | Q37: 7 | R37: 3.5 | S37: 14.5 | T37: 1 | V37: 5.44 | W37: 4.27 | X37: 6.39 | Y37: 4.26 | Z37: 1.08 | AA37: 5.33 | AB37: 2.68 | AC37: 0.99 | AD37: 1.31 | AE37: 2.22 | AG37: 8.4 | AH37: 20 | AJ37: 100 | AK37: 100 | AL37: 50 | AM37: 4.5 | AN37: 6.8 | AO37: 2.7 | AP37: 12.5 | AQ37: 75 | AR37: 5 | AS37: 10.6 | AT37: 8.34 | AU37: 171 | AV37: 34.2 | AW37: 4.01 | AX37: 12.2 | AY37: 4.88 | AZ37: 1.07 | BA37: 8.57 | BB37: 6.4 | BC37: 28 | BE37: 30 | BF37: 100
A38: 11 | B38: 0.411 | C38: 53200 | E38: 8x19 Lif Özlü | F38: 1370/1770 | M38: 40x20 | N38: 40 | O38: 20 | P38: 5 | Q38: 5.5 | R38: 2.5 | S38: 11 | T38: 18 | V38: 3.66 | W38: 2.87 | X38: 7.58 | Y38: 3.79 | Z38: 1.44 | AA38: 1.14 | AB38: 0.86 | AC38: 0.56 | AD38: 0.67 | AE38: 1.01 | AG38: 6.4 | AH38: 11 | AJ38: 120 | AK38: 120 | AL38: 56 | AM38: 5.1 | AN38: 7.7 | AO38: 3.1 | AP38: 14 | AQ38: 92 | AR38: 5.7 | AS38: 14.2 | AT38: 11.1 | AU38: 328 | AV38: 54.7 | AW38: 4.81 | AX38: 21.5 | AY38: 7.41 | AZ38: 1.23 | BA38: 10.3 | BB38: 8.4 | BC38: 32 | BE38: 40x20 | BF38: 120
A39: 12 | B39: 0.49 | C39: 63300 | E39: 8x19 Lif Özlü | F39: 1370/1770 | M39: 40 | N39: 40 | O39: 35 | P39: 5 | Q39: 7 | R39: 3.5 | S39: 14.5 | T39: 11 | V39: 6.21 | W39: 4.87 | X39: 14.1 | Y39: 7.05 | Z39: 1.5 | AA39: 6.68 | AB39: 3.08 | AC39: 1.04 | AD39: 1.33 | AE39: 2.32 | AG39: 8.4 | AH39: 20 | AJ39: 140 | AK39: 140 | AL39: 58 | AM39: 5.7 | AN39: 8.6 | AO39: 3.4 | AP39: 15.5 | AQ39: 109 | AR39: 6.3 | AS39: 18.2 | AT39: 14.3 | AU39: 573 | AV39: 81.9 | AW39: 5.61 | AX39: 35.2 | AY39: 10.7 | AZ39: 1.4 | BA39: 12 | BB39: 11 | BC39: 34 | BE39: 40 | BF39: 140
A40: 13 | B40: 0.575 | C40: 74300 | E40: 8x19 Lif Özlü | F40: 1370/1770 | M40: 50x25 | N40: 50 | O40: 25 | P40: 5 | Q40: 6 | R40: 3 | S40: 12.5 | T40: 25 | V40: 4.92 | W40: 3.86 | X40: 16.8 | Y40: 6.73 | Z40: 1.85 | AA40: 2.49 | AB40: 1.48 | AC40: 0.71 | AD40: 0.81 | AE40: 1.34 | AG40: 8.4 | AH40: 16 | AJ40: 160 | AK40: 160 | AL40: 66 | AM40: 6.3 | AN40: 9.5 | AO40: 3.8 | AP40: 17.5 | AQ40: 125 | AR40: 6.9 | AS40: 22.6 | AT40: 17.9 | AU40: 935 | AV40: 117 | AW40: 6.4 | AX40: 54.7 | AY40: 14.8 | AZ40: 1.55 | BA40: 13.7 | BB40: 11 | BC40: 40 | BE40: 50x25 | BF40: 160
